Workbook

Sheet BASE_ABASTECIMENTO
A1: DATA | B1: SEMANA ANO | C1: PLATAFORMA | D1: VALOR | E1: EQUIPE | F1: CENTRO DE CUSTO | G1: PLACA | H1: OBS | I1: MÊS/ANO
A2: 46076 | B2: =WEEKNUM(A2,21) -> 9 | C2: TICKETLOG | D2: 80 | E2: MANFAC-1 | F2: =VLOOKUP(E2,BASE_VEICULOS!A:G,7,0) -> FAC - 140004 - MANUTENÇÃO PREDIAL DPSP 2025 | G2: =IFERROR(VLOOKUP(E2,BASE_VEICULOS!$A:$B,2,0),"") -> TEW9A25 | I2: =DATE(YEAR(A2),MONTH(A2),1) -> 46054
A3: 46076 | B3: =WEEKNUM(A3,21) -> 9 | C3: TICKETLOG | D3: 150 | E3: MANFAC-2 | F3: =VLOOKUP(E3,BASE_VEICULOS!A:G,7,0) -> PROF - 07001 - MANUTENÇÃO PREDIAL- PROFARMA-2025 | G3: =IFERROR(VLOOKUP(E3,BASE_VEICULOS!$A:$B,2,0),"") -> TEW9A28 | I3: =DATE(YEAR(A3),MONTH(A3),1) -> 46054
A4: 46076 | B4: =WEEKNUM(A4,21) -> 9 | C4: TICKETLOG | D4: 79.98 | E4: MANFAC-3 | F4: =VLOOKUP(E4,BASE_VEICULOS!A:G,7,0) -> FAC - 140004 - MANUTENÇÃO PREDIAL DPSP 2025 | G4: =IFERROR(VLOOKUP(E4,BASE_VEICULOS!$A:$B,2,0),"") -> FIL8C14 | I4: =DATE(YEAR(A4),MONTH(A4),1) -> 46054
A5: 46076 | B5: =WEEKNUM(A5,21) -> 9 | C5: TICKETLOG | D5: 79.98 | E5: MANFAC-4 | F5: =VLOOKUP(E5,BASE_VEICULOS!A:G,7,0) -> FAC - 140005 - SPOT MANUTENÇÃO DPSP 2025 | G5: =IFERROR(VLOOKUP(E5,BASE_VEICULOS!$A:$B,2,0),"") -> FGO3C61 | I5: =DATE(YEAR(A5),MONTH(A5),1) -> 46054
A6: 46076 | B6: =WEEKNUM(A6,21) -> 9 | C6: TICKETLOG | D6: 90 | E6: MANFAC-5 | F6: =VLOOKUP(E6,BASE_VEICULOS!A:G,7,0) -> FAC - 140004 - MANUTENÇÃO PREDIAL DPSP 2025 | G6: =IFERROR(VLOOKUP(E6,BASE_VEICULOS!$A:$B,2,0),"") -> FOK8A73 | I6: =DATE(YEAR(A6),MONTH(A6),1) -> 46054
A7: 46076 | B7: =WEEKNUM(A7,21) -> 9 | C7: TICKETLOG | D7: 70 | E7: MANFAC-6 | F7: =VLOOKUP(E7,BASE_VEICULOS!A:G,7,0) -> FAC - 140005 - SPOT MANUTENÇÃO DPSP 2025 | G7: =IFERROR(VLOOKUP(E7,BASE_VEICULOS!$A:$B,2,0),"") -> EWH1B84 | I7: =DATE(YEAR(A7),MONTH(A7),1) -> 46054
A8: 46076 | B8: =WEEKNUM(A8,21) -> 9 | C8: TICKETLOG | D8: 80 | E8: MANFAC-7 | F8: =VLOOKUP(E8,BASE_VEICULOS!A:G,7,0) -> FAC - 140005 - SPOT MANUTENÇÃO DPSP 2025 | G8: =IFERROR(VLOOKUP(E8,BASE_VEICULOS!$A:$B,2,0),"") -> TEW9A27 | I8: =DATE(YEAR(A8),MONTH(A8),1) -> 46054
A9: 46076 | B9: =WEEKNUM(A9,21) -> 9 | C9: TICKETLOG | D9: 119.97 | E9: MANFAC-8 | F9: =VLOOKUP(E9,BASE_VEICULOS!A:G,7,0) -> #N/A | G9: =IFERROR(VLOOKUP(E9,BASE_VEICULOS!$A:$B,2,0),"") | I9: =DATE(YEAR(A9),MONTH(A9),1) -> 46054
A10: 46076 | B10: =WEEKNUM(A10,21) -> 9 | C10: TICKETLOG | D10: 200 | E10: MANFAC-9 | F10: =VLOOKUP(E10,BASE_VEICULOS!A:G,7,0) -> FAC - 140004 - MANUTENÇÃO PREDIAL DPSP 2025 | G10: =IFERROR(VLOOKUP(E10,BASE_VEICULOS!$A:$B,2,0),"") -> TEW9A29 | I10: =DATE(YEAR(A10),MONTH(A10),1) -> 46054
A11: 46076 | B11: =WEEKNUM(A11,21) -> 9 | C11: TICKETLOG | D11: 160 | E11: MANFAC-11 | F11: =VLOOKUP(E11,BASE_VEICULOS!A:G,7,0) -> PROF - 07001 - MANUTENÇÃO PREDIAL- PROFARMA-2025 | G11: =IFERROR(VLOOKUP(E11,BASE_VEICULOS!$A:$B,2,0),"") -> TEW9A24 | I11: =DATE(YEAR(A11),MONTH(A11),1) -> 46054
A12: 46076 | B12: =WEEKNUM(A12,21) -> 9 | C12: TICKETLOG | D12: 80 | E12: MANFAC-12 | F12: =VLOOKUP(E12,BASE_VEICULOS!A:G,7,0) -> PROF - 07001 - MANUTENÇÃO PREDIAL- PROFARMA-2025 | G12: =IFERROR(VLOOKUP(E12,BASE_VEICULOS!$A:$B,2,0),"") -> TEW9A34 | I12: =DATE(YEAR(A12),MONTH(A12),1) -> 46054
A13: 46076 | B13: =WEEKNUM(A13,21) -> 9 | C13: TICKETLOG | D13: 80 | E13: MANFAC-13 | F13: =VLOOKUP(E13,BASE_VEICULOS!A:G,7,0) -> PROF - 07001 - MANUTENÇÃO PREDIAL- PROFARMA-2025 | G13: =IFERROR(VLOOKUP(E13,BASE_VEICULOS!$A:$B,2,0),"") -> TEW9A33 | I13: =DATE(YEAR(A13),MONTH(A13),1) -> 46054
... A37: 46077 | B37: =WEEKNUM(A37,21) -> 9 | C37: TICKETLOG | D37: 50 | E37: MANFAC-15 | F37: =VLOOKUP(E37,BASE_VEICULOS!A:G,7,0) -> PROF - 07001 - MANUTENÇÃO PREDIAL- PROFARMA-2025 | G37: =IFERROR(VLOOKUP(E37,BASE_VEICULOS!$A:$B,2,0),"") -> TEQ2I74 | I37: =DATE(YEAR(A37),MONTH(A37),1) -> 46054
A38: 46077 | B38: =WEEKNUM(A38,21) -> 9 | C38: TICKETLOG | D38: 80 | E38: MANFAC-20 | F38: =VLOOKUP(E38,BASE_VEICULOS!A:G,7,0) -> #N/A | G38: =IFERROR(VLOOKUP(E38,BASE_VEICULOS!$A:$B,2,0),"") | H38: Incluso 100,00 dia 24/02/2026 | I38: =DATE(YEAR(A38),MONTH(A38),1) -> 46054
A39: 46078 | B39: =WEEKNUM(A39,21) -> 9 | C39: TICKETLOG | D39: 140 | E39: MANFAC-1 | F39: =VLOOKUP(E39,BASE_VEICULOS!A:G,7,0) -> FAC - 140004 - MANUTENÇÃO PREDIAL DPSP 2025 | G39: =IFERROR(VLOOKUP(E39,BASE_VEICULOS!$A:$B,2,0),"") -> TEW9A25 | I39: =DATE(YEAR(A39),MONTH(A39),1) -> 46054
A40: 46078 | B40: =WEEKNUM(A40,21) -> 9 | C40: TICKETLOG | D40: 150.08 | E40: MANFAC-2 | F40: =VLOOKUP(E40,BASE_VEICULOS!A:G,7,0) -> PROF - 07001 - MANUTENÇÃO PREDIAL- PROFARMA-2025 | G40: =IFERROR(VLOOKUP(E40,BASE_VEICULOS!$A:$B,2,0),"") -> TEW9A28 | I40: =DATE(YEAR(A40),MONTH(A40),1) -> 46054
A41: 46078 | B41: =WEEKNUM(A41,21) -> 9 | C41: TICKETLOG | D41: 119.98 | E41: MANFAC-3 | F41: =VLOOKUP(E41,BASE_VEICULOS!A:G,7,0) -> FAC - 140004 - MANUTENÇÃO PREDIAL DPSP 2025 | G41: =IFERROR(VLOOKUP(E41,BASE_VEICULOS!$A:$B,2,0),"") -> FIL8C14 | I41: =DATE(YEAR(A41),MONTH(A41),1) -> 46054
A42: 46078 | B42: =WEEKNUM(A42,21) -> 9 | C42: TICKETLOG | D42: 79.97 | E42: MANFAC-4 | F42: =VLOOKUP(E42,BASE_VEICULOS!A:G,7,0) -> FAC - 140005 - SPOT MANUTENÇÃO DPSP 2025 | G42: =IFERROR(VLOOKUP(E42,BASE_VEICULOS!$A:$B,2,0),"") -> FGO3C61 | I42: =DATE(YEAR(A42),MONTH(A42),1) -> 46054
A43: 46078 | B43: =WEEKNUM(A43,21) -> 9 | C43: TICKETLOG | D43: 80 | E43: MANFAC-5 | F43: =VLOOKUP(E43,BASE_VEICULOS!A:G,7,0) -> FAC - 140004 - MANUTENÇÃO PREDIAL DPSP 2025 | G43: =IFERROR(VLOOKUP(E43,BASE_VEICULOS!$A:$B,2,0),"") -> FOK8A73 | I43: =DATE(YEAR(A43),MONTH(A43),1) -> 46054
A44: 46078 | B44: =WEEKNUM(A44,21) -> 9 | C44: TICKETLOG | D44: 70 | E44: MANFAC-6 | F44: =VLOOKUP(E44,BASE_VEICULOS!A:G,7,0) -> FAC - 140005 - SPOT MANUTENÇÃO DPSP 2025 | G44: =IFERROR(VLOOKUP(E44,BASE_VEICULOS!$A:$B,2,0),"") -> EWH1B84 | I44: =DATE(YEAR(A44),MONTH(A44),1) -> 46054
A45: 46078 | B45: =WEEKNUM(A45,21) -> 9 | C45: TICKETLOG | D45: 50 | E45: MANFAC-7 | F45: =VLOOKUP(E45,BASE_VEICULOS!A:G,7,0) -> FAC - 140005 - SPOT MANUTENÇÃO DPSP 2025 | G45: =IFERROR(VLOOKUP(E45,BASE_VEICULOS!$A:$B,2,0),"") -> TEW9A27 | I45: =DATE(YEAR(A45),MONTH(A45),1) -> 46054
A46: 46078 | B46: =WEEKNUM(A46,21) -> 9 | C46: TICKETLOG | D46: 120.03 | E46: MANFAC-8 | F46: =VLOOKUP(E46,BASE_VEICULOS!A:G,7,0) -> #N/A | G46: =IFERROR(VLOOKUP(E46,BASE_VEICULOS!$A:$B,2,0),"") | I46: =DATE(YEAR(A46),MONTH(A46),1) -> 46054
A47: 46078 | B47: =WEEKNUM(A47,21) -> 9 | C47: TICKETLOG | D47: 80 | E47: MANFAC-9 | F47: =VLOOKUP(E47,BASE_VEICULOS!A:G,7,0) -> FAC - 140004 - MANUTENÇÃO PREDIAL DPSP 2025 | G47: =IFERROR(VLOOKUP(E47,BASE_VEICULOS!$A:$B,2,0),"") -> TEW9A29 | I47: =DATE(YEAR(A47),MONTH(A47),1) -> 46054
A48: 46078 | B48: =WEEKNUM(A48,21) -> 9 | C48: TICKETLOG | D48: 100 | E48: MANFAC-11 | F48: =VLOOKUP(E48,BASE_VEICULOS!A:G,7,0) -> PROF - 07001 - MANUTENÇÃO PREDIAL- PROFARMA-2025 | G48: =IFERROR(VLOOKUP(E48,BASE_VEICULOS!$A:$B,2,0),"") -> TEW9A24 | I48: =DATE(YEAR(A48),MONTH(A48),1) -> 46054
A49: 46078 | B49: =WEEKNUM(A49,21) -> 9 | C49: TICKETLOG | D49: 80 | E49: MANFAC-12 | F49: =VLOOKUP(E49,BASE_VEICULOS!A:G,7,0) -> PROF - 07001 - MANUTENÇÃO PREDIAL- PROFARMA-2025 | G49: =IFERROR(VLOOKUP(E49,BASE_VEICULOS!$A:$B,2,0),"") -> TEW9A34 | I49: =DATE(YEAR(A49),MONTH(A49),1) -> 46054
A50: 46078 | B50: =WEEKNUM(A50,21) -> 9 | C50: TICKETLOG | D50: 100 | E50: MANFAC-13 | F50: =VLOOKUP(E50,BASE_VEICULOS!A:G,7,0) -> PROF - 07001 - MANUTENÇÃO PREDIAL- PROFARMA-2025 | G50: =IFERROR(VLOOKUP(E50,BASE_VEICULOS!$A:$B,2,0),"") -> TEW9A33 | I50: =DATE(YEAR(A50),MONTH(A50),1) -> 46054
... A290: 46094 | B290: =WEEKNUM(A290,21) -> 11 | C290: CAIXINHA | D290: 80 | E290: MANFAC-5 | F290: =VLOOKUP(E290,BASE_VEICULOS!A:G,7,0) -> FAC - 140004 - MANUTENÇÃO PREDIAL DPSP 2025 | G290: =IFERROR(VLOOKUP(E290,BASE_VEICULOS!$A:$B,2,0),"") -> FOK8A73 | I290: =DATE(YEAR(A290),MONTH(A290),1) -> 46082
A291: 46094 | B291: =WEEKNUM(A291,21) -> 11 | C291: CAIXINHA | E291: MANFAC-23 | F291: =VLOOKUP(E291,BASE_VEICULOS!A:G,7,0) -> #N/A | G291: =IFERROR(VLOOKUP(E291,BASE_VEICULOS!$A:$B,2,0),"") | I291: =DATE(YEAR(A291),MONTH(A291),1) -> 46082
A292: 46094 | B292: =WEEKNUM(A292,21) -> 11 | C292: CAIXINHA | E292: MANFAC-15 | F292: =VLOOKUP(E292,BASE_VEICULOS!A:G,7,0) -> PROF - 07001 - MANUTENÇÃO PREDIAL- PROFARMA-2025 | G292: =IFERROR(VLOOKUP(E292,BASE_VEICULOS!$A:$B,2,0),"") -> TEQ2I74 | I292: =DATE(YEAR(A292),MONTH(A292),1) -> 46082
A293: 46094 | B293: =WEEKNUM(A293,21) -> 11 | C293: CAIXINHA | E293: MANFAC-21 | F293: =VLOOKUP(E293,BASE_VEICULOS!A:G,7,0) -> PROF - 07001 - MANUTENÇÃO PREDIAL- PROFARMA-2025 | G293: =IFERROR(VLOOKUP(E293,BASE_VEICULOS!$A:$B,2,0),"") -> TEW9A23 | I293: =DATE(YEAR(A293),MONTH(A293),1) -> 46082
A294: 46094 | B294: =WEEKNUM(A294,21) -> 11 | C294: CAIXINHA | E294: MANFAC-18 | F294: =VLOOKUP(E294,BASE_VEICULOS!A:G,7,0) -> PROF - 07001 - MANUTENÇÃO PREDIAL- PROFARMA-2025 | G294: =IFERROR(VLOOKUP(E294,BASE_VEICULOS!$A:$B,2,0),"") -> TET5H37 | I294: =DATE(YEAR(A294),MONTH(A294),1) -> 46082
A295: 46094 | B295: =WEEKNUM(A295,21) -> 11 | C295: CAIXINHA | E295: MANFAC-4 | F295: =VLOOKUP(E295,BASE_VEICULOS!A:G,7,0) -> FAC - 140005 - SPOT MANUTENÇÃO DPSP 2025 | G295: =IFERROR(VLOOKUP(E295,BASE_VEICULOS!$A:$B,2,0),"") -> FGO3C61 | I295: =DATE(YEAR(A295),MONTH(A295),1) -> 46082
A296: 46094 | B296: =WEEKNUM(A296,21) -> 11 | C296: CAIXINHA | E296: MANFAC-22 | F296: =VLOOKUP(E296,BASE_VEICULOS!A:G,7,0) -> PROF - 07001 - MANUTENÇÃO PREDIAL- PROFARMA-2025 | G296: =IFERROR(VLOOKUP(E296,BASE_VEICULOS!$A:$B,2,0),"") -> TEW9A26 | I296: =DATE(YEAR(A296),MONTH(A296),1) -> 46082
A297: 46094 | B297: =WEEKNUM(A297,21) -> 11 | C297: CAIXINHA | E297: MANFAC-10 | F297: =VLOOKUP(E297,BASE_VEICULOS!A:G,7,0) -> PROF - 07001 - MANUTENÇÃO PREDIAL- PROFARMA-2025 | G297: =IFERROR(VLOOKUP(E297,BASE_VEICULOS!$A:$B,2,0),"") -> TEW9A30 | I297: =DATE(YEAR(A297),MONTH(A297),1) -> 46082
A298: 46094 | B298: =WEEKNUM(A298,21) -> 11 | C298: CAIXINHA | E298: MANFAC-20 | F298: =VLOOKUP(E298,BASE_VEICULOS!A:G,7,0) -> #N/A | G298: =IFERROR(VLOOKUP(E298,BASE_VEICULOS!$A:$B,2,0),"") | I298: =DATE(YEAR(A298),MONTH(A298),1) -> 46082
A299: 46094 | B299: =WEEKNUM(A299,21) -> 11 | C299: CAIXINHA | E299: MANFAC-2 | F299: =VLOOKUP(E299,BASE_VEICULOS!A:G,7,0) -> PROF - 07001 - MANUTENÇÃO PREDIAL- PROFARMA-2025 | G299: =IFERROR(VLOOKUP(E299,BASE_VEICULOS!$A:$B,2,0),"") -> TEW9A28 | I299: =DATE(YEAR(A299),MONTH(A299),1) -> 46082
A300: 46095 | B300: =WEEKNUM(A300,21) -> 11 | C300: CAIXINHA | E300: MANFAC-11 | F300: =VLOOKUP(E300,BASE_VEICULOS!A:G,7,0) -> PROF - 07001 - MANUTENÇÃO PREDIAL- PROFARMA-2025 | G300: =IFERROR(VLOOKUP(E300,BASE_VEICULOS!$A:$B,2,0),"") -> TEW9A24 | I300: =DATE(YEAR(A300),MONTH(A300),1) -> 46082
A301: 46095 | B301: =WEEKNUM(A301,21) -> 11 | C301: CAIXINHA | E301: MANFAC-19 | F301: =VLOOKUP(E301,BASE_VEICULOS!A:G,7,0) -> PROF - 07001 - MANUTENÇÃO PREDIAL- PROFARMA-2025 | G301: =IFERROR(VLOOKUP(E301,BASE_VEICULOS!$A:$B,2,0),"") -> TEH3I02 | I301: =DATE(YEAR(A301),MONTH(A301),1) -> 46082
A302: 46095 | B302: =WEEKNUM(A302,21) -> 11 | C302: CAIXINHA | E302: MANFAC-18 | F302: =VLOOKUP(E302,BASE_VEICULOS!A:G,7,0) -> PROF - 07001 - MANUTENÇÃO PREDIAL- PROFARMA-2025 | G302: =IFERROR(VLOOKUP(E302,BASE_VEICULOS!$A:$B,2,0),"") -> TET5H37 | I302: =DATE(YEAR(A302),MONTH(A302),1) -> 46082
...

Sheet DASH_DADOS
A2: Início mês | B2: =DATE(YEAR(B3),MONTH(B3),1) -> 46174 | D2: EQUIPE | E2: TODOS
A3: Fim mês | B3: =EOMONTH(B4,0) -> 46203 | D3: CENTRO DE CUSTO | E3: PROF - 07001 - MANUTENÇÃO PREDIAL- PROFARMA-2025
A4: Hoje | B4: =TODAY() -> 46184
A6: CONSUMO x PLANEJADO
A7: Semana (início) | B7: Semana (fim) | C7: Consumo (R$) | D7: Planejado (R$) | E7: Desvio (R$)
A8: =($B$2-WEEKDAY($B$2,2)+1) -> 46174 | B8: =A8+6 -> 46180 | C8: =IF(A8>$B$3,"",SUMIFS(BASE_ABASTECIMENTO!$D$2:$D$97,BASE_ABASTECIMENTO!$A$2:$A$145,">="&A8,BASE_ABASTECIMENTO!$A$2:$A$145,"<="&MIN(B8,$B$3,$B$4),BASE_ABASTECIMENTO!$E$2:$E$145,IF($E$2="TODOS","*",$E$2),BASE_ABASTECIMENTO!$F$2:$F$145,IF($E$3="TODOS","*",$E$3))) -> #VALUE! | D8: =IF(A8>$B$3,"",SUMIFS(BASE_PLANEJADO!$D$2:$D$1000,BASE_PLANEJADO!$B$2:$B$1000,DATE(YEAR($B$4),MONTH($B$4),1),BASE_PLANEJADO!$A$2:$A$1000,IF($E$3="TODOS","*",$E$3))) -> 0 | E8: =IF(C8="","",C8-D8) -> #VALUE!
A9: =A8+7 -> 46181 | B9: =A9+6 -> 46187 | C9: =IF(A9>$B$3,"",SUMIFS(BASE_ABASTECIMENTO!$D$2:$D$97,BASE_ABASTECIMENTO!$A$2:$A$145,">="&A9,BASE_ABASTECIMENTO!$A$2:$A$145,"<="&MIN(B9,$B$3,$B$4),BASE_ABASTECIMENTO!$E$2:$E$145,IF($E$2="TODOS","*",$E$2),BASE_ABASTECIMENTO!$F$2:$F$145,IF($E$3="TODOS","*",$E$3))) -> #VALUE! | D9: =IF(A9>$B$3,"",SUMIFS(BASE_PLANEJADO!$D$2:$D$1000,BASE_PLANEJADO!$B$2:$B$1000,DATE(YEAR($B$4),MONTH($B$4),1),BASE_PLANEJADO!$A$2:$A$1000,IF($E$3="TODOS","*",$E$3))) -> 0 | E9: =IF(C9="","",C9-D9) -> #VALUE!
A10: =A9+7 -> 46188 | B10: =A10+6 -> 46194 | C10: =IF(A10>$B$3,"",SUMIFS(BASE_ABASTECIMENTO!$D$2:$D$97,BASE_ABASTECIMENTO!$A$2:$A$145,">="&A10,BASE_ABASTECIMENTO!$A$2:$A$145,"<="&MIN(B10,$B$3,$B$4),BASE_ABASTECIMENTO!$E$2:$E$145,IF($E$2="TODOS","*",$E$2),BASE_ABASTECIMENTO!$F$2:$F$145,IF($E$3="TODOS","*",$E$3))) -> #VALUE! | D10: =IF(A10>$B$3,"",SUMIFS(BASE_PLANEJADO!$D$2:$D$1000,BASE_PLANEJADO!$B$2:$B$1000,DATE(YEAR($B$4),MONTH($B$4),1),BASE_PLANEJADO!$A$2:$A$1000,IF($E$3="TODOS","*",$E$3))) -> 0 | E10: =IF(C10="","",C10-D10) -> #VALUE!
A11: =A10+7 -> 46195 | B11: =A11+6 -> 46201 | C11: =IF(A11>$B$3,"",SUMIFS(BASE_ABASTECIMENTO!$D$2:$D$97,BASE_ABASTECIMENTO!$A$2:$A$145,">="&A11,BASE_ABASTECIMENTO!$A$2:$A$145,"<="&MIN(B11,$B$3,$B$4),BASE_ABASTECIMENTO!$E$2:$E$145,IF($E$2="TODOS","*",$E$2),BASE_ABASTECIMENTO!$F$2:$F$145,IF($E$3="TODOS","*",$E$3))) -> #VALUE! | D11: =IF(A11>$B$3,"",SUMIFS(BASE_PLANEJADO!$D$2:$D$1000,BASE_PLANEJADO!$B$2:$B$1000,DATE(YEAR($B$4),MONTH($B$4),1),BASE_PLANEJADO!$A$2:$A$1000,IF($E$3="TODOS","*",$E$3))) -> 0 | E11: =IF(C11="","",C11-D11) -> #VALUE!
A12: =A11+7 -> 46202 | B12: =A12+6 -> 46208 | C12: =IF(A12>$B$3,"",SUMIFS(BASE_ABASTECIMENTO!$D$2:$D$97,BASE_ABASTECIMENTO!$A$2:$A$145,">="&A12,BASE_ABASTECIMENTO!$A$2:$A$145,"<="&MIN(B12,$B$3,$B$4),BASE_ABASTECIMENTO!$E$2:$E$145,IF($E$2="TODOS","*",$E$2),BASE_ABASTECIMENTO!$F$2:$F$145,IF($E$3="TODOS","*",$E$3))) -> #VALUE! | D12: =IF(A12>$B$3,"",SUMIFS(BASE_PLANEJADO!$D$2:$D$1000,BASE_PLANEJADO!$B$2:$B$1000,DATE(YEAR($B$4),MONTH($B$4),1),BASE_PLANEJADO!$A$2:$A$1000,IF($E$3="TODOS","*",$E$3))) -> 0 | E12: =IF(C12="","",C12-D12) -> #VALUE!
A13: =A12+7 -> 46209 | B13: =A13+6 -> 46215 | C13: =IF(A13>$B$3,"",SUMIFS(BASE_ABASTECIMENTO!$D$2:$D$97,BASE_ABASTECIMENTO!$A$2:$A$145,">="&A13,BASE_ABASTECIMENTO!$A$2:$A$145,"<="&MIN(B13,$B$3,$B$4),BASE_ABASTECIMENTO!$E$2:$E$145,IF($E$2="TODOS","*",$E$2),BASE_ABASTECIMENTO!$F$2:$F$145,IF($E$3="TODOS","*",$E$3))) | D13: =IF(A13>$B$3,"",SUMIFS(BASE_PLANEJADO!$D$2:$D$1000,BASE_PLANEJADO!$B$2:$B$1000,DATE(YEAR($B$4),MONTH($B$4),1),BASE_PLANEJADO!$A$2:$A$1000,IF($E$3="TODOS","*",$E$3))) | E13: =IF(C13="","",C13-D13)
A15: TOP 10 CONSUMO COMBUSTÍVEL (POR EQUIPE) | G15: EQUIPE | H15: CENTRO DE CUSTO | I15: COMBUSTÍVEL | J15: PEDAGIO | K15: ESTACIONAMENTO | L15: MULTA | M15: MANUTENÇÃO | N15: CUSTO TOTAL FROTA | O15: KM CONTRATUAL | P15: ULTIMO KM | Q15: DESVIO KM
A16: #POS | B16: EQUIPE | C16: VALOR CONSUMIDO | G16: MANFAC-1 | H16: =IF(G16="","",IFERROR(VLOOKUP(G16,BASE_VEICULOS!$A:$G,7,FALSE),"")) -> FAC - 140004 - MANUTENÇÃO PREDIAL DPSP 2025 | I16: =SUMIFS(BASE_ABASTECIMENTO!D:D,BASE_ABASTECIMENTO!E:E,$G16,BASE_ABASTECIMENTO!A:A,">="&$B$2,BASE_ABASTECIMENTO!A:A,"<="&$B$3) -> 0 | J16: =SUMIFS(BASE_VELOE!$F:$F,BASE_VELOE!$B:$B,$G16,BASE_VELOE!$A:$A,">="&$B$2,BASE_VELOE!$A:$A,"<="&$B$3,BASE_VELOE!$D:$D,J$15) -> 0 | K16: =SUMIFS(BASE_VELOE!$F:$F,BASE_VELOE!$B:$B,$G16,BASE_VELOE!$A:$A,">="&$B$2,BASE_VELOE!$A:$A,"<="&$B$3,BASE_VELOE!$D:$D,K$15) -> 0 | N16: =SUM(I16:M16) -> 0 | O16: =IF(VLOOKUP(G16,BASE_VEICULOS!A:O,10,0)="CONTRATO FROTAS",($B$4-VLOOKUP(G16,BASE_VEICULOS!A:O,15,0))/30*VLOOKUP(G16,BASE_VEICULOS!A:O,12,0),"") -> 23100 | P16: =IFERROR(__xludf.DUMMYFUNCTION("IF(G16="""","""",IFERROR(MAX(FILTER(BASE_KM!$C$2:$C1000, BASE_KM!$B$2:$B1000=G16, BASE_KM!$A$2:$A1000=MAX(FILTER(BASE_KM!$A$2:$A1000, BASE_KM!$B$2:$B1000=G16)))),""""))"),25030.0) -> 25030 | Q16: =O16-P16 -> -1930
A17: =IFERROR(__xludf.DUMMYFUNCTION("IFERROR({SEQUENCE(10),SORTN(FILTER({$G$16:$G$41,$I$16:$I$41},$G$16:$G$41<>"""",$I$16:$I$41<>""""),10,0,2,FALSE)},"""")"),1.0) -> 1 | B17: =IFERROR(__xludf.DUMMYFUNCTION("""COMPUTED_VALUE"""),"MANFAC-1") -> MANFAC-1 | C17: =IFERROR(__xludf.DUMMYFUNCTION("""COMPUTED_VALUE"""),0.0) -> 0 | G17: MANFAC-2 | H17: =IF(G17="","",IFERROR(VLOOKUP(G17,BASE_VEICULOS!$A:$G,7,FALSE),"")) -> PROF - 07001 - MANUTENÇÃO PREDIAL- PROFARMA-2025 | I17: =SUMIFS(BASE_ABASTECIMENTO!D:D,BASE_ABASTECIMENTO!E:E,$G17,BASE_ABASTECIMENTO!A:A,">="&$B$2,BASE_ABASTECIMENTO!A:A,"<="&$B$3) -> 0 | J17: =SUMIFS(BASE_VELOE!F:F,BASE_VELOE!B:B,G17,BASE_VELOE!A:A,">="&$B$2,BASE_VELOE!A:A,"<="&$B$3,BASE_VELOE!D:D,J$15) -> 0 | K17: =SUMIFS(BASE_VELOE!$F:$F,BASE_VELOE!$B:$B,$G17,BASE_VELOE!$A:$A,">="&$B$2,BASE_VELOE!$A:$A,"<="&$B$3,BASE_VELOE!$D:$D,K$15) -> 0 | N17: =SUM(I17:M17) -> 0 | O17: =($B$4- VLOOKUP(G17,BASE_VEICULOS!A:O,15,0))/30*VLOOKUP(G17,BASE_VEICULOS!A:O,12,0) -> 21900 | P17: =IFERROR(__xludf.DUMMYFUNCTION("IF(G17="""","""",IFERROR(MAX(FILTER(BASE_KM!$C$2:$C1000, BASE_KM!$B$2:$B1000=G17, BASE_KM!$A$2:$A1000=MAX(FILTER(BASE_KM!$A$2:$A1000, BASE_KM!$B$2:$B1000=G17)))),""""))"),27226.0) -> 27226 | Q17: =O17-P17 -> -5326
A18: =IFERROR(__xludf.DUMMYFUNCTION("""COMPUTED_VALUE"""),2.0) -> 2 | B18: =IFERROR(__xludf.DUMMYFUNCTION("""COMPUTED_VALUE"""),"MANFAC-2") -> MANFAC-2 | C18: =IFERROR(__xludf.DUMMYFUNCTION("""COMPUTED_VALUE"""),0.0) -> 0 | G18: MANFAC-3 | H18: =IF(G18="","",IFERROR(VLOOKUP(G18,BASE_VEICULOS!$A:$G,7,FALSE),"")) -> FAC - 140004 - MANUTENÇÃO PREDIAL DPSP 2025 | I18: =SUMIFS(BASE_ABASTECIMENTO!D:D,BASE_ABASTECIMENTO!E:E,$G18,BASE_ABASTECIMENTO!A:A,">="&$B$2,BASE_ABASTECIMENTO!A:A,"<="&$B$3) -> 0 | J18: =SUMIFS(BASE_VELOE!F:F,BASE_VELOE!B:B,G18,BASE_VELOE!A:A,">="&$B$2,BASE_VELOE!A:A,"<="&$B$3,BASE_VELOE!D:D,J$15) -> 0 | K18: =SUMIFS(BASE_VELOE!$F:$F,BASE_VELOE!$B:$B,$G18,BASE_VELOE!$A:$A,">="&$B$2,BASE_VELOE!$A:$A,"<="&$B$3,BASE_VELOE!$D:$D,K$15) -> 0 | N18: =SUM(I18:M18) -> 0 | O18: =($B$4- VLOOKUP(G18,BASE_VEICULOS!A:O,15,0))/30*VLOOKUP(G18,BASE_VEICULOS!A:O,12,0) -> 100400 | P18: =IFERROR(__xludf.DUMMYFUNCTION("IF(G18="""","""",IFERROR(MAX(FILTER(BASE_KM!$C$2:$C1000, BASE_KM!$B$2:$B1000=G18, BASE_KM!$A$2:$A1000=MAX(FILTER(BASE_KM!$A$2:$A1000, BASE_KM!$B$2:$B1000=G18)))),""""))"),96713.0) -> 96713 | Q18: =O18-P18 -> 3687
A19: =IFERROR(__xludf.DUMMYFUNCTION("""COMPUTED_VALUE"""),3.0) -> 3 | B19: =IFERROR(__xludf.DUMMYFUNCTION("""COMPUTED_VALUE"""),"MANFAC-3") -> MANFAC-3 | C19: =IFERROR(__xludf.DUMMYFUNCTION("""COMPUTED_VALUE"""),0.0) -> 0 | G19: MANFAC-4 | H19: =IF(G19="","",IFERROR(VLOOKUP(G19,BASE_VEICULOS!$A:$G,7,FALSE),"")) -> FAC - 140005 - SPOT MANUTENÇÃO DPSP 2025 | I19: =SUMIFS(BASE_ABASTECIMENTO!D:D,BASE_ABASTECIMENTO!E:E,$G19,BASE_ABASTECIMENTO!A:A,">="&$B$2,BASE_ABASTECIMENTO!A:A,"<="&$B$3) -> 0 | J19: =SUMIFS(BASE_VELOE!F:F,BASE_VELOE!B:B,G19,BASE_VELOE!A:A,">="&$B$2,BASE_VELOE!A:A,"<="&$B$3,BASE_VELOE!D:D,J$15) -> 0 | K19: =SUMIFS(BASE_VELOE!$F:$F,BASE_VELOE!$B:$B,$G19,BASE_VELOE!$A:$A,">="&$B$2,BASE_VELOE!$A:$A,"<="&$B$3,BASE_VELOE!$D:$D,K$15) -> 0 | N19: =SUM(I19:M19) -> 0 | O19: =($B$4- VLOOKUP(G19,BASE_VEICULOS!A:O,15,0))/30*VLOOKUP(G19,BASE_VEICULOS!A:O,12,0) -> 105300 | P19: =IFERROR(__xludf.DUMMYFUNCTION("IF(G19="""","""",IFERROR(MAX(FILTER(BASE_KM!$C$2:$C1000, BASE_KM!$B$2:$B1000=G19, BASE_KM!$A$2:$A1000=MAX(FILTER(BASE_KM!$A$2:$A1000, BASE_KM!$B$2:$B1000=G19)))),""""))"),113188.0) -> 113188 | Q19: =O19-P19 -> -7888
A20: =IFERROR(__xludf.DUMMYFUNCTION("""COMPUTED_VALUE"""),4.0) -> 4 | B20: =IFERROR(__xludf.DUMMYFUNCTION("""COMPUTED_VALUE"""),"MANFAC-4") -> MANFAC-4 | C20: =IFERROR(__xludf.DUMMYFUNCTION("""COMPUTED_VALUE"""),0.0) -> 0 | G20: MANFAC-5 | H20: =IF(G20="","",IFERROR(VLOOKUP(G20,BASE_VEICULOS!$A:$G,7,FALSE),"")) -> FAC - 140004 - MANUTENÇÃO PREDIAL DPSP 2025 | I20: =SUMIFS(BASE_ABASTECIMENTO!D:D,BASE_ABASTECIMENTO!E:E,$G20,BASE_ABASTECIMENTO!A:A,">="&$B$2,BASE_ABASTECIMENTO!A:A,"<="&$B$3) -> 0 | J20: =SUMIFS(BASE_VELOE!F:F,BASE_VELOE!B:B,G20,BASE_VELOE!A:A,">="&$B$2,BASE_VELOE!A:A,"<="&$B$3,BASE_VELOE!D:D,J$15) -> 0 | K20: =SUMIFS(BASE_VELOE!$F:$F,BASE_VELOE!$B:$B,$G20,BASE_VELOE!$A:$A,">="&$B$2,BASE_VELOE!$A:$A,"<="&$B$3,BASE_VELOE!$D:$D,K$15) -> 0 | N20: =SUM(I20:M20) -> 0 | O20: =($B$4- VLOOKUP(G20,BASE_VEICULOS!A:O,15,0))/30*VLOOKUP(G20,BASE_VEICULOS!A:O,12,0) -> 105300 | P20: =IFERROR(__xludf.DUMMYFUNCTION("IF(G20="""","""",IFERROR(MAX(FILTER(BASE_KM!$C$2:$C1000, BASE_KM!$B$2:$B1000=G20, BASE_KM!$A$2:$A1000=MAX(FILTER(BASE_KM!$A$2:$A1000, BASE_KM!$B$2:$B1000=G20)))),""""))"),98530.0) -> 98530 | Q20: =O20-P20 -> 6770
A21: =IFERROR(__xludf.DUMMYFUNCTION("""COMPUTED_VALUE"""),5.0) -> 5 | B21: =IFERROR(__xludf.DUMMYFUNCTION("""COMPUTED_VALUE"""),"MANFAC-5") -> MANFAC-5 | C21: =IFERROR(__xludf.DUMMYFUNCTION("""COMPUTED_VALUE"""),0.0) -> 0 | G21: MANFAC-6 | H21: =IF(G21="","",IFERROR(VLOOKUP(G21,BASE_VEICULOS!$A:$G,7,FALSE),"")) -> FAC - 140005 - SPOT MANUTENÇÃO DPSP 2025 | I21: =SUMIFS(BASE_ABASTECIMENTO!D:D,BASE_ABASTECIMENTO!E:E,$G21,BASE_ABASTECIMENTO!A:A,">="&$B$2,BASE_ABASTECIMENTO!A:A,"<="&$B$3) -> 0 | J21: =SUMIFS(BASE_VELOE!F:F,BASE_VELOE!B:B,G21,BASE_VELOE!A:A,">="&$B$2,BASE_VELOE!A:A,"<="&$B$3,BASE_VELOE!D:D,J$15) -> 0 | K21: =SUMIFS(BASE_VELOE!$F:$F,BASE_VELOE!$B:$B,$G21,BASE_VELOE!$A:$A,">="&$B$2,BASE_VELOE!$A:$A,"<="&$B$3,BASE_VELOE!$D:$D,K$15) -> 0 | N21: =SUM(I21:M21) -> 0 | O21: =($B$4- VLOOKUP(G21,BASE_VEICULOS!A:O,15,0))/30*VLOOKUP(G21,BASE_VEICULOS!A:O,12,0) -> 94500 | P21: =IFERROR(__xludf.DUMMYFUNCTION("IF(G21="""","""",IFERROR(MAX(FILTER(BASE_KM!$C$2:$C1000, BASE_KM!$B$2:$B1000=G21, BASE_KM!$A$2:$A1000=MAX(FILTER(BASE_KM!$A$2:$A1000, BASE_KM!$B$2:$B1000=G21)))),""""))"),114223.0) -> 114223 | Q21: =O21-P21 -> -19723
A22: =IFERROR(__xludf.DUMMYFUNCTION("""COMPUTED_VALUE"""),6.0) -> 6 | B22: =IFERROR(__xludf.DUMMYFUNCTION("""COMPUTED_VALUE"""),"MANFAC-6") -> MANFAC-6 | C22: =IFERROR(__xludf.DUMMYFUNCTION("""COMPUTED_VALUE"""),0.0) -> 0 | G22: MANFAC-7 | H22: =IF(G22="","",IFERROR(VLOOKUP(G22,BASE_VEICULOS!$A:$G,7,FALSE),"")) -> FAC - 140005 - SPOT MANUTENÇÃO DPSP 2025 | I22: =SUMIFS(BASE_ABASTECIMENTO!D:D,BASE_ABASTECIMENTO!E:E,$G22,BASE_ABASTECIMENTO!A:A,">="&$B$2,BASE_ABASTECIMENTO!A:A,"<="&$B$3) -> 0 | J22: =SUMIFS(BASE_VELOE!F:F,BASE_VELOE!B:B,G22,BASE_VELOE!A:A,">="&$B$2,BASE_VELOE!A:A,"<="&$B$3,BASE_VELOE!D:D,J$15) -> 0 | K22: =SUMIFS(BASE_VELOE!$F:$F,BASE_VELOE!$B:$B,$G22,BASE_VELOE!$A:$A,">="&$B$2,BASE_VELOE!$A:$A,"<="&$B$3,BASE_VELOE!$D:$D,K$15) -> 0 | N22: =SUM(I22:M22) -> 0 | O22: =($B$4- VLOOKUP(G22,BASE_VEICULOS!A:O,15,0))/30*VLOOKUP(G22,BASE_VEICULOS!A:O,12,0) -> 21800 | P22: =IFERROR(__xludf.DUMMYFUNCTION("IF(G22="""","""",IFERROR(MAX(FILTER(BASE_KM!$C$2:$C1000, BASE_KM!$B$2:$B1000=G22, BASE_KM!$A$2:$A1000=MAX(FILTER(BASE_KM!$A$2:$A1000, BASE_KM!$B$2:$B1000=G22)))),""""))"),16032.0) -> 16032 | Q22: =O22-P22 -> 5768
A23: =IFERROR(__xludf.DUMMYFUNCTION("""COMPUTED_VALUE"""),7.0) -> 7 | B23: =IFERROR(__xludf.DUMMYFUNCTION("""COMPUTED_VALUE"""),"MANFAC-7") -> MANFAC-7 | C23: =IFERROR(__xludf.DUMMYFUNCTION("""COMPUTED_VALUE"""),0.0) -> 0 | G23: MANFAC-8 | H23: =IF(G23="","",IFERROR(VLOOKUP(G23,BASE_VEICULOS!$A:$G,7,FALSE),"")) | I23: =SUMIFS(BASE_ABASTECIMENTO!D:D,BASE_ABASTECIMENTO!E:E,$G23,BASE_ABASTECIMENTO!A:A,">="&$B$2,BASE_ABASTECIMENTO!A:A,"<="&$B$3) -> 0 | J23: =SUMIFS(BASE_VELOE!F:F,BASE_VELOE!B:B,G23,BASE_VELOE!A:A,">="&$B$2,BASE_VELOE!A:A,"<="&$B$3,BASE_VELOE!D:D,J$15) -> 0 | K23: =SUMIFS(BASE_VELOE!$F:$F,BASE_VELOE!$B:$B,$G23,BASE_VELOE!$A:$A,">="&$B$2,BASE_VELOE!$A:$A,"<="&$B$3,BASE_VELOE!$D:$D,K$15) -> 0 | N23: =SUM(I23:M23) -> 0 | O23: =($B$4- VLOOKUP(G23,BASE_VEICULOS!A:O,15,0))/30*VLOOKUP(G23,BASE_VEICULOS!A:O,12,0) -> #N/A | P23: =IFERROR(__xludf.DUMMYFUNCTION("IF(G23="""","""",IFERROR(MAX(FILTER(BASE_KM!$C$2:$C1000, BASE_KM!$B$2:$B1000=G23, BASE_KM!$A$2:$A1000=MAX(FILTER(BASE_KM!$A$2:$A1000, BASE_KM!$B$2:$B1000=G23)))),""""))"),17420.0) -> 17420 | Q23: =O23-P23 -> #N/A
A24: =IFERROR(__xludf.DUMMYFUNCTION("""COMPUTED_VALUE"""),8.0) -> 8 | B24: =IFERROR(__xludf.DUMMYFUNCTION("""COMPUTED_VALUE"""),"MANFAC-8") -> MANFAC-8 | C24: =IFERROR(__xludf.DUMMYFUNCTION("""COMPUTED_VALUE"""),0.0) -> 0 | G24: MANFAC-9 | H24: =IF(G24="","",IFERROR(VLOOKUP(G24,BASE_VEICULOS!$A:$G,7,FALSE),"")) -> FAC - 140004 - MANUTENÇÃO PREDIAL DPSP 2025 | I24: =SUMIFS(BASE_ABASTECIMENTO!D:D,BASE_ABASTECIMENTO!E:E,$G24,BASE_ABASTECIMENTO!A:A,">="&$B$2,BASE_ABASTECIMENTO!A:A,"<="&$B$3) -> 0 | J24: =SUMIFS(BASE_VELOE!F:F,BASE_VELOE!B:B,G24,BASE_VELOE!A:A,">="&$B$2,BASE_VELOE!A:A,"<="&$B$3,BASE_VELOE!D:D,J$15) -> 0 | K24: =SUMIFS(BASE_VELOE!$F:$F,BASE_VELOE!$B:$B,$G24,BASE_VELOE!$A:$A,">="&$B$2,BASE_VELOE!$A:$A,"<="&$B$3,BASE_VELOE!$D:$D,K$15) -> 0 | N24: =SUM(I24:M24) -> 0 | O24: =($B$4- VLOOKUP(G24,BASE_VEICULOS!A:O,15,0))/30*VLOOKUP(G24,BASE_VEICULOS!A:O,12,0) -> 23300 | P24: =IFERROR(__xludf.DUMMYFUNCTION("IF(G24="""","""",IFERROR(MAX(FILTER(BASE_KM!$C$2:$C1000, BASE_KM!$B$2:$B1000=G24, BASE_KM!$A$2:$A1000=MAX(FILTER(BASE_KM!$A$2:$A1000, BASE_KM!$B$2:$B1000=G24)))),""""))"),25035.0) -> 25035 | Q24: =O24-P24 -> -1735
A25: =IFERROR(__xludf.DUMMYFUNCTION("""COMPUTED_VALUE"""),9.0) -> 9 | B25: =IFERROR(__xludf.DUMMYFUNCTION("""COMPUTED_VALUE"""),"MANFAC-9") -> MANFAC-9 | C25: =IFERROR(__xludf.DUMMYFUNCTION("""COMPUTED_VALUE"""),0.0) -> 0 | G25: MANFAC-10 | H25: =IF(G25="","",IFERROR(VLOOKUP(G25,BASE_VEICULOS!$A:$G,7,FALSE),"")) -> PROF - 07001 - MANUTENÇÃO PREDIAL- PROFARMA-2025 | I25: =SUMIFS(BASE_ABASTECIMENTO!D:D,BASE_ABASTECIMENTO!E:E,$G25,BASE_ABASTECIMENTO!A:A,">="&$B$2,BASE_ABASTECIMENTO!A:A,"<="&$B$3) -> 0 | J25: =SUMIFS(BASE_VELOE!F:F,BASE_VELOE!B:B,G25,BASE_VELOE!A:A,">="&$B$2,BASE_VELOE!A:A,"<="&$B$3,BASE_VELOE!D:D,J$15) -> 0 | K25: =SUMIFS(BASE_VELOE!$F:$F,BASE_VELOE!$B:$B,$G25,BASE_VELOE!$A:$A,">="&$B$2,BASE_VELOE!$A:$A,"<="&$B$3,BASE_VELOE!$D:$D,K$15) -> 0 | N25: =SUM(I25:M25) -> 0 | O25: =($B$4- VLOOKUP(G25,BASE_VEICULOS!A:O,15,0))/30*VLOOKUP(G25,BASE_VEICULOS!A:O,12,0) -> 21200 | P25: =IFERROR(__xludf.DUMMYFUNCTION("IF(G25="""","""",IFERROR(MAX(FILTER(BASE_KM!$C$2:$C1000, BASE_KM!$B$2:$B1000=G25, BASE_KM!$A$2:$A1000=MAX(FILTER(BASE_KM!$A$2:$A1000, BASE_KM!$B$2:$B1000=G25)))),""""))"),22512.0) -> 22512 | Q25: =O25-P25 -> -1312
A26: =IFERROR(__xludf.DUMMYFUNCTION("""COMPUTED_VALUE"""),10.0) -> 10 | B26: =IFERROR(__xludf.DUMMYFUNCTION("""COMPUTED_VALUE"""),"MANFAC-10") -> MANFAC-10 | C26: =IFERROR(__xludf.DUMMYFUNCTION("""COMPUTED_VALUE"""),0.0) -> 0 | G26: MANFAC-11 | H26: =IF(G26="","",IFERROR(VLOOKUP(G26,BASE_VEICULOS!$A:$G,7,FALSE),"")) -> PROF - 07001 - MANUTENÇÃO PREDIAL- PROFARMA-2025 | I26: =SUMIFS(BASE_ABASTECIMENTO!D:D,BASE_ABASTECIMENTO!E:E,$G26,BASE_ABASTECIMENTO!A:A,">="&$B$2,BASE_ABASTECIMENTO!A:A,"<="&$B$3) -> 0 | J26: =SUMIFS(BASE_VELOE!F:F,BASE_VELOE!B:B,G26,BASE_VELOE!A:A,">="&$B$2,BASE_VELOE!A:A,"<="&$B$3,BASE_VELOE!D:D,J$15) -> 0 | K26: =SUMIFS(BASE_VELOE!$F:$F,BASE_VELOE!$B:$B,$G26,BASE_VELOE!$A:$A,">="&$B$2,BASE_VELOE!$A:$A,"<="&$B$3,BASE_VELOE!$D:$D,K$15) -> 0 | N26: =SUM(I26:M26) -> 0 | O26: =($B$4- VLOOKUP(G26,BASE_VEICULOS!A:O,15,0))/30*VLOOKUP(G26,BASE_VEICULOS!A:O,12,0) -> 23400 | P26: =IFERROR(__xludf.DUMMYFUNCTION("IF(G26="""","""",IFERROR(MAX(FILTER(BASE_KM!$C$2:$C1000, BASE_KM!$B$2:$B1000=G26, BASE_KM!$A$2:$A1000=MAX(FILTER(BASE_KM!$A$2:$A1000, BASE_KM!$B$2:$B1000=G26)))),""""))"),29003.0) -> 29003 | Q26: =O26-P26 -> -5603
G27: MANFAC-12 | H27: =IF(G27="","",IFERROR(VLOOKUP(G27,BASE_VEICULOS!$A:$G,7,FALSE),"")) -> PROF - 07001 - MANUTENÇÃO PREDIAL- PROFARMA-2025 | I27: =SUMIFS(BASE_ABASTECIMENTO!D:D,BASE_ABASTECIMENTO!E:E,$G27,BASE_ABASTECIMENTO!A:A,">="&$B$2,BASE_ABASTECIMENTO!A:A,"<="&$B$3) -> 0 | J27: =SUMIFS(BASE_VELOE!F:F,BASE_VELOE!B:B,G27,BASE_VELOE!A:A,">="&$B$2,BASE_VELOE!A:A,"<="&$B$3,BASE_VELOE!D:D,J$15) -> 0 | K27: =SUMIFS(BASE_VELOE!$F:$F,BASE_VELOE!$B:$B,$G27,BASE_VELOE!$A:$A,">="&$B$2,BASE_VELOE!$A:$A,"<="&$B$3,BASE_VELOE!$D:$D,K$15) -> 0 | N27: =SUM(I27:M27) -> 0 | O27: =($B$4- VLOOKUP(G27,BASE_VEICULOS!A:O,15,0))/30*VLOOKUP(G27,BASE_VEICULOS!A:O,12,0) -> 23300 | P27: =IFERROR(__xludf.DUMMYFUNCTION("IF(G27="""","""",IFERROR(MAX(FILTER(BASE_KM!$C$2:$C1000, BASE_KM!$B$2:$B1000=G27, BASE_KM!$A$2:$A1000=MAX(FILTER(BASE_KM!$A$2:$A1000, BASE_KM!$B$2:$B1000=G27)))),""""))"),23929.0) -> 23929 | Q27: =O27-P27 -> -629
A28: RANKING CONSUMO COMBUSTÍVEL (POR CC) | G28: MANFAC-13 | H28: =IF(G28="","",IFERROR(VLOOKUP(G28,BASE_VEICULOS!$A:$G,7,FALSE),"")) -> PROF - 07001 - MANUTENÇÃO PREDIAL- PROFARMA-2025 | I28: =SUMIFS(BASE_ABASTECIMENTO!D:D,BASE_ABASTECIMENTO!E:E,$G28,BASE_ABASTECIMENTO!A:A,">="&$B$2,BASE_ABASTECIMENTO!A:A,"<="&$B$3) -> 0 | J28: =SUMIFS(BASE_VELOE!F:F,BASE_VELOE!B:B,G28,BASE_VELOE!A:A,">="&$B$2,BASE_VELOE!A:A,"<="&$B$3,BASE_VELOE!D:D,J$15) -> 0 | K28: =SUMIFS(BASE_VELOE!$F:$F,BASE_VELOE!$B:$B,$G28,BASE_VELOE!$A:$A,">="&$B$2,BASE_VELOE!$A:$A,"<="&$B$3,BASE_VELOE!$D:$D,K$15) -> 0 | N28: =SUM(I28:M28) -> 0 | O28: =($B$4- VLOOKUP(G28,BASE_VEICULOS!A:O,15,0))/30*VLOOKUP(G28,BASE_VEICULOS!A:O,12,0) -> 23300 | P28: =IFERROR(__xludf.DUMMYFUNCTION("IF(G28="""","""",IFERROR(MAX(FILTER(BASE_KM!$C$2:$C1000, BASE_KM!$B$2:$B1000=G28, BASE_KM!$A$2:$A1000=MAX(FILTER(BASE_KM!$A$2:$A1000, BASE_KM!$B$2:$B1000=G28)))),""""))"),25563.0) -> 25563 | Q28: =O28-P28 -> -2263
A29: #POS | B29: EQUIPE | C29: VALOR CONSUMIDO | G29: MANFAC-15 | H29: =IF(G29="","",IFERROR(VLOOKUP(G29,BASE_VEICULOS!$A:$G,7,FALSE),"")) -> PROF - 07001 - MANUTENÇÃO PREDIAL- PROFARMA-2025 | I29: =SUMIFS(BASE_ABASTECIMENTO!D:D,BASE_ABASTECIMENTO!E:E,$G29,BASE_ABASTECIMENTO!A:A,">="&$B$2,BASE_ABASTECIMENTO!A:A,"<="&$B$3) -> 0 | J29: =SUMIFS(BASE_VELOE!F:F,BASE_VELOE!B:B,G29,BASE_VELOE!A:A,">="&$B$2,BASE_VELOE!A:A,"<="&$B$3,BASE_VELOE!D:D,J$15) -> 0 | K29: =SUMIFS(BASE_VELOE!$F:$F,BASE_VELOE!$B:$B,$G29,BASE_VELOE!$A:$A,">="&$B$2,BASE_VELOE!$A:$A,"<="&$B$3,BASE_VELOE!$D:$D,K$15) -> 0 | N29: =SUM(I29:M29) -> 0 | O29: =($B$4- VLOOKUP(G29,BASE_VEICULOS!A:O,15,0))/30*VLOOKUP(G29,BASE_VEICULOS!A:O,12,0) -> 10800 | P29: =IFERROR(__xludf.DUMMYFUNCTION("IF(G29="""","""",IFERROR(MAX(FILTER(BASE_KM!$C$2:$C1000, BASE_KM!$B$2:$B1000=G29, BASE_KM!$A$2:$A1000=MAX(FILTER(BASE_KM!$A$2:$A1000, BASE_KM!$B$2:$B1000=G29)))),""""))"),25331.0) -> 25331 | Q29: =O29-P29 -> -14531
A30: =IFERROR(__xludf.DUMMYFUNCTION("IFERROR({SEQUENCE(10),QUERY({$H$16:$H$41,IFERROR(VALUE(SUBSTITUTE(SUBSTITUTE(SUBSTITUTE($I$16:$I$41,""R$"",""""),""."",""""),"","",""."")),$I$16:$I$41)},""select Col1, sum(Col2) where Col1 is not null and Col1<>'' group by Col1 order by sum(Col2) desc lim"&"it 10 label sum(Col2) ''"",0)},"""")"),"")
G31: MANFAC-18 | H31: =IF(G31="","",IFERROR(VLOOKUP(G31,BASE_VEICULOS!$A:$G,7,FALSE),"")) -> PROF - 07001 - MANUTENÇÃO PREDIAL- PROFARMA-2025 | I31: =SUMIFS(BASE_ABASTECIMENTO!D:D,BASE_ABASTECIMENTO!E:E,$G31,BASE_ABASTECIMENTO!A:A,">="&$B$2,BASE_ABASTECIMENTO!A:A,"<="&$B$3) -> 0 | J31: =SUMIFS(BASE_VELOE!F:F,BASE_VELOE!B:B,G31,BASE_VELOE!A:A,">="&$B$2,BASE_VELOE!A:A,"<="&$B$3,BASE_VELOE!D:D,J$15) -> 0 | K31: =SUMIFS(BASE_VELOE!$F:$F,BASE_VELOE!$B:$B,$G31,BASE_VELOE!$A:$A,">="&$B$2,BASE_VELOE!$A:$A,"<="&$B$3,BASE_VELOE!$D:$D,K$15) -> 0 | N31: =SUM(I31:M31) -> 0 | O31: =($B$4- VLOOKUP(G31,BASE_VEICULOS!A:O,15,0))/30*VLOOKUP(G31,BASE_VEICULOS!A:O,12,0) -> 24400 | P31: =IFERROR(__xludf.DUMMYFUNCTION("IF(G31="""","""",IFERROR(MAX(FILTER(BASE_KM!$C$2:$C1000, BASE_KM!$B$2:$B1000=G31, BASE_KM!$A$2:$A1000=MAX(FILTER(BASE_KM!$A$2:$A1000, BASE_KM!$B$2:$B1000=G31)))),""""))"),38528.0) -> 38528 | Q31: =O31-P31 -> -14128
G32: MANFAC-19 | H32: =IF(G32="","",IFERROR(VLOOKUP(G32,BASE_VEICULOS!$A:$G,7,FALSE),"")) -> PROF - 07001 - MANUTENÇÃO PREDIAL- PROFARMA-2025 | I32: =SUMIFS(BASE_ABASTECIMENTO!D:D,BASE_ABASTECIMENTO!E:E,$G32,BASE_ABASTECIMENTO!A:A,">="&$B$2,BASE_ABASTECIMENTO!A:A,"<="&$B$3) -> 0 | J32: =SUMIFS(BASE_VELOE!F:F,BASE_VELOE!B:B,G32,BASE_VELOE!A:A,">="&$B$2,BASE_VELOE!A:A,"<="&$B$3,BASE_VELOE!D:D,J$15) -> 0 | K32: =SUMIFS(BASE_VELOE!$F:$F,BASE_VELOE!$B:$B,$G32,BASE_VELOE!$A:$A,">="&$B$2,BASE_VELOE!$A:$A,"<="&$B$3,BASE_VELOE!$D:$D,K$15) -> 0 | N32: =SUM(I32:M32) -> 0 | O32: =($B$4- VLOOKUP(G32,BASE_VEICULOS!A:O,15,0))/30*VLOOKUP(G32,BASE_VEICULOS!A:O,12,0) -> 9200 | P32: =IFERROR(__xludf.DUMMYFUNCTION("IF(G32="""","""",IFERROR(MAX(FILTER(BASE_KM!$C$2:$C1000, BASE_KM!$B$2:$B1000=G32, BASE_KM!$A$2:$A1000=MAX(FILTER(BASE_KM!$A$2:$A1000, BASE_KM!$B$2:$B1000=G32)))),""""))"),23062.0) -> 23062 | Q32: =O32-P32 -> -13862
G33: MANFAC-20 | H33: =IF(G33="","",IFERROR(VLOOKUP(G33,BASE_VEICULOS!$A:$G,7,FALSE),"")) | I33: =SUMIFS(BASE_ABASTECIMENTO!D:D,BASE_ABASTECIMENTO!E:E,$G33,BASE_ABASTECIMENTO!A:A,">="&$B$2,BASE_ABASTECIMENTO!A:A,"<="&$B$3) -> 0 | J33: =SUMIFS(BASE_VELOE!F:F,BASE_VELOE!B:B,G33,BASE_VELOE!A:A,">="&$B$2,BASE_VELOE!A:A,"<="&$B$3,BASE_VELOE!D:D,J$15) -> 0 | K33: =SUMIFS(BASE_VELOE!$F:$F,BASE_VELOE!$B:$B,$G33,BASE_VELOE!$A:$A,">="&$B$2,BASE_VELOE!$A:$A,"<="&$B$3,BASE_VELOE!$D:$D,K$15) -> 0 | N33: =SUM(I33:M33) -> 0 | O33: =($B$4- VLOOKUP(G33,BASE_VEICULOS!A:O,15,0))/30*VLOOKUP(G33,BASE_VEICULOS!A:O,12,0) -> #N/A | P33: =IFERROR(__xludf.DUMMYFUNCTION("IF(G33="""","""",IFERROR(MAX(FILTER(BASE_KM!$C$2:$C1000, BASE_KM!$B$2:$B1000=G33, BASE_KM!$A$2:$A1000=MAX(FILTER(BASE_KM!$A$2:$A1000, BASE_KM!$B$2:$B1000=G33)))),""""))"),26286.0) -> 26286 | Q33: =O33-P33 -> #N/A
G34: MANFAC-21 | H34: =IF(G34="","",IFERROR(VLOOKUP(G34,BASE_VEICULOS!$A:$G,7,FALSE),"")) -> PROF - 07001 - MANUTENÇÃO PREDIAL- PROFARMA-2025 | I34: =SUMIFS(BASE_ABASTECIMENTO!D:D,BASE_ABASTECIMENTO!E:E,$G34,BASE_ABASTECIMENTO!A:A,">="&$B$2,BASE_ABASTECIMENTO!A:A,"<="&$B$3) -> 0 | J34: =SUMIFS(BASE_VELOE!F:F,BASE_VELOE!B:B,G34,BASE_VELOE!A:A,">="&$B$2,BASE_VELOE!A:A,"<="&$B$3,BASE_VELOE!D:D,J$15) -> 0 | K34: =SUMIFS(BASE_VELOE!$F:$F,BASE_VELOE!$B:$B,$G34,BASE_VELOE!$A:$A,">="&$B$2,BASE_VELOE!$A:$A,"<="&$B$3,BASE_VELOE!$D:$D,K$15) -> 0 | N34: =SUM(I34:M34) -> 0 | O34: =($B$4- VLOOKUP(G34,BASE_VEICULOS!A:O,15,0))/30*VLOOKUP(G34,BASE_VEICULOS!A:O,12,0) -> 23300 | P34: =IFERROR(__xludf.DUMMYFUNCTION("IF(G34="""","""",IFERROR(MAX(FILTER(BASE_KM!$C$2:$C1000, BASE_KM!$B$2:$B1000=G34, BASE_KM!$A$2:$A1000=MAX(FILTER(BASE_KM!$A$2:$A1000, BASE_KM!$B$2:$B1000=G34)))),""""))"),23810.0) -> 23810 | Q34: =O34-P34 -> -510
G35: MANFAC-22 | H35: =IF(G35="","",IFERROR(VLOOKUP(G35,BASE_VEICULOS!$A:$G,7,FALSE),"")) -> PROF - 07001 - MANUTENÇÃO PREDIAL- PROFARMA-2025 | I35: =SUMIFS(BASE_ABASTECIMENTO!D:D,BASE_ABASTECIMENTO!E:E,$G35,BASE_ABASTECIMENTO!A:A,">="&$B$2,BASE_ABASTECIMENTO!A:A,"<="&$B$3) -> 0 | J35: =SUMIFS(BASE_VELOE!F:F,BASE_VELOE!B:B,G35,BASE_VELOE!A:A,">="&$B$2,BASE_VELOE!A:A,"<="&$B$3,BASE_VELOE!D:D,J$15) -> 0 | K35: =SUMIFS(BASE_VELOE!$F:$F,BASE_VELOE!$B:$B,$G35,BASE_VELOE!$A:$A,">="&$B$2,BASE_VELOE!$A:$A,"<="&$B$3,BASE_VELOE!$D:$D,K$15) -> 0 | N35: =SUM(I35:M35) -> 0 | O35: =($B$4- VLOOKUP(G35,BASE_VEICULOS!A:O,15,0))/30*VLOOKUP(G35,BASE_VEICULOS!A:O,12,0) -> 22700 | P35: =IFERROR(__xludf.DUMMYFUNCTION("IF(G35="""","""",IFERROR(MAX(FILTER(BASE_KM!$C$2:$C1000, BASE_KM!$B$2:$B1000=G35, BASE_KM!$A$2:$A1000=MAX(FILTER(BASE_KM!$A$2:$A1000, BASE_KM!$B$2:$B1000=G35)))),""""))"),24560.0) -> 24560 | Q35: =O35-P35 -> -1860
G36: MANFAC-23 | H36: =IF(G36="","",IFERROR(VLOOKUP(G36,BASE_VEICULOS!$A:$G,7,FALSE),"")) | I36: =SUMIFS(BASE_ABASTECIMENTO!D:D,BASE_ABASTECIMENTO!E:E,$G36,BASE_ABASTECIMENTO!A:A,">="&$B$2,BASE_ABASTECIMENTO!A:A,"<="&$B$3) -> 0 | J36: =SUMIFS(BASE_VELOE!F:F,BASE_VELOE!B:B,G36,BASE_VELOE!A:A,">="&$B$2,BASE_VELOE!A:A,"<="&$B$3,BASE_VELOE!D:D,J$15) -> 0 | K36: =SUMIFS(BASE_VELOE!$F:$F,BASE_VELOE!$B:$B,$G36,BASE_VELOE!$A:$A,">="&$B$2,BASE_VELOE!$A:$A,"<="&$B$3,BASE_VELOE!$D:$D,K$15) -> 0 | N36: =SUM(I36:M36) -> 0 | O36: =($B$4- VLOOKUP(G36,BASE_VEICULOS!A:O,15,0))/30*VLOOKUP(G36,BASE_VEICULOS!A:O,12,0) -> #N/A | P36: =IFERROR(__xludf.DUMMYFUNCTION("IF(G36="""","""",IFERROR(MAX(FILTER(BASE_KM!$C$2:$C1000, BASE_KM!$B$2:$B1000=G36, BASE_KM!$A$2:$A1000=MAX(FILTER(BASE_KM!$A$2:$A1000, BASE_KM!$B$2:$B1000=G36)))),""""))"),110390.0) -> 110390 | Q36: =O36-P36 -> #N/A
G37: MANFAC-24 | H37: =IF(G37="","",IFERROR(VLOOKUP(G37,BASE_VEICULOS!$A:$G,7,FALSE),"")) -> PROF - 07001 - MANUTENÇÃO PREDIAL- PROFARMA-2025 | I37: =SUMIFS(BASE_ABASTECIMENTO!D:D,BASE_ABASTECIMENTO!E:E,$G37,BASE_ABASTECIMENTO!A:A,">="&$B$2,BASE_ABASTECIMENTO!A:A,"<="&$B$3) -> 0 | J37: =SUMIFS(BASE_VELOE!F:F,BASE_VELOE!B:B,G37,BASE_VELOE!A:A,">="&$B$2,BASE_VELOE!A:A,"<="&$B$3,BASE_VELOE!D:D,J$15) -> 0 | K37: =SUMIFS(BASE_VELOE!$F:$F,BASE_VELOE!$B:$B,$G37,BASE_VELOE!$A:$A,">="&$B$2,BASE_VELOE!$A:$A,"<="&$B$3,BASE_VELOE!$D:$D,K$15) -> 0 | N37: =SUM(I37:M37) -> 0 | O37: =($B$4- VLOOKUP(G37,BASE_VEICULOS!A:O,15,0))/30*VLOOKUP(G37,BASE_VEICULOS!A:O,12,0) -> 4618400 | P37: =IFERROR(__xludf.DUMMYFUNCTION("IF(G37="""","""",IFERROR(MAX(FILTER(BASE_KM!$C$2:$C1000, BASE_KM!$B$2:$B1000=G37, BASE_KM!$A$2:$A1000=MAX(FILTER(BASE_KM!$A$2:$A1000, BASE_KM!$B$2:$B1000=G37)))),""""))"),63144.0) -> 63144 | Q37: =O37-P37 -> 4555256
G38: T-ANDERSON | H38: =IF(G38="","",IFERROR(VLOOKUP(G38,BASE_VEICULOS!$A:$G,7,FALSE),"")) | I38: =SUMIFS(BASE_ABASTECIMENTO!D:D,BASE_ABASTECIMENTO!E:E,$G38,BASE_ABASTECIMENTO!A:A,">="&$B$2,BASE_ABASTECIMENTO!A:A,"<="&$B$3) -> 0 | J38: =SUMIFS(BASE_VELOE!F:F,BASE_VELOE!B:B,G38,BASE_VELOE!A:A,">="&$B$2,BASE_VELOE!A:A,"<="&$B$3,BASE_VELOE!D:D,J$15) -> 0 | K38: =SUMIFS(BASE_VELOE!$F:$F,BASE_VELOE!$B:$B,$G38,BASE_VELOE!$A:$A,">="&$B$2,BASE_VELOE!$A:$A,"<="&$B$3,BASE_VELOE!$D:$D,K$15) -> 0 | N38: =SUM(I38:M38) -> 0 | O38: =($B$4- VLOOKUP(G38,BASE_VEICULOS!A:O,15,0))/30*VLOOKUP(G38,BASE_VEICULOS!A:O,12,0) -> #N/A | P38: =IFERROR(__xludf.DUMMYFUNCTION("IF(G38="""","""",IFERROR(MAX(FILTER(BASE_KM!$C$2:$C1000, BASE_KM!$B$2:$B1000=G38, BASE_KM!$A$2:$A1000=MAX(FILTER(BASE_KM!$A$2:$A1000, BASE_KM!$B$2:$B1000=G38)))),""""))"),17379.0) -> 17379 | Q38: =O38-P38 -> #N/A
G39: REINALDO | H39: =IF(G39="","",IFERROR(VLOOKUP(G39,BASE_VEICULOS!$A:$G,7,FALSE),"")) | I39: =SUMIFS(BASE_ABASTECIMENTO!D:D,BASE_ABASTECIMENTO!E:E,$G39,BASE_ABASTECIMENTO!A:A,">="&$B$2,BASE_ABASTECIMENTO!A:A,"<="&$B$3) -> 0 | J39: =SUMIFS(BASE_VELOE!F:F,BASE_VELOE!B:B,G39,BASE_VELOE!A:A,">="&$B$2,BASE_VELOE!A:A,"<="&$B$3,BASE_VELOE!D:D,J$15) -> 0 | K39: =SUMIFS(BASE_VELOE!$F:$F,BASE_VELOE!$B:$B,$G39,BASE_VELOE!$A:$A,">="&$B$2,BASE_VELOE!$A:$A,"<="&$B$3,BASE_VELOE!$D:$D,K$15) -> 0 | N39: =SUM(I39:M39) -> 0 | O39: =($B$4- VLOOKUP(G39,BASE_VEICULOS!A:O,15,0))/30*VLOOKUP(G39,BASE_VEICULOS!A:O,12,0) -> #N/A | P39: =IFERROR(__xludf.DUMMYFUNCTION("IF(G39="""","""",IFERROR(MAX(FILTER(BASE_KM!$C$2:$C1000, BASE_KM!$B$2:$B1000=G39, BASE_KM!$A$2:$A1000=MAX(FILTER(BASE_KM!$A$2:$A1000, BASE_KM!$B$2:$B1000=G39)))),""""))"),"") | Q39: =O39-P39 -> #N/A
G40: GABRIEL | H40: =IF(G40="","",IFERROR(VLOOKUP(G40,BASE_VEICULOS!$A:$G,7,FALSE),"")) | I40: =SUMIFS(BASE_ABASTECIMENTO!D:D,BASE_ABASTECIMENTO!E:E,$G40,BASE_ABASTECIMENTO!A:A,">="&$B$2,BASE_ABASTECIMENTO!A:A,"<="&$B$3) -> 0 | J40: =SUMIFS(BASE_VELOE!F:F,BASE_VELOE!B:B,G40,BASE_VELOE!A:A,">="&$B$2,BASE_VELOE!A:A,"<="&$B$3,BASE_VELOE!D:D,J$15) -> 0 | K40: =SUMIFS(BASE_VELOE!$F:$F,BASE_VELOE!$B:$B,$G40,BASE_VELOE!$A:$A,">="&$B$2,BASE_VELOE!$A:$A,"<="&$B$3,BASE_VELOE!$D:$D,K$15) -> 0 | N40: =SUM(I40:M40) -> 0 | O40: =($B$4- VLOOKUP(G40,BASE_VEICULOS!A:O,15,0))/30*VLOOKUP(G40,BASE_VEICULOS!A:O,12,0) -> #N/A | P40: =IFERROR(__xludf.DUMMYFUNCTION("IF(G40="""","""",IFERROR(MAX(FILTER(BASE_KM!$C$2:$C1000, BASE_KM!$B$2:$B1000=G40, BASE_KM!$A$2:$A1000=MAX(FILTER(BASE_KM!$A$2:$A1000, BASE_KM!$B$2:$B1000=G40)))),""""))"),"") | Q40: =O40-P40 -> #N/A
G41: YURI | H41: =IF(G41="","",IFERROR(VLOOKUP(G41,BASE_VEICULOS!$A:$G,7,FALSE),"")) -> FAC - 140005 - SPOT MANUTENÇÃO DPSP 2025 | I41: =SUMIFS(BASE_ABASTECIMENTO!D:D,BASE_ABASTECIMENTO!E:E,$G41,BASE_ABASTECIMENTO!A:A,">="&$B$2,BASE_ABASTECIMENTO!A:A,"<="&$B$3) -> 0 | J41: =SUMIFS(BASE_VELOE!F:F,BASE_VELOE!B:B,G41,BASE_VELOE!A:A,">="&$B$2,BASE_VELOE!A:A,"<="&$B$3,BASE_VELOE!D:D,J$15) -> 0 | K41: =SUMIFS(BASE_VELOE!$F:$F,BASE_VELOE!$B:$B,$G41,BASE_VELOE!$A:$A,">="&$B$2,BASE_VELOE!$A:$A,"<="&$B$3,BASE_VELOE!$D:$D,K$15) -> 0 | N41: =SUM(I41:M41) -> 0 | O41: =($B$4- VLOOKUP(G41,BASE_VEICULOS!A:O,15,0))/30*VLOOKUP(G41,BASE_VEICULOS!A:O,12,0) -> 3066.6667 | P41: =IFERROR(__xludf.DUMMYFUNCTION("IF(G41="""","""",IFERROR(MAX(FILTER(BASE_KM!$C$2:$C1000, BASE_KM!$B$2:$B1000=G41, BASE_KM!$A$2:$A1000=MAX(FILTER(BASE_KM!$A$2:$A1000, BASE_KM!$B$2:$B1000=G41)))),""""))"),"") | Q41: =O41-P41 -> 3066.6667

Sheet BASE_PLANEJADO
A1: CENTRO DE CUSTO | B1: MÊS COMPETÊNCIA | C1: VALOR PLANEJADO | D1: VALOR POR SEMANA
A2: FAC - 140004 - MANUTENÇÃO PREDIAL DPSP 2025 | B2: 46023 | C2: 15360 | D2: =C2/4 -> 3840
A3: FAC - 140004 - MANUTENÇÃO PREDIAL DPSP 2025 | B3: 46054 | C3: 15360 | D3: =C3/4 -> 3840
A4: FAC - 140004 - MANUTENÇÃO PREDIAL DPSP 2025 | B4: 46082 | C4: 15360 | D4: =C4/4 -> 3840
A5: PROF - 07001 - MANUTENÇÃO PREDIAL- PROFARMA-2025 | B5: 46023 | C5: 16160 | D5: =C5/4 -> 4040
A6: PROF - 07001 - MANUTENÇÃO PREDIAL- PROFARMA-2025 | B6: 46054 | C6: 16160 | D6: =C6/4 -> 4040
A7: PROF - 07001 - MANUTENÇÃO PREDIAL- PROFARMA-2025 | B7: 46082 | C7: 16160 | D7: =C7/4 -> 4040
A8: PROF - 07002 - SPOT MANUTENÇÃO PROFARMA | B8: 46023 | C8: 6560 | D8: =C8/4 -> 1640
A9: PROF - 07002 - SPOT MANUTENÇÃO PROFARMA | B9: 46054 | C9: 6560 | D9: =C9/4 -> 1640
A10: PROF - 07002 - SPOT MANUTENÇÃO PROFARMA | B10: 46082 | C10: 6560 | D10: =C10/4 -> 1640
A11: FAC - 140005 - SPOT MANUTENÇÃO DPSP 2025 | B11: 46023 | C11: 11200 | D11: =C11/4 -> 2800
A12: FAC - 140005 - SPOT MANUTENÇÃO DPSP 2025 | B12: 46054 | C12: 11200 | D12: =C12/4 -> 2800
A13: FAC - 140005 - SPOT MANUTENÇÃO DPSP 2025 | B13: 46082 | C13: 11200 | D13: =C13/4 -> 2800
... A16: EC - ESCRITORIO CENTRAL | B16: 46082 | C16: 2150 | D16: =C16/4 -> 537.5

Sheet BASE_MOTORISTAS
A1: EQUIPE | B1: STATUS | C1: COLABORADOR | D1: CENTRO DE CUSTO | E1: HABILITAÇÃO | F1: DATA EM QUE EXPIRA
A2: MANFAC-1 | B2: LIDER | C2: GABRIEL DE JESUS FIALHO MIRANDA | D2: FAC - 140004 - MANUTENÇÃO PREDIAL DPSP 2025 | E2: 8087985740 | F2: 48169
A3: MANFAC-10 | B3: LIDER | C3: NADSON SANTOS DE JESUS | D3: PROF - 07001 - MANUTENÇÃO PREDIAL- PROFARMA-2025 | E3: 4350350996 | F3: 47978
A4: MANFAC-11 | B4: LIDER | C4: MARCELO LOPES VIEIRA | D4: PROF - 07001 - MANUTENÇÃO PREDIAL- PROFARMA-2025 | E4: 5974391748 | F4: 46821
A5: MANFAC-12 | B5: LIDER | C5: ANDRE VINICIUS NAZARE ESCOBAR | D5: PROF - 07001 - MANUTENÇÃO PREDIAL- PROFARMA-2025 | E5: 9057636403 | F5: 46221
A6: MANFAC-13 | B6: LIDER | C6: CARLOS HENRIQUE SILVA MENDES | D6: PROF - 07001 - MANUTENÇÃO PREDIAL- PROFARMA-2025 | E6: 6273686368 | F6: 49080
A7: MANFAC-14 | D7: PROF - 07001 - MANUTENÇÃO PREDIAL- PROFARMA-2025 | E7: LIDER | F7: MANFAC-7
A8: MANFAC-15 | B8: LIDER | C8: ALDENIR TEIXIERA CARVALHO | D8: PROF - 07001 - MANUTENÇÃO PREDIAL- PROFARMA-2025 | E8: 7692354540 | F8: 49626
A9: MANFAC-7 | B9: LIDER | C9: HELENO ROVANE DOS SANTOS | D9: FAC - 140005 - SPOT MANUTENÇÃO DPSP 2025 | E9: 506291588
A10: MANFAC-17 | D10: PROF - 07001 - MANUTENÇÃO PREDIAL- PROFARMA-2025 | E10: LIDER | F10: MANFAC-10
A11: MANFAC-18 | B11: LIDER | C11: JORGE LUIZ DOS SANTOS VIEIRA | D11: FAC - 140004 - MANUTENÇÃO PREDIAL DPSP 2025 | E11: 1910272443 | F11: 48110
A12: MANFAC-19 | B12: LIDER | C12: CARLOS ARTHUR FERREIRA DE ANDRADE | D12: FAC - 140005 - SPOT MANUTENÇÃO DPSP 2025 | E12: LIDER | F12: MANFAC-12
A13: MANFAC-2 | B13: LIDER | C13: FABIO DA CONCEIÇÃO | D13: FAC - 140004 - MANUTENÇÃO PREDIAL DPSP 2025 | E13: 4350350996 | F13: 47978
A14: MANFAC-20 | B14: LIDER | C14: WEVERTON MIRANDA MATOS | D14: PROF - 07001 - MANUTENÇÃO PREDIAL- PROFARMA-2025 | E14: 8699424265 | F14: 48903
A15: MANFAC-21 | B15: LIDER | C15: MULLER GOMES DOS SANTOS | D15: PROF - 07001 - MANUTENÇÃO PREDIAL- PROFARMA-2025 | E15: 5550137007 | F15: 48181
A16: MANFAC-22 | B16: LIDER | C16: RICHARD GUIMARÃES FARIAS | D16: PROF - 07001 - MANUTENÇÃO PREDIAL- PROFARMA-2025 | E16: 4355440260 | F16: 48933
A17: MANFAC-23 | B17: LIDER | C17: DOUGLAS SIQUEIRA DOS SANTOS | D17: FAC - 140005 - SPOT MANUTENÇÃO DPSP 2025 | E17: LIDER | F17: MANFAC-17
A18: MANFAC-8 | C18: TIAGO LOURENÇO DOS SANTOS CONCEIÇÃO NUNES | D18: PROF - 07001 - MANUTENÇÃO PREDIAL- PROFARMA-2025 | E18: LIDER | F18: MANFAC-18
A19: MANFAC-3 | B19: LIDER | C19: AILTON HONORATO DOS SANTOS | D19: FAC - 140004 - MANUTENÇÃO PREDIAL DPSP 2025 | E19: 78247835 | F19: 48966
A20: MANFAC-4 | B20: LIDER | C20: MICHEL DA SILVA PINHEIRO | D20: FAC - 140005 - SPOT MANUTENÇÃO DPSP 2025 | E20: NÃO POSSUI
A21: MANFAC-5 | B21: LIDER | C21: RAFAEL SILVA DE OLIVEIRA | D21: FAC - 140004 - MANUTENÇÃO PREDIAL DPSP 2025 | E21: 7346753153 | F21: 49128
A22: MANFAC-20 | C22: WEVERTON MIRANDA MATOS | D22: PROF - 07001 - MANUTENÇÃO PREDIAL- PROFARMA-2025 | E22: LIDER | F22: MANFAC-22
A23: MANFAC-6 | B23: LIDER | C23: DIEGO DA SILVA OLIVEIRA | D23: FAC - 140005 - SPOT MANUTENÇÃO DPSP 2025 | E23: 7572524788 | F23: 49343
A24: MANFAC-8 | B24: LIDER | C24: ALAN DAVID SILVA DOS SANTOS | D24: PROF - 07001 - MANUTENÇÃO PREDIAL- PROFARMA-2025 | E24: 5454035601 | F24: 48111
A25: MANFAC-9 | B25: LIDER | C25: MARCELINO ALMEIDA DE CASTRO | D25: FAC - 140004 - MANUTENÇÃO PREDIAL DPSP 2025 | E25: 6660373002 | F25: 49706

Sheet BASE_VELOE
A1: DATA | B1: EQUIPE | C1: PLACA | D1: TIPO | E1: LOCAL | F1: VALOR | G1: =IFERROR(VLOOKUP(C2,BASE_VEICULOS!A:B,2, FALSE),"")
A2: 46076 | B2: MANFAC-19 | C2: =VLOOKUP(B2,BASE_VEICULOS!A:B,2,0) -> TEH3I02 | D2: PEDAGIO | E2: CONCESSIONARIA ECORIOMINAS | F2: 17.04
A3: 46076 | B3: MANFAC-19 | C3: =VLOOKUP(B3,BASE_VEICULOS!A:B,2,0) -> TEH3I02 | D3: PEDAGIO | E3: CONCESSIONARIA ROTA 116 S.A | F3: 9.6
A4: 46076 | B4: MANFAC-19 | C4: =VLOOKUP(B4,BASE_VEICULOS!A:B,2,0) -> TEH3I02 | D4: PEDAGIO | E4: CONCESSIONARIA ROTA 116 S.A | F4: 9.6
A5: 46076 | B5: MANFAC-19 | C5: =VLOOKUP(B5,BASE_VEICULOS!A:B,2,0) -> TEH3I02 | D5: PEDAGIO | E5: CONCESSIONARIA ECORIOMINAS | F5: 17.04
A6: 46076 | B6: MANFAC-21 | C6: =VLOOKUP(B6,BASE_VEICULOS!A:B,2,0) -> TEW9A23 | D6: PEDAGIO | E6: CONCESSIONARIA ECORIOMINAS | F6: 18.34
A7: 46076 | B7: MANFAC-21 | C7: =VLOOKUP(B7,BASE_VEICULOS!A:B,2,0) -> TEW9A23 | D7: PEDAGIO | E7: CONCESSIONARIA ECORIOMINAS | F7: 18.34
A8: 46076 | B8: MANFAC-21 | C8: =VLOOKUP(B8,BASE_VEICULOS!A:B,2,0) -> TEW9A23 | D8: PEDAGIO | E8: CONCESSIONARIA ROTA 116 S.A | F8: 9.6
A9: 46076 | B9: MANFAC-21 | C9: =VLOOKUP(B9,BASE_VEICULOS!A:B,2,0) -> TEW9A23 | D9: PEDAGIO | E9: CONCESSIONARIA ROTA 116 S.A | F9: 9.6
A10: 46076 | B10: MANFAC-8 | C10: =VLOOKUP(B10,BASE_VEICULOS!A:B,2,0) -> #N/A | D10: PEDAGIO | E10: CONCESSIONARIA ECORIOMINAS | F10: 12.69
A11: 46076 | B11: MANFAC-8 | C11: =VLOOKUP(B11,BASE_VEICULOS!A:B,2,0) -> #N/A | D11: PEDAGIO | E11: CONCESSIONARIA ECORIOMINAS | F11: 12.69
A12: 46076 | B12: MANFAC-15 | C12: =VLOOKUP(B12,BASE_VEICULOS!A:B,2,0) -> TEQ2I74 | D12: PEDAGIO | E12: CONCESSIONARIA PONTE RIO NITEROI S.A | F12: 6.8
A13: 46076 | B13: MANFAC-2 | C13: =VLOOKUP(B13,BASE_VEICULOS!A:B,2,0) -> TEW9A28 | D13: PEDAGIO | E13: CONCESSIONARIA DA RODOVIA DOS LAGOS S.A | F13: 18.4
... A213: 46089 | B213: MANFAC-15 | C213: =VLOOKUP(B213,BASE_VEICULOS!A:B,2,0) -> TEQ2I74 | D213: PEDAGIO | E213: CONCESSIONARIA ECORIOMINAS | F213: 19.1
A214: 46089 | C214: TEW9A20 | D214: PEDAGIO | E214: ELOVIAS S.A. | F214: 19.95
A215: 46089 | B215: MANFAC-7 | C215: =VLOOKUP(B215,BASE_VEICULOS!A:B,2,0) -> TEW9A27 | D215: PEDAGIO | E215: AUTOPISTA FLUMINENSE S.A | F215: 7.5
A216: 46089 | B216: MANFAC-7 | C216: =VLOOKUP(B216,BASE_VEICULOS!A:B,2,0) -> TEW9A27 | D216: PEDAGIO | E216: CONCESSIONARIA DA RODOVIA DOS LAGOS S.A | F216: 30.6
A217: 46089 | B217: MANFAC-9 | C217: =VLOOKUP(B217,BASE_VEICULOS!A:B,2,0) -> TEW9A29 | D217: PEDAGIO | E217: ELOVIAS S.A. | F217: 19.95
A218: 46089 | B218: MANFAC-13 | C218: =VLOOKUP(B218,BASE_VEICULOS!A:B,2,0) -> TEW9A33 | D218: PEDAGIO | E218: AUTOPISTA FLUMINENSE S.A | F218: 7.5
A219: 46090 | B219: MANFAC-6 | C219: =VLOOKUP(B219,BASE_VEICULOS!A:B,2,0) -> EWH1B84 | D219: PEDAGIO | E219: AUTOPISTA FLUMINENSE S.A | F219: 7.5
A220: 46090 | B220: MANFAC-6 | C220: =VLOOKUP(B220,BASE_VEICULOS!A:B,2,0) -> EWH1B84 | D220: PEDAGIO | E220: CONCESSIONARIA PONTE RIO NITEROI S.A | F220: 6.2
A221: 46090 | B221: MANFAC-2 | C221: =VLOOKUP(B221,BASE_VEICULOS!A:B,2,0) -> TEW9A28 | D221: PEDAGIO | E221: CONCESSIONARIA PONTE RIO NITEROI S.A | F221: 6.2
A222: 46090 | B222: REINALDO | C222: =VLOOKUP(B222,BASE_VEICULOS!A:B,2,0) -> #N/A | D222: PEDAGIO | E222: CONCESSIONARIA VIARIO S.A | F222: 8.95
A223: 46090 | B223: MANFAC-19 | C223: =VLOOKUP(B223,BASE_VEICULOS!A:B,2,0) -> TEH3I02 | D223: PEDAGIO | E223: CONCESSIONARIA VIARIO S.A | F223: 8.95
A224: 46090 | B224: MANFAC-19 | C224: =VLOOKUP(B224,BASE_VEICULOS!A:B,2,0) -> TEH3I02 | D224: PEDAGIO | E224: CONCESSIONARIA VIARIO S.A | F224: 8.95
A225: 46090 | B225: MANFAC-18 | C225: =VLOOKUP(B225,BASE_VEICULOS!A:B,2,0) -> TET5H37 | D225: PEDAGIO | E225: CONCESSIONARIA DA RODOVIA DOS LAGOS S.A | F225: 30.6
A226: 46090 | B226: MANFAC-18 | C226: =VLOOKUP(B226,BASE_VEICULOS!A:B,2,0) -> TET5H37 | D226: PEDAGIO | E226: CONCESSIONARIA PONTE RIO NITEROI S.A | F226: 6.2
... A411: 46099 | B411: GABRIEL VIDAL | C411: =VLOOKUP(B411,BASE_VEICULOS!A:B,2,0) -> #N/A | D411: PEDAGIO | E411: LINHA AMARELA S.A | F411: 3.8
A412: 46099 | C412: RNK | D412: PEDAGIO | E412: CONCESSIONARIA DO SISTEMA RODOVIARIO RIO SAO PAULO S.A | F412: 4.56
A413: 46099 | C413: RNK | D413: PEDAGIO | E413: CONCESSIONARIA DO SISTEMA RODOVIARIO RIO SAO PAULO S.A | F413: 4.56
A414: 46099 | B414: MANFAC-15 | C414: =VLOOKUP(B414,BASE_VEICULOS!A:B,2,0) -> TEQ2I74 | D414: PEDAGIO | E414: AUTOPISTA FLUMINENSE S.A | F414: 7.12
A415: 46099 | B415: MANFAC-15 | C415: =VLOOKUP(B415,BASE_VEICULOS!A:B,2,0) -> TEQ2I74 | D415: PEDAGIO | E415: AUTOPISTA FLUMINENSE S.A | F415: 7.12
A416: 46099 | B416: MANFAC-15 | C416: =VLOOKUP(B416,BASE_VEICULOS!A:B,2,0) -> TEQ2I74 | D416: PEDAGIO | E416: AUTOPISTA FLUMINENSE S.A | F416: 3.98
A417: 46099 | B417: MANFAC-24 | C417: =VLOOKUP(B417,BASE_VEICULOS!A:B,2,0) -> SRU8D16 | D417: PEDAGIO | E417: CONCESSIONARIA PONTE RIO NITEROI S.A | F417: 6.6
A418: 46099 | B418: MANFAC-7 | C418: =VLOOKUP(B418,BASE_VEICULOS!A:B,2,0) -> TEW9A27 | D418: PEDAGIO | E418: CONCESSIONARIA PONTE RIO NITEROI S.A | F418: 6.6
A419: 46099 | B419: REINALDO | C419: =VLOOKUP(B419,BASE_VEICULOS!A:B,2,0) -> #N/A | D419: PEDAGIO | E419: CONCESSIONARIA PONTE RIO NITEROI S.A | F419: 6.6
A420: 46099 | B420: MANFAC-19 | C420: =VLOOKUP(B420,BASE_VEICULOS!A:B,2,0) -> TEH3I02 | D420: ESTACIONAMENTO | E420: CONSORCIO PARKING NORTESHOPPING | F420: 20
A421: 46099 | B421: MANFAC-18 | C421: =VLOOKUP(B421,BASE_VEICULOS!A:B,2,0) -> TET5H37 | D421: PEDAGIO | E421: CONCESSIONARIA ECORIOMINAS | F421: 9.98
A422: 46099 | B422: MANFAC-18 | C422: =VLOOKUP(B422,BASE_VEICULOS!A:B,2,0) -> TET5H37 | D422: PEDAGIO | E422: CONCESSIONARIA DO SISTEMA RODOVIARIO RIO SAO PAULO S.A | F422: 4.56
A423: 46099 | B423: MANFAC-18 | C423: =VLOOKUP(B423,BASE_VEICULOS!A:B,2,0) -> TET5H37 | D423: PEDAGIO | E423: CONCESSIONARIA DO SISTEMA RODOVIARIO RIO SAO PAULO S.A | F423: 4.56
...

Sheet BASE_KM
A1: DATA | B1: EQUIPE | C1: KM | D1: PLACA | E1: KM RODADO
A2: 46076 | B2: MANFAC-1 | C2: 14236 | D2: =IFERROR(VLOOKUP(B2,BASE_VEICULOS!$A:$B,2,0),"") -> TEW9A25 | E2: =IFERROR(__xludf.DUMMYFUNCTION("IF(OR(A2="""",D2="""",C2=""""),"""",IFERROR(MAX(0,C2-MAX(FILTER($C$2:$C2,TRIM($D$2:$D2)=TRIM(D2),(($A$2:$A2<A2)+(($A$2:$A2=A2)*(ROW($A$2:$A2)<ROW(A2))))))),""""))"),"")
A3: 46076 | B3: MANFAC-11 | C3: 14715 | D3: =IFERROR(VLOOKUP(B3,BASE_VEICULOS!$A:$B,2,0),"") -> TEW9A24 | E3: =IFERROR(__xludf.DUMMYFUNCTION("IF(OR(A3="""",D3="""",C3=""""),"""",IFERROR(MAX(0,C3-MAX(FILTER($C$2:$C3,TRIM($D$2:$D3)=TRIM(D3),(($A$2:$A3<A3)+(($A$2:$A3=A3)*(ROW($A$2:$A3)<ROW(A3))))))),""""))"),"")
A4: 46076 | B4: MANFAC-24 | C4: 52136 | D4: =IFERROR(VLOOKUP(B4,BASE_VEICULOS!$A:$B,2,0),"") -> SRU8D16 | E4: =IFERROR(__xludf.DUMMYFUNCTION("IF(OR(A4="""",D4="""",C4=""""),"""",IFERROR(MAX(0,C4-MAX(FILTER($C$2:$C4,TRIM($D$2:$D4)=TRIM(D4),(($A$2:$A4<A4)+(($A$2:$A4=A4)*(ROW($A$2:$A4)<ROW(A4))))))),""""))"),"")
A5: 46076 | B5: MANFAC-12 | C5: 13756 | D5: =IFERROR(VLOOKUP(B5,BASE_VEICULOS!$A:$B,2,0),"") -> TEW9A34 | E5: =IFERROR(__xludf.DUMMYFUNCTION("IF(OR(A5="""",D5="""",C5=""""),"""",IFERROR(MAX(0,C5-MAX(FILTER($C$2:$C5,TRIM($D$2:$D5)=TRIM(D5),(($A$2:$A5<A5)+(($A$2:$A5=A5)*(ROW($A$2:$A5)<ROW(A5))))))),""""))"),"")
A6: 46076 | B6: MANFAC-13 | C6: 15391 | D6: =IFERROR(VLOOKUP(B6,BASE_VEICULOS!$A:$B,2,0),"") -> TEW9A33 | E6: =IFERROR(__xludf.DUMMYFUNCTION("IF(OR(A6="""",D6="""",C6=""""),"""",IFERROR(MAX(0,C6-MAX(FILTER($C$2:$C6,TRIM($D$2:$D6)=TRIM(D6),(($A$2:$A6<A6)+(($A$2:$A6=A6)*(ROW($A$2:$A6)<ROW(A6))))))),""""))"),"")
A7: 46076 | B7: MANFAC-18 | C7: 24327 | D7: =IFERROR(VLOOKUP(B7,BASE_VEICULOS!$A:$B,2,0),"") -> TET5H37 | E7: =IFERROR(__xludf.DUMMYFUNCTION("IF(OR(A7="""",D7="""",C7=""""),"""",IFERROR(MAX(0,C7-MAX(FILTER($C$2:$C7,TRIM($D$2:$D7)=TRIM(D7),(($A$2:$A7<A7)+(($A$2:$A7=A7)*(ROW($A$2:$A7)<ROW(A7))))))),""""))"),"")
A8: 46076 | B8: MANFAC-19 | C8: 14148 | D8: =IFERROR(VLOOKUP(B8,BASE_VEICULOS!$A:$B,2,0),"") -> TEH3I02 | E8: =IFERROR(__xludf.DUMMYFUNCTION("IF(OR(A8="""",D8="""",C8=""""),"""",IFERROR(MAX(0,C8-MAX(FILTER($C$2:$C8,TRIM($D$2:$D8)=TRIM(D8),(($A$2:$A8<A8)+(($A$2:$A8=A8)*(ROW($A$2:$A8)<ROW(A8))))))),""""))"),"")
A9: 46076 | B9: MANFAC-2 | C9: 93945 | D9: =IFERROR(VLOOKUP(B9,BASE_VEICULOS!$A:$B,2,0),"") -> TEW9A28 | E9: =IFERROR(__xludf.DUMMYFUNCTION("IF(OR(A9="""",D9="""",C9=""""),"""",IFERROR(MAX(0,C9-MAX(FILTER($C$2:$C9,TRIM($D$2:$D9)=TRIM(D9),(($A$2:$A9<A9)+(($A$2:$A9=A9)*(ROW($A$2:$A9)<ROW(A9))))))),""""))"),"")
A10: 46076 | B10: MANFAC-20 | C10: 16073 | D10: =IFERROR(VLOOKUP(B10,BASE_VEICULOS!$A:$B,2,0),"") | E10: =IFERROR(__xludf.DUMMYFUNCTION("IF(OR(A10="""",D10="""",C10=""""),"""",IFERROR(MAX(0,C10-MAX(FILTER($C$2:$C10,TRIM($D$2:$D10)=TRIM(D10),(($A$2:$A10<A10)+(($A$2:$A10=A10)*(ROW($A$2:$A10)<ROW(A10))))))),""""))"),"")
A11: 46076 | B11: MANFAC-21 | C11: 14187 | D11: =IFERROR(VLOOKUP(B11,BASE_VEICULOS!$A:$B,2,0),"") -> TEW9A23 | E11: =IFERROR(__xludf.DUMMYFUNCTION("IF(OR(A11="""",D11="""",C11=""""),"""",IFERROR(MAX(0,C11-MAX(FILTER($C$2:$C11,TRIM($D$2:$D11)=TRIM(D11),(($A$2:$A11<A11)+(($A$2:$A11=A11)*(ROW($A$2:$A11)<ROW(A11))))))),""""))"),"")
A12: 46076 | B12: MANFAC-22 | C12: 12552 | D12: =IFERROR(VLOOKUP(B12,BASE_VEICULOS!$A:$B,2,0),"") -> TEW9A26 | E12: =IFERROR(__xludf.DUMMYFUNCTION("IF(OR(A12="""",D12="""",C12=""""),"""",IFERROR(MAX(0,C12-MAX(FILTER($C$2:$C12,TRIM($D$2:$D12)=TRIM(D12),(($A$2:$A12<A12)+(($A$2:$A12=A12)*(ROW($A$2:$A12)<ROW(A12))))))),""""))"),"")
A13: 46076 | B13: MANFAC-23 | C13: 103981 | D13: =IFERROR(VLOOKUP(B13,BASE_VEICULOS!$A:$B,2,0),"") | E13: =IFERROR(__xludf.DUMMYFUNCTION("IF(OR(A13="""",D13="""",C13=""""),"""",IFERROR(MAX(0,C13-MAX(FILTER($C$2:$C13,TRIM($D$2:$D13)=TRIM(D13),(($A$2:$A13<A13)+(($A$2:$A13=A13)*(ROW($A$2:$A13)<ROW(A13))))))),""""))"),"")
A14: 46076 | B14: MANFAC-3 | C14: 87151 | D14: =IFERROR(VLOOKUP(B14,BASE_VEICULOS!$A:$B,2,0),"") -> FIL8C14 | E14: =IFERROR(__xludf.DUMMYFUNCTION("IF(OR(A14="""",D14="""",C14=""""),"""",IFERROR(MAX(0,C14-MAX(FILTER($C$2:$C14,TRIM($D$2:$D14)=TRIM(D14),(($A$2:$A14<A14)+(($A$2:$A14=A14)*(ROW($A$2:$A14)<ROW(A14))))))),""""))"),"")
A15: 46076 | B15: MANFAC-4 | C15: 103459 | D15: =IFERROR(VLOOKUP(B15,BASE_VEICULOS!$A:$B,2,0),"") -> FGO3C61 | E15: =IFERROR(__xludf.DUMMYFUNCTION("IF(OR(A15="""",D15="""",C15=""""),"""",IFERROR(MAX(0,C15-MAX(FILTER($C$2:$C15,TRIM($D$2:$D15)=TRIM(D15),(($A$2:$A15<A15)+(($A$2:$A15=A15)*(ROW($A$2:$A15)<ROW(A15))))))),""""))"),"")
A16: 46076 | B16: MANFAC-5 | C16: 87891 | D16: =IFERROR(VLOOKUP(B16,BASE_VEICULOS!$A:$B,2,0),"") -> FOK8A73 | E16: =IFERROR(__xludf.DUMMYFUNCTION("IF(OR(A16="""",D16="""",C16=""""),"""",IFERROR(MAX(0,C16-MAX(FILTER($C$2:$C16,TRIM($D$2:$D16)=TRIM(D16),(($A$2:$A16<A16)+(($A$2:$A16=A16)*(ROW($A$2:$A16)<ROW(A16))))))),""""))"),"")
A17: 46076 | B17: MANFAC-6 | C17: 105805 | D17: =IFERROR(VLOOKUP(B17,BASE_VEICULOS!$A:$B,2,0),"") -> EWH1B84 | E17: =IFERROR(__xludf.DUMMYFUNCTION("IF(OR(A17="""",D17="""",C17=""""),"""",IFERROR(MAX(0,C17-MAX(FILTER($C$2:$C17,TRIM($D$2:$D17)=TRIM(D17),(($A$2:$A17<A17)+(($A$2:$A17=A17)*(ROW($A$2:$A17)<ROW(A17))))))),""""))"),"")
A18: 46076 | B18: MANFAC-7 | C18: 9819 | D18: =IFERROR(VLOOKUP(B18,BASE_VEICULOS!$A:$B,2,0),"") -> TEW9A27 | E18: =IFERROR(__xludf.DUMMYFUNCTION("IF(OR(A18="""",D18="""",C18=""""),"""",IFERROR(MAX(0,C18-MAX(FILTER($C$2:$C18,TRIM($D$2:$D18)=TRIM(D18),(($A$2:$A18<A18)+(($A$2:$A18=A18)*(ROW($A$2:$A18)<ROW(A18))))))),""""))"),"")
A19: 46076 | B19: MANFAC-8 | C19: 10224 | D19: =IFERROR(VLOOKUP(B19,BASE_VEICULOS!$A:$B,2,0),"") | E19: =IFERROR(__xludf.DUMMYFUNCTION("IF(OR(A19="""",D19="""",C19=""""),"""",IFERROR(MAX(0,C19-MAX(FILTER($C$2:$C19,TRIM($D$2:$D19)=TRIM(D19),(($A$2:$A19<A19)+(($A$2:$A19=A19)*(ROW($A$2:$A19)<ROW(A19))))))),""""))"),"")
A20: 46076 | B20: MANFAC-9 | C20: 14263 | D20: =IFERROR(VLOOKUP(B20,BASE_VEICULOS!$A:$B,2,0),"") -> TEW9A29 | E20: =IFERROR(__xludf.DUMMYFUNCTION("IF(OR(A20="""",D20="""",C20=""""),"""",IFERROR(MAX(0,C20-MAX(FILTER($C$2:$C20,TRIM($D$2:$D20)=TRIM(D20),(($A$2:$A20<A20)+(($A$2:$A20=A20)*(ROW($A$2:$A20)<ROW(A20))))))),""""))"),"")
A21: 46077 | B21: MANFAC-1 | C21: 14453 | D21: =IFERROR(VLOOKUP(B21,BASE_VEICULOS!$A:$B,2,0),"") -> TEW9A25 | E21: =IFERROR(__xludf.DUMMYFUNCTION("IF(OR(A21="""",D21="""",C21=""""),"""",IFERROR(MAX(0,C21-MAX(FILTER($C$2:$C21,TRIM($D$2:$D21)=TRIM(D21),(($A$2:$A21<A21)+(($A$2:$A21=A21)*(ROW($A$2:$A21)<ROW(A21))))))),""""))"),217.0) -> 217
A22: 46077 | B22: MANFAC-11 | C22: 14822 | D22: =IFERROR(VLOOKUP(B22,BASE_VEICULOS!$A:$B,2,0),"") -> TEW9A24 | E22: =IFERROR(__xludf.DUMMYFUNCTION("IF(OR(A22="""",D22="""",C22=""""),"""",IFERROR(MAX(0,C22-MAX(FILTER($C$2:$C22,TRIM($D$2:$D22)=TRIM(D22),(($A$2:$A22<A22)+(($A$2:$A22=A22)*(ROW($A$2:$A22)<ROW(A22))))))),""""))"),107.0) -> 107
A23: 46077 | B23: MANFAC-12 | C23: 13891 | D23: =IFERROR(VLOOKUP(B23,BASE_VEICULOS!$A:$B,2,0),"") -> TEW9A34 | E23: =IFERROR(__xludf.DUMMYFUNCTION("IF(OR(A23="""",D23="""",C23=""""),"""",IFERROR(MAX(0,C23-MAX(FILTER($C$2:$C23,TRIM($D$2:$D23)=TRIM(D23),(($A$2:$A23<A23)+(($A$2:$A23=A23)*(ROW($A$2:$A23)<ROW(A23))))))),""""))"),135.0) -> 135
A24: 46077 | B24: MANFAC-13 | C24: 15463 | D24: =IFERROR(VLOOKUP(B24,BASE_VEICULOS!$A:$B,2,0),"") -> TEW9A33 | E24: =IFERROR(__xludf.DUMMYFUNCTION("IF(OR(A24="""",D24="""",C24=""""),"""",IFERROR(MAX(0,C24-MAX(FILTER($C$2:$C24,TRIM($D$2:$D24)=TRIM(D24),(($A$2:$A24<A24)+(($A$2:$A24=A24)*(ROW($A$2:$A24)<ROW(A24))))))),""""))"),72.0) -> 72
A25: 46077 | B25: MANFAC-19 | C25: 14292 | D25: =IFERROR(VLOOKUP(B25,BASE_VEICULOS!$A:$B,2,0),"") -> TEH3I02 | E25: =IFERROR(__xludf.DUMMYFUNCTION("IF(OR(A25="""",D25="""",C25=""""),"""",IFERROR(MAX(0,C25-MAX(FILTER($C$2:$C25,TRIM($D$2:$D25)=TRIM(D25),(($A$2:$A25<A25)+(($A$2:$A25=A25)*(ROW($A$2:$A25)<ROW(A25))))))),""""))"),144.0) -> 144
A26: 46077 | B26: MANFAC-20 | C26: 16186 | D26: =IFERROR(VLOOKUP(B26,BASE_VEICULOS!$A:$B,2,0),"") | E26: =IFERROR(__xludf.DUMMYFUNCTION("IF(OR(A26="""",D26="""",C26=""""),"""",IFERROR(MAX(0,C26-MAX(FILTER($C$2:$C26,TRIM($D$2:$D26)=TRIM(D26),(($A$2:$A26<A26)+(($A$2:$A26=A26)*(ROW($A$2:$A26)<ROW(A26))))))),""""))"),"")
A27: 46077 | B27: MANFAC-21 | C27: 14392 | D27: =IFERROR(VLOOKUP(B27,BASE_VEICULOS!$A:$B,2,0),"") -> TEW9A23 | E27: =IFERROR(__xludf.DUMMYFUNCTION("IF(OR(A27="""",D27="""",C27=""""),"""",IFERROR(MAX(0,C27-MAX(FILTER($C$2:$C27,TRIM($D$2:$D27)=TRIM(D27),(($A$2:$A27<A27)+(($A$2:$A27=A27)*(ROW($A$2:$A27)<ROW(A27))))))),""""))"),205.0) -> 205
A28: 46077 | B28: MANFAC-22 | C28: 12679 | D28: =IFERROR(VLOOKUP(B28,BASE_VEICULOS!$A:$B,2,0),"") -> TEW9A26 | E28: =IFERROR(__xludf.DUMMYFUNCTION("IF(OR(A28="""",D28="""",C28=""""),"""",IFERROR(MAX(0,C28-MAX(FILTER($C$2:$C28,TRIM($D$2:$D28)=TRIM(D28),(($A$2:$A28<A28)+(($A$2:$A28=A28)*(ROW($A$2:$A28)<ROW(A28))))))),""""))"),127.0) -> 127
