Workbook

Sheet RESUMO
E1: OS EXECUTADAS AGUARDANDO LIBERAÇÃO — MANFAC x DPSP
E2: Contrato DPSP Facilities | Regional RJ Zona Sul + Lagos | K2: Data-base: | L2: 46317
B5: OS AGUARDANDO LIBERAÇÃO | F5: HÁ MAIS DE 30 DIAS | J5: LIBERADO EM 21/10
B6: =D11 -> 394438.64 | F6: =D12 -> 120773.3 | J6: ='LIBERADAS 21-10'!I8 -> 20352.2
B7: =C11&" OS executadas e resolvidas no DESK" -> 76 OS executadas e resolvidas no DESK | F7: =C12&" OS em farol vermelho" -> 13 OS em farol vermelho | J7: =L11&" OS no fechamento da janela" -> 2 OS no fechamento da janela
B9: 1. VALOR AGUARDANDO LIBERAÇÃO DE PEDIDO | J9: 2. LIBERADO NO FECHAMENTO DA JANELA
B10: Situação | C10: Qtd OS | D10: Valor (R$) | F10: % do valor | J10: Data da liberação | L10: =DATE(2026,10,21) -> 46316
B11: OS executadas aguardando liberação de pedido | C11: =COUNTA(BASE!$A$6:$A$81) -> 76 | D11: =SUM(BASE!$J$6:$J$81) -> 394438.64 | F11: =D11/$D$11 -> 1 | J11: OS liberadas | L11: =COUNTA('LIBERADAS 21-10'!A6:A7) -> 2
B12: dos quais: aguardando há mais de 30 dias | C12: =SUM(C21:C23) -> 13 | D12: =SUM(D21:D23) -> 120773.3 | F12: =D12/$D$11 -> 0.30619034 | J12: Valor liberado | L12: ='LIBERADAS 21-10'!I8 -> 20352.2
B13: dos quais: aguardando há mais de 90 dias | C13: =C23 -> 6 | D13: =D23 -> 29384.55 | F13: =D13/$D$11 -> 0.074497139 | J13: % do valor pendente | L13: =L12/(L12+D11) -> 0.049066175
J14: Dias que aguardaram (média) | L14: =AVERAGE('LIBERADAS 21-10'!K6:K7) -> 137
B17: 3. HÁ QUANTO TEMPO AS OS AGUARDAM LIBERAÇÃO
B18: Faixa | C18: Qtd OS | D18: Valor (R$) | F18: % valor | G18: Farol
B19: 0–15 dias | C19: =COUNTIF(BASE!$H$6:$H$81,B19) -> 10 | D19: =SUMIF(BASE!$H$6:$H$81,B19,BASE!$J$6:$J$81) -> 47478.4 | F19: =D19/$D$25 -> 0.12036955 | G19: VERDE
B20: 16–30 dias | C20: =COUNTIF(BASE!$H$6:$H$81,B20) -> 32 | D20: =SUMIF(BASE!$H$6:$H$81,B20,BASE!$J$6:$J$81) -> 148256.32 | F20: =D20/$D$25 -> 0.37586662 | G20: AMARELO
B21: 31–60 dias | C21: =COUNTIF(BASE!$H$6:$H$81,B21) -> 4 | D21: =SUMIF(BASE!$H$6:$H$81,B21,BASE!$J$6:$J$81) -> 26600.55 | F21: =D21/$D$25 -> 0.067439006 | G21: VERMELHO
B22: 61–90 dias | C22: =COUNTIF(BASE!$H$6:$H$81,B22) -> 3 | D22: =SUMIF(BASE!$H$6:$H$81,B22,BASE!$J$6:$J$81) -> 64788.2 | F22: =D22/$D$25 -> 0.16425419 | G22: VERMELHO
B23: Acima de 90 dias | C23: =COUNTIF(BASE!$H$6:$H$81,B23) -> 6 | D23: =SUMIF(BASE!$H$6:$H$81,B23,BASE!$J$6:$J$81) -> 29384.55 | F23: =D23/$D$25 -> 0.074497139 | G23: VERMELHO
B24: Data a informar | C24: =COUNTIF(BASE!$H$6:$H$81,B24) -> 21 | D24: =SUMIF(BASE!$H$6:$H$81,B24,BASE!$J$6:$J$81) -> 77930.62 | F24: =D24/$D$25 -> 0.19757349 | G24: —
B25: TOTAL | C25: =SUM(C19:C24) -> 76 | D25: =SUM(D19:D24) -> 394438.64 | F25: =SUM(F19:F24) -> 1
B26: Aguardando há mais de 30 dias | D26: =SUM(D21:D23) -> 120773.3 | F26: =SUM(F21:F23) -> 0.30619034
B28: 4. OS AGUARDANDO LIBERAÇÃO POR ANALISTA DPSP
B29: Analista | C29: Qtd OS | D29: Valor (R$) | F29: % valor | G29: Acima de 30 dias (R$)
B30: LEANDRO | C30: =COUNTIF(BASE!$E$6:$E$81,"LEANDRO") -> 52 | D30: =SUMIF(BASE!$E$6:$E$81,"LEANDRO",BASE!$J$6:$J$81) -> 331751.59 | F30: =D30/SUM(BASE!$J$6:$J$81) -> 0.84107275 | G30: =SUMPRODUCT((BASE!$E$6:$E$81="LEANDRO")*(BASE!$I$6:$I$81="VERMELHO")*BASE!$J$6:$J$81) -> 114006.55
B31: AMANDA | C31: =COUNTIF(BASE!$E$6:$E$81,"AMANDA") -> 18 | D31: =SUMIF(BASE!$E$6:$E$81,"AMANDA",BASE!$J$6:$J$81) -> 42627.59 | F31: =D31/SUM(BASE!$J$6:$J$81) -> 0.10807154 | G31: =SUMPRODUCT((BASE!$E$6:$E$81="AMANDA")*(BASE!$I$6:$I$81="VERMELHO")*BASE!$J$6:$J$81) -> 5267.72
B32: JUAN | C32: =COUNTIF(BASE!$E$6:$E$81,"JUAN") -> 3 | D32: =SUMIF(BASE!$E$6:$E$81,"JUAN",BASE!$J$6:$J$81) -> 1999.03 | F32: =D32/SUM(BASE!$J$6:$J$81) -> 0.005068038 | G32: =SUMPRODUCT((BASE!$E$6:$E$81="JUAN")*(BASE!$I$6:$I$81="VERMELHO")*BASE!$J$6:$J$81) -> 1499.03
B33: ALINE | C33: =COUNTIF(BASE!$E$6:$E$81,"ALINE") -> 0 | D33: =SUMIF(BASE!$E$6:$E$81,"ALINE",BASE!$J$6:$J$81) -> 0 | F33: =D33/SUM(BASE!$J$6:$J$81) -> 0 | G33: =SUMPRODUCT((BASE!$E$6:$E$81="ALINE")*(BASE!$I$6:$I$81="VERMELHO")*BASE!$J$6:$J$81) -> 0
B34: (não informado) | C34: =COUNTIF(BASE!$E$6:$E$81,"—") -> 3 | D34: =SUMIF(BASE!$E$6:$E$81,"—",BASE!$J$6:$J$81) -> 18060.43 | F34: =D34/SUM(BASE!$J$6:$J$81) -> 0.045787679 | G34: =SUMPRODUCT((BASE!$E$6:$E$81="—")*(BASE!$I$6:$I$81="VERMELHO")*BASE!$J$6:$J$81) -> 0
B35: TOTAL | C35: =SUM(C30:C34) -> 76 | D35: =SUM(D30:D34) -> 394438.64 | F35: =SUM(F30:F34) -> 1 | G35: =SUM(G30:G34) -> 120773.3
B37: 5. AS 10 OS HÁ MAIS TEMPO AGUARDANDO LIBERAÇÃO
B38: OS · Loja | C38: Tipo | D38: Analista | F38: Finalização | G38: Dias aguardando | H38: Farol | J38: Valor (R$)
B39: =N39&" · "&INDEX(BASE!$B$6:$B$81,MATCH($N39,BASE!$A$6:$A$81,0)) -> 1125-016236 · DP MACAE 3 | C39: =INDEX(BASE!$C$6:$C$81,MATCH($N39,BASE!$A$6:$A$81,0)) -> NOBREAK | D39: =INDEX(BASE!$E$6:$E$81,MATCH($N39,BASE!$A$6:$A$81,0)) -> LEANDRO | F39: =INDEX(BASE!$F$6:$F$81,MATCH($N39,BASE!$A$6:$A$81,0)) -> 46113 | G39: =INDEX(BASE!$G$6:$G$81,MATCH($N39,BASE!$A$6:$A$81,0)) -> 204 | H39: =INDEX(BASE!$I$6:$I$81,MATCH($N39,BASE!$A$6:$A$81,0)) -> VERMELHO | J39: =INDEX(BASE!$J$6:$J$81,MATCH($N39,BASE!$A$6:$A$81,0)) -> 8975.81 | N39: 1125-016236
B40: =N40&" · "&INDEX(BASE!$B$6:$B$81,MATCH($N40,BASE!$A$6:$A$81,0)) -> #N/A | C40: =INDEX(BASE!$C$6:$C$81,MATCH($N40,BASE!$A$6:$A$81,0)) -> #N/A | D40: =INDEX(BASE!$E$6:$E$81,MATCH($N40,BASE!$A$6:$A$81,0)) -> #N/A | F40: =INDEX(BASE!$F$6:$F$81,MATCH($N40,BASE!$A$6:$A$81,0)) -> #N/A | G40: =INDEX(BASE!$G$6:$G$81,MATCH($N40,BASE!$A$6:$A$81,0)) -> #N/A | H40: =INDEX(BASE!$I$6:$I$81,MATCH($N40,BASE!$A$6:$A$81,0)) -> #N/A | J40: =INDEX(BASE!$J$6:$J$81,MATCH($N40,BASE!$A$6:$A$81,0)) -> #N/A | N40: 1125-015968
B41: =N41&" · "&INDEX(BASE!$B$6:$B$81,MATCH($N41,BASE!$A$6:$A$81,0)) -> 0326-009215 · DP GLORIA | C41: =INDEX(BASE!$C$6:$C$81,MATCH($N41,BASE!$A$6:$A$81,0)) -> ELETRICA | D41: =INDEX(BASE!$E$6:$E$81,MATCH($N41,BASE!$A$6:$A$81,0)) -> LEANDRO | F41: =INDEX(BASE!$F$6:$F$81,MATCH($N41,BASE!$A$6:$A$81,0)) -> 46135 | G41: =INDEX(BASE!$G$6:$G$81,MATCH($N41,BASE!$A$6:$A$81,0)) -> 182 | H41: =INDEX(BASE!$I$6:$I$81,MATCH($N41,BASE!$A$6:$A$81,0)) -> VERMELHO | J41: =INDEX(BASE!$J$6:$J$81,MATCH($N41,BASE!$A$6:$A$81,0)) -> 786.06 | N41: 0326-009215
B42: =N42&" · "&INDEX(BASE!$B$6:$B$81,MATCH($N42,BASE!$A$6:$A$81,0)) -> #N/A | C42: =INDEX(BASE!$C$6:$C$81,MATCH($N42,BASE!$A$6:$A$81,0)) -> #N/A | D42: =INDEX(BASE!$E$6:$E$81,MATCH($N42,BASE!$A$6:$A$81,0)) -> #N/A | F42: =INDEX(BASE!$F$6:$F$81,MATCH($N42,BASE!$A$6:$A$81,0)) -> #N/A | G42: =INDEX(BASE!$G$6:$G$81,MATCH($N42,BASE!$A$6:$A$81,0)) -> #N/A | H42: =INDEX(BASE!$I$6:$I$81,MATCH($N42,BASE!$A$6:$A$81,0)) -> #N/A | J42: =INDEX(BASE!$J$6:$J$81,MATCH($N42,BASE!$A$6:$A$81,0)) -> #N/A | N42: 0426-016931
B43: =N43&" · "&INDEX(BASE!$B$6:$B$81,MATCH($N43,BASE!$A$6:$A$81,0)) -> #N/A | C43: =INDEX(BASE!$C$6:$C$81,MATCH($N43,BASE!$A$6:$A$81,0)) -> #N/A | D43: =INDEX(BASE!$E$6:$E$81,MATCH($N43,BASE!$A$6:$A$81,0)) -> #N/A | F43: =INDEX(BASE!$F$6:$F$81,MATCH($N43,BASE!$A$6:$A$81,0)) -> #N/A | G43: =INDEX(BASE!$G$6:$G$81,MATCH($N43,BASE!$A$6:$A$81,0)) -> #N/A | H43: =INDEX(BASE!$I$6:$I$81,MATCH($N43,BASE!$A$6:$A$81,0)) -> #N/A | J43: =INDEX(BASE!$J$6:$J$81,MATCH($N43,BASE!$A$6:$A$81,0)) -> #N/A | N43: 0426-016925
B44: =N44&" · "&INDEX(BASE!$B$6:$B$81,MATCH($N44,BASE!$A$6:$A$81,0)) -> 1125-010536 · DP BARRA DA TIJUCA 8 | C44: =INDEX(BASE!$C$6:$C$81,MATCH($N44,BASE!$A$6:$A$81,0)) -> TELHADO | D44: =INDEX(BASE!$E$6:$E$81,MATCH($N44,BASE!$A$6:$A$81,0)) -> LEANDRO | F44: =INDEX(BASE!$F$6:$F$81,MATCH($N44,BASE!$A$6:$A$81,0)) -> 46164 | G44: =INDEX(BASE!$G$6:$G$81,MATCH($N44,BASE!$A$6:$A$81,0)) -> 153 | H44: =INDEX(BASE!$I$6:$I$81,MATCH($N44,BASE!$A$6:$A$81,0)) -> VERMELHO | J44: =INDEX(BASE!$J$6:$J$81,MATCH($N44,BASE!$A$6:$A$81,0)) -> 1961.4 | N44: 1125-010536
B45: =N45&" · "&INDEX(BASE!$B$6:$B$81,MATCH($N45,BASE!$A$6:$A$81,0)) -> 0326-012395 · DP SENADOR DANTAS 2 | C45: =INDEX(BASE!$C$6:$C$81,MATCH($N45,BASE!$A$6:$A$81,0)) -> CIVIL | D45: =INDEX(BASE!$E$6:$E$81,MATCH($N45,BASE!$A$6:$A$81,0)) -> LEANDRO | F45: =INDEX(BASE!$F$6:$F$81,MATCH($N45,BASE!$A$6:$A$81,0)) -> 46178 | G45: =INDEX(BASE!$G$6:$G$81,MATCH($N45,BASE!$A$6:$A$81,0)) -> 139 | H45: =INDEX(BASE!$I$6:$I$81,MATCH($N45,BASE!$A$6:$A$81,0)) -> VERMELHO | J45: =INDEX(BASE!$J$6:$J$81,MATCH($N45,BASE!$A$6:$A$81,0)) -> 1519.42 | N45: 0326-012395
B46: =N46&" · "&INDEX(BASE!$B$6:$B$81,MATCH($N46,BASE!$A$6:$A$81,0)) -> 0526-019340 · DP PADRE MIGUEL | C46: =INDEX(BASE!$C$6:$C$81,MATCH($N46,BASE!$A$6:$A$81,0)) -> CIVIL | D46: =INDEX(BASE!$E$6:$E$81,MATCH($N46,BASE!$A$6:$A$81,0)) -> JUAN | F46: =INDEX(BASE!$F$6:$F$81,MATCH($N46,BASE!$A$6:$A$81,0)) -> 46184 | G46: =INDEX(BASE!$G$6:$G$81,MATCH($N46,BASE!$A$6:$A$81,0)) -> 133 | H46: =INDEX(BASE!$I$6:$I$81,MATCH($N46,BASE!$A$6:$A$81,0)) -> VERMELHO | J46: =INDEX(BASE!$J$6:$J$81,MATCH($N46,BASE!$A$6:$A$81,0)) -> 500.63 | N46: 0526-019340
B47: =N47&" · "&INDEX(BASE!$B$6:$B$81,MATCH($N47,BASE!$A$6:$A$81,0)) -> #N/A | C47: =INDEX(BASE!$C$6:$C$81,MATCH($N47,BASE!$A$6:$A$81,0)) -> #N/A | D47: =INDEX(BASE!$E$6:$E$81,MATCH($N47,BASE!$A$6:$A$81,0)) -> #N/A | F47: =INDEX(BASE!$F$6:$F$81,MATCH($N47,BASE!$A$6:$A$81,0)) -> #N/A | G47: =INDEX(BASE!$G$6:$G$81,MATCH($N47,BASE!$A$6:$A$81,0)) -> #N/A | H47: =INDEX(BASE!$I$6:$I$81,MATCH($N47,BASE!$A$6:$A$81,0)) -> #N/A | J47: =INDEX(BASE!$J$6:$J$81,MATCH($N47,BASE!$A$6:$A$81,0)) -> #N/A | N47: 0526-013810
...

Sheet BASE
E1: BASE — OS EXECUTADAS AGUARDANDO LIBERAÇÃO DE PEDIDO
E2: Serviços finalizados pela MANFAC e resolvidos no DESK, aguardando liberação de pedido/folha pela DPSP | Regional RJ Zona Sul + Lagos
A5: Nº OS | B5: Loja | C5: Tipo | D5: Descrição do chamado | E5: Analista DPSP | F5: Data finalização | G5: Dias aguardando | H5: Faixa | I5: Farol | J5: Valor (R$) | K5: Status obra | L5: Status DESK | M5: DPSP | N5: STATUS | O5: COMPETÊNCIA | P5: obs
A6: 1125-016236 | B6: DP MACAE 3 | C6: NOBREAK | D6: Escopo Base - Adequação Elétrica para Nobreak 6kva-Itens que serão alimentados pelo quadro de emergência: 100% dos computadores da loja e dispositivos de TI (impressoras, tira teima, ponto eletrônico e servidor), geladeira de medicamento, câmeras + rack/servidor de CFTV e Parte da iluminação (definir com analista a quantidade de luminárias)-Remanejamento de circuitos para quadro de emergência com chave reversora que será alimentado pelo nobreak-Instalação de quadro bypass -Instalação e Balanceamento de cargas no quadro bypass e emergência-Verificar se as geladeiras, Kibon, Redbull estão no mesmo circuito do caixa.. caso contrário, criar um circuito independente | E6: LEANDRO | F6: 46113 | G6: =IF(F6="","",RESUMO!$L$2-F6) -> 204 | H6: =IF(F6="","Data a informar",IF(G6<=15,"0–15 dias",IF(G6<=30,"16–30 dias",IF(G6<=60,"31–60 dias",IF(G6<=90,"61–90 dias","Acima de 90 dias"))))) -> Acima de 90 dias | I6: =IF(F6="","—",IF(G6<=15,"VERDE",IF(G6<=30,"AMARELO","VERMELHO"))) -> VERMELHO | J6: 8975.81 | K6: FINALIZADO | L6: Resolvido | M6: Em processo de liberação interna | N6: EXECUTADO | O6: 9 | P6: LIBERAÇÃO NOV
A7: 0326-009215 | B7: DP GLORIA | C7: ELETRICA | D7: Solicito instalação de uma tomada 220:v na cozinha, pois estamos usando o microondas emprestado de outra filial na sala de treinamentos porque não tem tomada 220v na cozinha da filial. | E7: LEANDRO | F7: 46135 | G7: =IF(F7="","",RESUMO!$L$2-F7) -> 182 | H7: =IF(F7="","Data a informar",IF(G7<=15,"0–15 dias",IF(G7<=30,"16–30 dias",IF(G7<=60,"31–60 dias",IF(G7<=90,"61–90 dias","Acima de 90 dias"))))) -> Acima de 90 dias | I7: =IF(F7="","—",IF(G7<=15,"VERDE",IF(G7<=30,"AMARELO","VERMELHO"))) -> VERMELHO | J7: 786.06 | K7: FINALIZADO | L7: Resolvido | M7: Validar com analista de campo | N7: 0 | O7: 12 | P7: competências futuras
A8: 1125-010536 | B8: DP BARRA DA TIJUCA 8 | C8: TELHADO | D8: Forro soltando com o vento causando danos na estrutura da loja | E8: LEANDRO | F8: 46164 | G8: =IF(F8="","",RESUMO!$L$2-F8) -> 153 | H8: =IF(F8="","Data a informar",IF(G8<=15,"0–15 dias",IF(G8<=30,"16–30 dias",IF(G8<=60,"31–60 dias",IF(G8<=90,"61–90 dias","Acima de 90 dias"))))) -> Acima de 90 dias | I8: =IF(F8="","—",IF(G8<=15,"VERDE",IF(G8<=30,"AMARELO","VERMELHO"))) -> VERMELHO | J8: 1961.4 | K8: FINALIZADO | L8: Resolvido | M8: 01/11 - liberação de faturamento | N8: CANCELADO | O8: 4 | P8: Alinha a demanda com o analista
A9: 0326-012395 | B9: DP SENADOR DANTAS 2 | C9: CIVIL | D9: SOLICITO AJUDA COM FIXAÇÃO DE UM PROJETOR E TELA QUE TEMOS NO POLO SENAOR DANTAS O PROJETOR NO TETO E A TELA DE PROJEÇÃO TAMBEM NO TETO. | E9: LEANDRO | F9: 46178 | G9: =IF(F9="","",RESUMO!$L$2-F9) -> 139 | H9: =IF(F9="","Data a informar",IF(G9<=15,"0–15 dias",IF(G9<=30,"16–30 dias",IF(G9<=60,"31–60 dias",IF(G9<=90,"61–90 dias","Acima de 90 dias"))))) -> Acima de 90 dias | I9: =IF(F9="","—",IF(G9<=15,"VERDE",IF(G9<=30,"AMARELO","VERMELHO"))) -> VERMELHO | J9: 1519.42 | K9: FINALIZADO | L9: Resolvido | M9: Validar com analista de campo | N9: 0 | O9: 12 | P9: competências futuras
A10: 0526-019340 | B10: DP PADRE MIGUEL | C10: CIVIL | D10: FIXAÇÃO DE 08 BRAÇO DE MONITOR DO CAIXA E BALCÃO DE MEDICAMENTO | E10: JUAN | F10: 46184 | G10: =IF(F10="","",RESUMO!$L$2-F10) -> 133 | H10: =IF(F10="","Data a informar",IF(G10<=15,"0–15 dias",IF(G10<=30,"16–30 dias",IF(G10<=60,"31–60 dias",IF(G10<=90,"61–90 dias","Acima de 90 dias"))))) -> Acima de 90 dias | I10: =IF(F10="","—",IF(G10<=15,"VERDE",IF(G10<=30,"AMARELO","VERMELHO"))) -> VERMELHO | J10: 500.63 | K10: FINALIZADO | L10: Resolvido | M10: Em processo de liberação interna | N10: EXECUTADO | O10: 12 | P10: competências futuras
A11: 0426-012516 | B11: DP MACAE 2 | C11: CAPEX | D11: Mão de obra para reforma Light | E11: LEANDRO | F11: 46201 | G11: =IF(F11="","",RESUMO!$L$2-F11) -> 116 | H11: =IF(F11="","Data a informar",IF(G11<=15,"0–15 dias",IF(G11<=30,"16–30 dias",IF(G11<=60,"31–60 dias",IF(G11<=90,"61–90 dias","Acima de 90 dias"))))) -> Acima de 90 dias | I11: =IF(F11="","—",IF(G11<=15,"VERDE",IF(G11<=30,"AMARELO","VERMELHO"))) -> VERMELHO | J11: 15641.23 | K11: FINALIZADO | L11: Resolvido | M11: 01/11 - liberação de faturamento | N11: EXECUTADO | O11: Reforma Light | P11: LIBERAÇÃO NOV
A12: 0626-005880 | B12: DP BARRA DA TIJUCA 10 | C12: CIVIL | D12: Mão de obra para pintura da fachada. | E12: LEANDRO | F12: 46241 | G12: =IF(F12="","",RESUMO!$L$2-F12) -> 76 | H12: =IF(F12="","Data a informar",IF(G12<=15,"0–15 dias",IF(G12<=30,"16–30 dias",IF(G12<=60,"31–60 dias",IF(G12<=90,"61–90 dias","Acima de 90 dias"))))) -> 61–90 dias | I12: =IF(F12="","—",IF(G12<=15,"VERDE",IF(G12<=30,"AMARELO","VERMELHO"))) -> VERMELHO | J12: 34078.2 | K12: FINALIZADO | L12: Resolvido | M12: Em processo de liberação interna | N12: EXECUTADO | O12: 8 | P12: LIBERAÇÃO NOV
A13: 0726-009420 | B13: DP RECREIO 1 | C13: TRANSPORTE | D13: remoção de entulho | E13: JUAN | F13: 46252 | G13: =IF(F13="","",RESUMO!$L$2-F13) -> 65 | H13: =IF(F13="","Data a informar",IF(G13<=15,"0–15 dias",IF(G13<=30,"16–30 dias",IF(G13<=60,"31–60 dias",IF(G13<=90,"61–90 dias","Acima de 90 dias"))))) -> 61–90 dias | I13: =IF(F13="","—",IF(G13<=15,"VERDE",IF(G13<=30,"AMARELO","VERMELHO"))) -> VERMELHO | J13: 998.4 | K13: FINALIZADO | L13: Resolvido | M13: Em processo de liberação interna | N13: EXECUTADO | O13: 9 | P13: LIBERAÇÃO NOV
A14: 0726-011532 | B14: DPA BARRA DA TIJUCA 6 | C14: CIVIL | D14: Mão de obra para pintura da fachada. | E14: LEANDRO | F14: 46254 | G14: =IF(F14="","",RESUMO!$L$2-F14) -> 63 | H14: =IF(F14="","Data a informar",IF(G14<=15,"0–15 dias",IF(G14<=30,"16–30 dias",IF(G14<=60,"31–60 dias",IF(G14<=90,"61–90 dias","Acima de 90 dias"))))) -> 61–90 dias | I14: =IF(F14="","—",IF(G14<=15,"VERDE",IF(G14<=30,"AMARELO","VERMELHO"))) -> VERMELHO | J14: 29711.6 | K14: FINALIZADO | L14: Resolvido | M14: Em processo de liberação interna | N14: EXECUTADO | O14: 7 | P14: LIBERAÇÃO NOV
A15: 0826-006388 | B15: DP LEME | C15: TELHADO | D15: Solicito bandejamento em vários pontos da área de vendas. | E15: LEANDRO | F15: 46279 | G15: =IF(F15="","",RESUMO!$L$2-F15) -> 38 | H15: =IF(F15="","Data a informar",IF(G15<=15,"0–15 dias",IF(G15<=30,"16–30 dias",IF(G15<=60,"31–60 dias",IF(G15<=90,"61–90 dias","Acima de 90 dias"))))) -> 31–60 dias | I15: =IF(F15="","—",IF(G15<=15,"VERDE",IF(G15<=30,"AMARELO","VERMELHO"))) -> VERMELHO | J15: 13436.9 | K15: FINALIZADO | L15: Resolvido | M15: NF 1457 | N15: CANCELADO | O15: 9 | P15: Alinha a demanda com o analista
A16: 0226-011338 | B16: DP MARICA 1 | C16: CIVIL | D16: Solicito a tapagem,de um buraco que temos no segundo estoque e atrás do paredao de Dermo. Buraco do palco,pois estamos enfrentando problemas com ratazanas.. Loja precisando de desratização, além dessa tapagem. | E16: AMANDA | F16: 46280 | G16: =IF(F16="","",RESUMO!$L$2-F16) -> 37 | H16: =IF(F16="","Data a informar",IF(G16<=15,"0–15 dias",IF(G16<=30,"16–30 dias",IF(G16<=60,"31–60 dias",IF(G16<=90,"61–90 dias","Acima de 90 dias"))))) -> 31–60 dias | I16: =IF(F16="","—",IF(G16<=15,"VERDE",IF(G16<=30,"AMARELO","VERMELHO"))) -> VERMELHO | J16: 5267.72 | K16: FINALIZADO | L16: Resolvido | M16: Em processo de liberação interna | N16: EXECUTADO | O16: 10 | P16: LIBERAÇÃO NOV
A17: 0526-016397 | B17: DP MACAE 2 | C17: CAPEX | D17: Troca do forro da marquise. ( Aditivo) | E17: LEANDRO | F17: 46283 | G17: =IF(F17="","",RESUMO!$L$2-F17) -> 34 | H17: =IF(F17="","Data a informar",IF(G17<=15,"0–15 dias",IF(G17<=30,"16–30 dias",IF(G17<=60,"31–60 dias",IF(G17<=90,"61–90 dias","Acima de 90 dias"))))) -> 31–60 dias | I17: =IF(F17="","—",IF(G17<=15,"VERDE",IF(G17<=30,"AMARELO","VERMELHO"))) -> VERMELHO | J17: 7495.93 | K17: FINALIZADO | L17: Resolvido | M17: NF 1377 | N17: EXECUTADO | O17: Reforma Light | P17: PAG 30/10
A18: 0626-012206 | B18: DP SENADOR DANTAS 1 | C18: SERRALHERIA | D18: Solicito substituição da fechadura de 05 armários do PC pois as mesmas estão com defeito. | E18: LEANDRO | F18: 46283 | G18: =IF(F18="","",RESUMO!$L$2-F18) -> 34 | H18: =IF(F18="","Data a informar",IF(G18<=15,"0–15 dias",IF(G18<=30,"16–30 dias",IF(G18<=60,"31–60 dias",IF(G18<=90,"61–90 dias","Acima de 90 dias"))))) -> 31–60 dias | I18: =IF(F18="","—",IF(G18<=15,"VERDE",IF(G18<=30,"AMARELO","VERMELHO"))) -> VERMELHO | J18: 400 | K18: FINALIZADO | L18: Resolvido | M18: Validar com analista de campo | N18: 0 | O18: 12 | P18: competências futuras
A19: 0926-010494 | B19: DP COPACABANA 12 | C19: HIDRAULICA | D19: Troca das 3 tampas de esgoto. | E19: LEANDRO | F19: 46289 | G19: =IF(F19="","",RESUMO!$L$2-F19) -> 28 | H19: =IF(F19="","Data a informar",IF(G19<=15,"0–15 dias",IF(G19<=30,"16–30 dias",IF(G19<=60,"31–60 dias",IF(G19<=90,"61–90 dias","Acima de 90 dias"))))) -> 16–30 dias | I19: =IF(F19="","—",IF(G19<=15,"VERDE",IF(G19<=30,"AMARELO","VERMELHO"))) -> AMARELO | J19: 1140.01 | K19: FINALIZADO | L19: Resolvido | M19: Em processo de liberação interna | N19: EXECUTADO | O19: 10 | P19: LIBERAÇÃO NOV
A20: 0726-018016 | B20: DP ICARAI 5 | C20: ELETRICA | D20: Solicito instalação de um novo ponto de tomada na voltagem 110. para a instalação de um novo refrigerador. | E20: AMANDA | F20: 46289 | G20: =IF(F20="","",RESUMO!$L$2-F20) -> 28 | H20: =IF(F20="","Data a informar",IF(G20<=15,"0–15 dias",IF(G20<=30,"16–30 dias",IF(G20<=60,"31–60 dias",IF(G20<=90,"61–90 dias","Acima de 90 dias"))))) -> 16–30 dias | I20: =IF(F20="","—",IF(G20<=15,"VERDE",IF(G20<=30,"AMARELO","VERMELHO"))) -> AMARELO | J20: 207 | K20: FINALIZADO | L20: Resolvido | M20: Em processo de liberação interna | N20: PENDENTE | O20: 10 | P20: Pendente - Liberação analista
A21: 0226-011039 | B21: DP SAO GONCALO 1 | C21: SERRALHERIA | D21: Na abertura de loja do dia 17/02/2026 o funcionário se confundiu com as chaves e tentou destrancar o tambor da porta 4 (porta de vitrine) com a chave da trava, quebrando a chave ao meio e permanecendo a metade da chave dentro do tambor, impossibilitando a abertura da porta. Solicitamos manutenção no tambor para realizarmos a abertura da loja normalmente. | E21: AMANDA | F21: 46289 | G21: =IF(F21="","",RESUMO!$L$2-F21) -> 28 | H21: =IF(F21="","Data a informar",IF(G21<=15,"0–15 dias",IF(G21<=30,"16–30 dias",IF(G21<=60,"31–60 dias",IF(G21<=90,"61–90 dias","Acima de 90 dias"))))) -> 16–30 dias | I21: =IF(F21="","—",IF(G21<=15,"VERDE",IF(G21<=30,"AMARELO","VERMELHO"))) -> AMARELO | J21: 175.66 | K21: FINALIZADO | L21: Resolvido | M21: Em processo de liberação interna | N21: EXECUTADO | O21: 10 | P21: LIBERAÇÃO NOV
A22: 0326-018781 | B22: DP SAO GONCALO 1 | C22: SERRALHERIA | D22: Chave tambor 4 quebrada | E22: AMANDA | F22: 46289 | G22: =IF(F22="","",RESUMO!$L$2-F22) -> 28 | H22: =IF(F22="","Data a informar",IF(G22<=15,"0–15 dias",IF(G22<=30,"16–30 dias",IF(G22<=60,"31–60 dias",IF(G22<=90,"61–90 dias","Acima de 90 dias"))))) -> 16–30 dias | I22: =IF(F22="","—",IF(G22<=15,"VERDE",IF(G22<=30,"AMARELO","VERMELHO"))) -> AMARELO | J22: 175.66 | K22: FINALIZADO | L22: Resolvido | M22: Em processo de liberação interna | N22: EXECUTADO | O22: 10 | P22: LIBERAÇÃO NOV
A23: 0426-017866 | B23: DP SAO GONCALO 1 | C23: SERRALHERIA | D23: Cheve do tambor quebrada antes de abrir a porta | E23: AMANDA | F23: 46289 | G23: =IF(F23="","",RESUMO!$L$2-F23) -> 28 | H23: =IF(F23="","Data a informar",IF(G23<=15,"0–15 dias",IF(G23<=30,"16–30 dias",IF(G23<=60,"31–60 dias",IF(G23<=90,"61–90 dias","Acima de 90 dias"))))) -> 16–30 dias | I23: =IF(F23="","—",IF(G23<=15,"VERDE",IF(G23<=30,"AMARELO","VERMELHO"))) -> AMARELO | J23: 175.66 | K23: FINALIZADO | L23: Resolvido | M23: Em processo de liberação interna | N23: EXECUTADO | O23: 10 | P23: LIBERAÇÃO NOV
A24: 0526-008051 | B24: DP SAO GONCALO 3 | C24: SERRALHERIA | D24: Solicito conserto na porta principal de aço. Chave quebrada na abertura de loja | E24: AMANDA | F24: 46289 | G24: =IF(F24="","",RESUMO!$L$2-F24) -> 28 | H24: =IF(F24="","Data a informar",IF(G24<=15,"0–15 dias",IF(G24<=30,"16–30 dias",IF(G24<=60,"31–60 dias",IF(G24<=90,"61–90 dias","Acima de 90 dias"))))) -> 16–30 dias | I24: =IF(F24="","—",IF(G24<=15,"VERDE",IF(G24<=30,"AMARELO","VERMELHO"))) -> AMARELO | J24: 175.66 | K24: FINALIZADO | L24: Resolvido | M24: Em processo de liberação interna | N24: EXECUTADO | O24: 10 | P24: LIBERAÇÃO NOV
A25: 0526-013041 | B25: DP RIO BONITO | C25: SERRALHERIA | D25: Bom dia, solicito ajuda para portado meio de loja quebrada, sem conseguir abrir | E25: AMANDA | F25: 46289 | G25: =IF(F25="","",RESUMO!$L$2-F25) -> 28 | H25: =IF(F25="","Data a informar",IF(G25<=15,"0–15 dias",IF(G25<=30,"16–30 dias",IF(G25<=60,"31–60 dias",IF(G25<=90,"61–90 dias","Acima de 90 dias"))))) -> 16–30 dias | I25: =IF(F25="","—",IF(G25<=15,"VERDE",IF(G25<=30,"AMARELO","VERMELHO"))) -> AMARELO | J25: 175.66 | K25: FINALIZADO | L25: Resolvido | M25: Em processo de liberação interna | N25: EXECUTADO | O25: 10 | P25: LIBERAÇÃO NOV
A26: 0826-011936 | B26: DP BACAXA | C26: SERRALHERIA | D26: bom dia solicito suporte urgente para a troca do tambor da porta de entrada, a chave quebrou dentro do tambor impossibilitando a abertura da porta | E26: LEANDRO | F26: 46289 | G26: =IF(F26="","",RESUMO!$L$2-F26) -> 28 | H26: =IF(F26="","Data a informar",IF(G26<=15,"0–15 dias",IF(G26<=30,"16–30 dias",IF(G26<=60,"31–60 dias",IF(G26<=90,"61–90 dias","Acima de 90 dias"))))) -> 16–30 dias | I26: =IF(F26="","—",IF(G26<=15,"VERDE",IF(G26<=30,"AMARELO","VERMELHO"))) -> AMARELO | J26: 175.66 | K26: FINALIZADO | L26: Resolvido | M26: Em processo de liberação interna | N26: EXECUTADO | O26: 10 | P26: LIBERAÇÃO NOV
A27: 0826-011526 | B27: DP BARRA DA TIJUCA 5 | C27: CIVIL | D27: Pintura da fachada. | E27: LEANDRO | F27: 46292 | G27: =IF(F27="","",RESUMO!$L$2-F27) -> 25 | H27: =IF(F27="","Data a informar",IF(G27<=15,"0–15 dias",IF(G27<=30,"16–30 dias",IF(G27<=60,"31–60 dias",IF(G27<=90,"61–90 dias","Acima de 90 dias"))))) -> 16–30 dias | I27: =IF(F27="","—",IF(G27<=15,"VERDE",IF(G27<=30,"AMARELO","VERMELHO"))) -> AMARELO | J27: 38999.2 | K27: FINALIZADO | L27: Resolvido | M27: Em processo de liberação interna | N27: EXECUTADO | O27: 8 | P27: LIBERAÇÃO NOV
A28: 0626-004592 | B28: DP IPANEMA 1 | C28: ELETRICA | D28: Boa tarde! Solicito a instalação de um novo ponto de tomada para a instalação da geladeira de medicamentos | E28: LEANDRO | F28: 46292 | G28: =IF(F28="","",RESUMO!$L$2-F28) -> 25 | H28: =IF(F28="","Data a informar",IF(G28<=15,"0–15 dias",IF(G28<=30,"16–30 dias",IF(G28<=60,"31–60 dias",IF(G28<=90,"61–90 dias","Acima de 90 dias"))))) -> 16–30 dias | I28: =IF(F28="","—",IF(G28<=15,"VERDE",IF(G28<=30,"AMARELO","VERMELHO"))) -> AMARELO | J28: 1599.18 | K28: FINALIZADO | L28: Resolvido | M28: Em processo de liberação interna | N28: PENDENTE | O28: 9 | P28: Pendente - Liberação analista
A29: 0626-006632 | B29: DP CATETE 3 | C29: SERRALHERIA | D29: Bom dia, tudo bem? Solicito a vinda de um técnico urgentemente em loja, pois a chave quebrou dentro do tambor e não temos a cópia. Att, Gerência. | E29: LEANDRO | F29: 46292 | G29: =IF(F29="","",RESUMO!$L$2-F29) -> 25 | H29: =IF(F29="","Data a informar",IF(G29<=15,"0–15 dias",IF(G29<=30,"16–30 dias",IF(G29<=60,"31–60 dias",IF(G29<=90,"61–90 dias","Acima de 90 dias"))))) -> 16–30 dias | I29: =IF(F29="","—",IF(G29<=15,"VERDE",IF(G29<=30,"AMARELO","VERMELHO"))) -> AMARELO | J29: 175.66 | K29: FINALIZADO | L29: Resolvido | M29: Em processo de liberação interna | N29: EXECUTADO | O29: 10 | P29: LIBERAÇÃO NOV
A30: 0826-004733 | B30: DP CATETE 2 | C30: CIVIL | D30: Solicito a pintura das fachadas laterais, o reparo das escadas e a pintura do piso. | E30: LEANDRO | F30: 46293 | G30: =IF(F30="","",RESUMO!$L$2-F30) -> 24 | H30: =IF(F30="","Data a informar",IF(G30<=15,"0–15 dias",IF(G30<=30,"16–30 dias",IF(G30<=60,"31–60 dias",IF(G30<=90,"61–90 dias","Acima de 90 dias"))))) -> 16–30 dias | I30: =IF(F30="","—",IF(G30<=15,"VERDE",IF(G30<=30,"AMARELO","VERMELHO"))) -> AMARELO | J30: 29636.94 | K30: FINALIZADO | L30: Resolvido | M30: Em processo de liberação interna | N30: EXECUTADO | O30: 10 | P30: LIBERAÇÃO NOV
... A60: 0926-010500 | B60: DP COPACABANA 12 | C60: TELHADO | D60: Troca da estrutura metálica do telhado. | E60: LEANDRO | F60: 46310 | G60: =IF(F60="","",RESUMO!$L$2-F60) -> 7 | H60: =IF(F60="","Data a informar",IF(G60<=15,"0–15 dias",IF(G60<=30,"16–30 dias",IF(G60<=60,"31–60 dias",IF(G60<=90,"61–90 dias","Acima de 90 dias"))))) -> 0–15 dias | I60: =IF(F60="","—",IF(G60<=15,"VERDE",IF(G60<=30,"AMARELO","VERMELHO"))) -> VERDE | J60: 3674.37 | K60: FINALIZADO | L60: Resolvido | M60: Em processo de liberação interna | N60: EXECUTADO | O60: 10 | P60: LIBERAÇÃO NOV
A61: 0926-014271 | B61: DP BARRA DE SAO JOAO | C61: CIVIL | D61: PINTURA DA FACHADA CAMINHO DO CLIENTE. | E61: LEANDRO | G61: =IF(F61="","",RESUMO!$L$2-F61) | H61: =IF(F61="","Data a informar",IF(G61<=15,"0–15 dias",IF(G61<=30,"16–30 dias",IF(G61<=60,"31–60 dias",IF(G61<=90,"61–90 dias","Acima de 90 dias"))))) -> Data a informar | I61: =IF(F61="","—",IF(G61<=15,"VERDE",IF(G61<=30,"AMARELO","VERMELHO"))) -> — | J61: 32272.77 | K61: FINALIZADO | L61: Resolvido | M61: Em processo de liberação interna | N61: EXECUTADO | O61: 8 | P61: LIBERAÇÃO NOV
A62: 0926-010665 | B62: DP COPACABANA 16 | C62: CIVIL | D62: Solicito pintura da fachada. (Caminho do cliente) | E62: LEANDRO | G62: =IF(F62="","",RESUMO!$L$2-F62) | H62: =IF(F62="","Data a informar",IF(G62<=15,"0–15 dias",IF(G62<=30,"16–30 dias",IF(G62<=60,"31–60 dias",IF(G62<=90,"61–90 dias","Acima de 90 dias"))))) -> Data a informar | I62: =IF(F62="","—",IF(G62<=15,"VERDE",IF(G62<=30,"AMARELO","VERMELHO"))) -> — | J62: 9123.9 | K62: FINALIZADO | L62: Resolvido | M62: Em processo de liberação interna | N62: EXECUTADO | O62: 8 | P62: LIBERAÇÃO NOV
A63: 0926-010851 | B63: DP COPACABANA 12 | C63: CIVIL | D63: Olá, bom dia! Solicitamos a revitalização das paredes da área em que fica a cisterna da filial. | E63: LEANDRO | G63: =IF(F63="","",RESUMO!$L$2-F63) | H63: =IF(F63="","Data a informar",IF(G63<=15,"0–15 dias",IF(G63<=30,"16–30 dias",IF(G63<=60,"31–60 dias",IF(G63<=90,"61–90 dias","Acima de 90 dias"))))) -> Data a informar | I63: =IF(F63="","—",IF(G63<=15,"VERDE",IF(G63<=30,"AMARELO","VERMELHO"))) -> — | J63: 7295.15 | K63: FINALIZADO | L63: Resolvido | M63: Em processo de liberação interna | N63: EXECUTADO | O63: 10 | P63: LIBERAÇÃO NOV
A64: 0526-019295 | B64: DP BARRA DA TIJUCA 5 | C64: HIDRAULICA | D64: Solicito desentupimento do esgoto e caixas de gordura, água retornando pra loja | E64: LEANDRO | G64: =IF(F64="","",RESUMO!$L$2-F64) | H64: =IF(F64="","Data a informar",IF(G64<=15,"0–15 dias",IF(G64<=30,"16–30 dias",IF(G64<=60,"31–60 dias",IF(G64<=90,"61–90 dias","Acima de 90 dias"))))) -> Data a informar | I64: =IF(F64="","—",IF(G64<=15,"VERDE",IF(G64<=30,"AMARELO","VERMELHO"))) -> — | J64: 4791.2 | K64: FINALIZADO | L64: Resolvido | M64: Em processo de liberação interna | N64: EXECUTADO | O64: 11 | P64: competências futuras
A65: 0926-010496 | B65: DP COPACABANA 12 | C65: SERRALHERIA | D65: Troca do portão na área da cisterna. | E65: LEANDRO | G65: =IF(F65="","",RESUMO!$L$2-F65) | H65: =IF(F65="","Data a informar",IF(G65<=15,"0–15 dias",IF(G65<=30,"16–30 dias",IF(G65<=60,"31–60 dias",IF(G65<=90,"61–90 dias","Acima de 90 dias"))))) -> Data a informar | I65: =IF(F65="","—",IF(G65<=15,"VERDE",IF(G65<=30,"AMARELO","VERMELHO"))) -> — | J65: 3758.75 | K65: FINALIZADO | L65: Resolvido | M65: Em processo de liberação interna | N65: EXECUTADO | O65: 11 | P65: competências futuras
A66: 0926-010490 | B66: DP COPACABANA 12 | C66: REFRIGERAÇÃO | D66: Desmontagem e descarte da máquina de ar condicionado antiga. | E66: LEANDRO | G66: =IF(F66="","",RESUMO!$L$2-F66) | H66: =IF(F66="","Data a informar",IF(G66<=15,"0–15 dias",IF(G66<=30,"16–30 dias",IF(G66<=60,"31–60 dias",IF(G66<=90,"61–90 dias","Acima de 90 dias"))))) -> Data a informar | I66: =IF(F66="","—",IF(G66<=15,"VERDE",IF(G66<=30,"AMARELO","VERMELHO"))) -> — | J66: 2959 | K66: FINALIZADO | L66: Resolvido | M66: Em processo de liberação interna | N66: PENDENTE | O66: 11 | P66: competências futuras
A67: 0926-010498 | B67: DP COPACABANA 12 | C67: TELHADO | D67: Reparo da Calha telhado retaguarda. | E67: LEANDRO | G67: =IF(F67="","",RESUMO!$L$2-F67) | H67: =IF(F67="","Data a informar",IF(G67<=15,"0–15 dias",IF(G67<=30,"16–30 dias",IF(G67<=60,"31–60 dias",IF(G67<=90,"61–90 dias","Acima de 90 dias"))))) -> Data a informar | I67: =IF(F67="","—",IF(G67<=15,"VERDE",IF(G67<=30,"AMARELO","VERMELHO"))) -> — | J67: 2391.4 | K67: FINALIZADO | L67: Resolvido | M67: Em processo de liberação interna | N67: EXECUTADO | O67: 10 | P67: LIBERAÇÃO NOV
A68: 0726-014463 | B68: DP TRINDADE | C68: CIVIL | D68: Bom Dia! Tampa do estacionamento encontra-se quebrada solicito troca. | E68: AMANDA | G68: =IF(F68="","",RESUMO!$L$2-F68) | H68: =IF(F68="","Data a informar",IF(G68<=15,"0–15 dias",IF(G68<=30,"16–30 dias",IF(G68<=60,"31–60 dias",IF(G68<=90,"61–90 dias","Acima de 90 dias"))))) -> Data a informar | I68: =IF(F68="","—",IF(G68<=15,"VERDE",IF(G68<=30,"AMARELO","VERMELHO"))) -> — | J68: 2210.02 | K68: FINALIZADO | L68: Resolvido | M68: Em processo de liberação interna | N68: EXECUTADO | O68: 10 | P68: LIBERAÇÃO NOV
A69: 1026-007646 | B69: DP SAO FRANCISCO DO ITABAPOANA | C69: ELETRICA | D69: Transporte da geladeira e instalação de tomada (Cinta) | E69: LEANDRO | G69: =IF(F69="","",RESUMO!$L$2-F69) | H69: =IF(F69="","Data a informar",IF(G69<=15,"0–15 dias",IF(G69<=30,"16–30 dias",IF(G69<=60,"31–60 dias",IF(G69<=90,"61–90 dias","Acima de 90 dias"))))) -> Data a informar | I69: =IF(F69="","—",IF(G69<=15,"VERDE",IF(G69<=30,"AMARELO","VERMELHO"))) -> — | J69: 2100 | K69: FINALIZADO | L69: Resolvido | M69: Em processo de liberação interna | N69: PENDENTE | O69: 11 | P69: competências futuras
A70: 0626-003845 | B70: DP RIO BRANCO 2 | C70: SERRALHERIA | D70: Prezados, bom dia! A Porta 3 encontra-se desalinhada, apresentando grande dificuldade para fechamento, sendo necessário o auxílio de dois colaboradores para realizar essa operação, o que compromete a rotina e a segurança operacional da filial. Ressalto que, em atendimento anterior, a equipe de manutenção informou que a porta não possui condições de reparo, sendo necessária a substituição completa por uma nova. Dessa forma, solicito providências para a troca da Porta 3 com a maior brevidade possível, a fim de garantir a segurança e o correto funcionamento da unidade. Atenciosamente, Dayane Polito Gerente de Loja | E70: LEANDRO | G70: =IF(F70="","",RESUMO!$L$2-F70) | H70: =IF(F70="","Data a informar",IF(G70<=15,"0–15 dias",IF(G70<=30,"16–30 dias",IF(G70<=60,"31–60 dias",IF(G70<=90,"61–90 dias","Acima de 90 dias"))))) -> Data a informar | I70: =IF(F70="","—",IF(G70<=15,"VERDE",IF(G70<=30,"AMARELO","VERMELHO"))) -> — | J70: 1300.66 | K70: FINALIZADO | L70: Resolvido | M70: Em processo de liberação interna | N70: EXECUTADO | O70: 11 | P70: competências futuras
A71: 0926-017427 | B71: DP TAQUARA 6 | C71: ELETRICA | D71: Solicito instalação de tomada 110v/127v para geladeira da cinta. | E71: AMANDA | G71: =IF(F71="","",RESUMO!$L$2-F71) | H71: =IF(F71="","Data a informar",IF(G71<=15,"0–15 dias",IF(G71<=30,"16–30 dias",IF(G71<=60,"31–60 dias",IF(G71<=90,"61–90 dias","Acima de 90 dias"))))) -> Data a informar | I71: =IF(F71="","—",IF(G71<=15,"VERDE",IF(G71<=30,"AMARELO","VERMELHO"))) -> — | J71: 1241.31 | K71: FINALIZADO | L71: Resolvido | M71: Em processo de liberação interna | N71: EXECUTADO | O71: 11 | P71: competências futuras
...

Sheet LIBERADAS 21-10
E1: OS LIBERADAS PELA DPSP NO FECHAMENTO DA JANELA — 21/10/2026
E2: Pedidos e folhas recebidos para faturamento
A5: Nº OS | B5: Loja | C5: Tipo | D5: Pedido | E5: Folha 10 | F5: Valor 10 (R$) | G5: Folha 20 | H5: Valor 20 (R$) | I5: Valor NF (R$) | J5: Data finalização | K5: Dias até liberação
A6: 1125-016234 | B6: DP CAMPOS 7 | C6: NOBREAK | D6: 4500764516 | E6: 1000701189 | F6: 3484.32 | G6: 1000701191 | H6: 5226.49 | I6: =F6+H6 -> 8710.81 | J6: 46104 | K6: =DATE(2026,10,21)-J6 -> 212
A7: 0426-008820 | B7: DP NILOPOLIS | C7: AR CONDICIONADO | D7: 4500764913 | E7: 1000701187 | F7: 4656.56 | G7: 1000701188 | H7: 6984.83 | I7: =F7+H7 -> 11641.39 | J7: 46254 | K7: =DATE(2026,10,21)-J7 -> 62
A8: TOTAL | H8: 2 OS | I8: =SUM(I6:I7) -> 20352.2
A10: Valores conforme planilha de liberação de pedido e folha enviada pela DPSP em 21/10/2026.

Sheet LP
A1: Data de pagamento | B1: valor
A2: 46366 | B2: -7569.7
A3: 46356 | B3: -86614.1
A4: 46346 | B4: -48687.11
A5: 46336 | B5: -116350.42
A6: 46325 | B6: -19563.05
A7: TOTAL | B7: -278784.38
