Workbook
Name DataBase: PAINEL!$C$8
Name DataRef: PAINEL!$C$9
Name Feriados: LISTAS!$E$5:$E$24
Name FimObra: PAINEL!$C$10
Name RelSeg: RELATORIO_CLIENTE!$C$6
Name RelSex: RELATORIO_CLIENTE!$C$7

Sheet LEIA_ME
B1: SGO MANFAC – Sistema de Gestão, Controle e Comunicação de Obra
B2: Obra DP Macaé 3 (DPSP DS 1505) – base única: tudo é registrado uma vez e alimenta painel, relatórios e comunicação.
B5: COMO LER AS CORES
B6: Amarelo, texto azul | C6: Campo para preencher ou ajustar.
B7: Branco, texto preto | C7: Fórmula. Não sobrescrever.
B8: Cinza itálico | C8: Linha de exemplo (não entra em nenhum total).
B10: ABAS
B11: PAINEL | C11: Visão da gestão MANFAC: parâmetros, avanço, financeiro interno, pendências, comunicação e alertas automáticos.
B12: CRONOGRAMA | C12: 28 atividades (20 da frente estrutural + 8 da reforma light) com predecessoras, dias úteis, peso pelo valor do orçamento, status, % realizado e gráfico de barras semanal.
B13: ORCAMENTO | C13: REV_04 e LPU rev 2 na mesma tabela. Cada linha ligada a uma atividade (peso físico), com % medido, custo previsto e custo real vindo de COMPRAS e LOCACOES.
B14: CONFLITOS | C14: Nove sobreposições de escopo entre REV_04 e LPU, com valores e ação recomendada.
B15: RDO | C15: Registro diário do encarregado, validado pelo engenheiro. Base do informe diário ao cliente.
B16: COMPRAS / LOCACOES | C16: Pedidos, entregas e locações com custo acumulado por dia. Cada lançamento usa a chave de um item do orçamento.
B17: MEDICOES | C17: Ciclo medição → aprovação DPSP → NF → recebimento, com dias em aprovação.
B18: PENDENCIAS | C18: Travas, riscos, decisões do cliente e ajustes de escopo. Já carregada com 14 pontos da conferência de 23/10/2026.
B19: COMUNICACAO | C19: Agenda de envios gerada pelo cronograma (diários, semanais às sextas, mensais no último dia útil, fases e entrega) e histórico de envio, com situação automática.
B20: RELATORIO_CLIENTE | C20: Relatório semanal pronto para PDF, sem custos: avanço, concluídas, em andamento, próxima semana, decisões do cliente e fotos.
B21: CURVA_S | C21: Previsto x realizado por semana. O realizado é registrado toda sexta (copiar do PAINEL).
B22: LISTAS | C22: Listas suspensas e feriados usados no cálculo de dias úteis.
B24: ROTINA
B25: Diariamente | C25: Encarregado preenche o RDO → engenheiro valida → COP envia o informe diário e marca "Enviado?" = Sim e a data real em COMUNICACAO. Atualizar status e % no CRONOGRAMA.
B26: Sexta-feira | C26: Atualizar CRONOGRAMA e PENDENCIAS → GO avalia desvios no PAINEL → copiar avanço realizado na CURVA_S → salvar RELATORIO_CLIENTE em PDF e enviar.
B27: Último dia útil do mês | C27: Engenharia e Financeiro atualizam ORCAMENTO (% medido) e MEDICOES → GO valida → relatório mensal ao cliente.
B28: Exceção | C28: Risco de atraso, custo adicional ou decisão do cliente: comunicação imediata, registrada em COMUNICACAO (linhas amarelas no fim).
B30: PREMISSAS
B31: Datas | C31: Data-base 26/10/2026 (ajustável no PAINEL). Durações em dias úteis são estimativas MANFAC para validação do engenheiro.
B32: Peso físico | C32: Proporcional ao valor de venda vinculado a cada atividade. Indiretos (9.1–9.3) e imposto (9.4) do REV_04 ficam fora do peso.
B33: Situação atual | C33: Escoramento parcial: falta a viga principal. Demolições bloqueadas até o nº 6 ficar "Concluído". Status das atividades 1 a 5 a confirmar.
B34: Fontes | C34: REV_04 (orçamento estrutural), LPU Padrão Reforma Light DP Macaé 3 rev 2, Laudo EGUTI Rev.00 (09/06/2026), Layout aprovado Macaé RJ, Fases da Obra Macaé 3.

Sheet PAINEL
A1: SGO – Painel da Obra | DP Macaé 3 (DPSP DS 1505)
A2: Visão da gestão MANFAC. Uso interno: contém custos e margem. Para o cliente, use a aba RELATORIO_CLIENTE.
B4: PARÂMETROS DA OBRA | E4: FINANCEIRO (USO INTERNO)
B5: Obra | C5: DP Macaé 3 – Intervenção estrutural + reforma light | E5: Pedido estrutural – REV_04 | F5: =SUMIFS(ORCAMENTO!G:G,ORCAMENTO!A:A,"Estrutural REV_04") -> 292968
B6: Cliente | C6: Grupo DPSP – DS 1505 | E6: Pedido reforma light – LPU rev 2 | F6: =SUMIFS(ORCAMENTO!G:G,ORCAMENTO!A:A,"Reforma light LPU") -> 213372.41
B7: Endereço | C7: Rua Maria Francisca Borges Reid, s/nº – Glória, Macaé/RJ | E7: Total contratado | F7: =F5+F6 -> 506340.41
B8: Data-base do planejamento (início das atividades restantes) | C8: 46321 | E8: Medido acumulado (aba ORCAMENTO) | F8: =SUM(ORCAMENTO!K5:K200) -> 0
B9: Data de referência (hoje – pode fixar para fechar relatório) | C9: =TODAY() -> 46318 | E9: Medições apresentadas | F9: =SUM(MEDICOES!E6:E200) -> 0
B10: Previsão de término (cronograma) | C10: =MAX(CRONOGRAMA!K5:K32) -> 46415 | E10: Medições aprovadas | F10: =SUMIFS(MEDICOES!E6:E200,MEDICOES!H6:H200,"<>") -> 0
B11: Engenheiro responsável | E11: Faturado (NF emitida) | F11: =SUM(MEDICOES!L6:L200) -> 0
E12: Recebido | F12: =SUMIFS(MEDICOES!L6:L200,MEDICOES!M6:M200,"<>") -> 0
B13: PRAZO E AVANÇO FÍSICO | E13: Saldo a medir | F13: =F7-F8 -> 506340.41
B14: Avanço previsto até a data de referência | C14: =SUMPRODUCT(CRONOGRAMA!M5:M32,CRONOGRAMA!R5:R32) -> 0 | E14: Custo real (compras + locações) | F14: =SUMIFS(COMPRAS!G6:G500,COMPRAS!J6:J500,"<>Cancelado")+SUM(LOCACOES!I6:I200) -> 0
B15: Avanço realizado | C15: =SUMPRODUCT(CRONOGRAMA!M5:M32,CRONOGRAMA!O5:O32) -> 0 | E15: Resultado sobre o medido (medido – custo real) | F15: =F8-F14 -> 0
B16: Desvio (pontos percentuais) | C16: =(C15-C14)*100 -> 0 | E16: Exposição a glosa por sobreposição REV_04 x LPU (não resolvida) | F16: =SUMIFS(CONFLITOS!J5:J13,CONFLITOS!I5:I13,"<>Resolvido") -> 35912.64
B17: Atividades atrasadas ou com início atrasado | C17: =COUNTIF(CRONOGRAMA!T5:T32,"ATRASADA")+COUNTIF(CRONOGRAMA!T5:T32,"INÍCIO ATRASADO") -> 0
B18: Atividades concluídas | C18: =COUNTIF(CRONOGRAMA!N5:N32,"Concluído")&" de "&COUNTA(CRONOGRAMA!A5:A32) -> 0 de 28
B19: Trava estrutural (escoramento da viga principal) | C19: =IF(CRONOGRAMA!N10="Concluído","LIBERADA – demolições autorizadas","BLOQUEADA – demolições proibidas") -> BLOQUEADA – demolições proibidas
B21: PENDÊNCIAS, COMUNICAÇÃO E RECURSOS | E21: ALERTAS AUTOMÁTICOS
B22: Pendências em aberto | C22: =COUNTIFS(PENDENCIAS!C5:C200,"<>",PENDENCIAS!J5:J200,"<>Concluída") -> 14 | E22: =IF(CRONOGRAMA!N10<>"Concluído","Escoramento da viga principal pendente: nenhuma demolição pode começar.","") -> Escoramento da viga principal pendente: nenhuma demolição pode começar.
B23: Pendências vencidas | C23: =COUNTIF(PENDENCIAS!M5:M200,"VENCIDA") -> 0 | E23: =IF(C17>0,C17&" atividade(s) atrasada(s) – comunicar o cliente hoje, sem esperar o semanal.","")
B24: Decisões aguardando o cliente | C24: =COUNTIFS(PENDENCIAS!G5:G200,"Sim",PENDENCIAS!J5:J200,"<>Concluída",PENDENCIAS!C5:C200,"<>") -> 6 | E24: =IF(C16<-5,"Desvio acima de 5 p.p. – definir ação de recuperação e registrar no semanal.","")
B25: Comunicações ao cliente atrasadas | C25: =COUNTIF(COMUNICACAO!L5:L300,"ATRASADO") -> 0 | E25: =IF(C25>0,C25&" comunicação(ões) ao cliente atrasada(s).","")
B26: Próximo envio programado | C26: =_xlfn.MINIFS(COMUNICACAO!E5:E300,COMUNICACAO!F5:F300,"",COMUNICACAO!E5:E300,">="&DataRef) -> 46321 | E26: =IF(C24>0,C24&" decisão(ões) aguardando o cliente – cobrar no próximo informe.","") -> 6 decisão(ões) aguardando o cliente – cobrar no próximo informe.
B27: RDOs registrados | C27: =COUNT(RDO!A6:A500) -> 0 | E27: =IF(F16>0,"Exposição de R$ "&FIXED(F16,0)&" em escopo sobreposto REV_04 x LPU – resolver antes da 1ª medição.","") -> Exposição de R$ 35.913 em escopo sobreposto REV_04 x LPU – resolver antes da 1ª medição.
B28: RDOs registrados e não enviados ao cliente | C28: =COUNTIFS(RDO!A6:A500,"<>",RDO!Q6:Q500,"<>Sim") -> 0 | E28: =IF(C30>0,C30&" locação(ões) vencida(s) – custo correndo.","")
B29: Locações ativas | C29: =COUNTIF(LOCACOES!K6:K200,"Ativa")+COUNTIF(LOCACOES!K6:K200,"VENCIDA*") -> 0 | E29: =IF(C28>0,C28&" RDO(s) sem envio ao cliente.","")
B30: Locações vencidas (renovar ou devolver) | C30: =COUNTIF(LOCACOES!K6:K200,"VENCIDA*") -> 0
B31: Compras com entrega atrasada | C31: =COUNTIF(COMPRAS!L6:L500,"ATRASADA") -> 0

Sheet CRONOGRAMA
A1: Cronograma físico – atividades, travas e avanço
A2: Amarelo = preencher. Datas previstas calculadas por predecessoras e dias úteis (feriados na aba LISTAS). Peso = valor do orçamento vinculado à atividade.
Z3: Gráfico de barras por semana (segunda-feira)
A4: Nº | B4: Frente | C4: Etapa | D4: Atividade | E4: Saída / trava | F4: Pred. 1 | G4: Pred. 2 | H4: Dias úteis | I4: Responsável | J4: Início previsto | K4: Fim previsto | L4: Valor vinculado | M4: Peso | N4: Status | O4: % realizado | P4: Início real | Q4: Fim real | R4: % previsto (hoje) | S4: Desvio | T4: Situação | U4: % prev. data relatório | V4: aux1 | W4: aux2 | X4: aux3 | Z4: =DataBase-WEEKDAY(DataBase,2)+1+0 -> 46321 | AA4: =DataBase-WEEKDAY(DataBase,2)+1+7 -> 46328 | AB4: =DataBase-WEEKDAY(DataBase,2)+1+14 -> 46335 | AC4: =DataBase-WEEKDAY(DataBase,2)+1+21 -> 46342 | AD4: =DataBase-WEEKDAY(DataBase,2)+1+28 -> 46349 | AE4: =DataBase-WEEKDAY(DataBase,2)+1+35 -> 46356 | AF4: =DataBase-WEEKDAY(DataBase,2)+1+42 -> 46363 | AG4: =DataBase-WEEKDAY(DataBase,2)+1+49 -> 46370 | AH4: =DataBase-WEEKDAY(DataBase,2)+1+56 -> 46377 | AI4: =DataBase-WEEKDAY(DataBase,2)+1+63 -> 46384 | AJ4: =DataBase-WEEKDAY(DataBase,2)+1+70 -> 46391 | AK4: =DataBase-WEEKDAY(DataBase,2)+1+77 -> 46398 | AL4: =DataBase-WEEKDAY(DataBase,2)+1+84 -> 46405 | AM4: =DataBase-WEEKDAY(DataBase,2)+1+91 -> 46412 | AN4: =DataBase-WEEKDAY(DataBase,2)+1+98 -> 46419 | AO4: =DataBase-WEEKDAY(DataBase,2)+1+105 -> 46426 | AP4: =DataBase-WEEKDAY(DataBase,2)+1+112 -> 46433 | AQ4: =DataBase-WEEKDAY(DataBase,2)+1+119 -> 46440 | AR4: =DataBase-WEEKDAY(DataBase,2)+1+126 -> 46447 | AS4: =DataBase-WEEKDAY(DataBase,2)+1+133 -> 46454
A5: 1 | B5: Estrutural | C5: 1 – Mobilização e isolamento | D5: Reunião de partida no local: identificar P1–P4, treliça e faixa de piso afetada | E5: Mapa de frentes validado pelo RT | H5: 1 | J5: =IF(AND(F5="",G5=""),WORKDAY(DataBase-1,1,Feriados),WORKDAY(MAX(IFERROR(INDEX($K$5:$K$32,MATCH(F5,$A$5:$A$32,0)),0),IFERROR(INDEX($K$5:$K$32,MATCH(G5,$A$5:$A$32,0)),0)),1,Feriados)) -> 46321 | K5: =WORKDAY(J5,MAX(H5,1)-1,Feriados) -> 46321 | L5: =SUMIFS(ORCAMENTO!$G$5:$G$200,ORCAMENTO!$H$5:$H$200,A5) -> 6650 | M5: =IF(SUM($L$5:$L$32)=0,0,L5/SUM($L$5:$L$32)) -> 0.015190542 | N5: Não iniciado | R5: =IF(DataRef<J5,0,IF(DataRef>=K5,1,NETWORKDAYS(J5,DataRef,Feriados)/MAX(H5,1))) -> 0 | S5: =N(O5)-R5 -> 0 | T5: =IF(N5="Concluído","Concluída",IF(N5="Bloqueado","BLOQUEADA",IF(DataRef>K5,"ATRASADA",IF(AND(DataRef>=J5,N5="Não iniciado"),"INÍCIO ATRASADO","No prazo")))) -> No prazo | U5: =IF(RelSex<J5,0,IF(RelSex>=K5,1,NETWORKDAYS(J5,RelSex,Feriados)/MAX(H5,1))) -> 0 | V5: =IF(N5="Concluído",COUNTIF($N$5:N5,"Concluído"),"") | W5: =IF(N5="Em andamento",COUNTIF($N$5:N5,"Em andamento"),"") | X5: =IF(AND(N5<>"Concluído",J5<=RelSex+7,K5>RelSex),COUNTIFS($N$5:N5,"<>Concluído",$J$5:J5,"<="&(RelSex+7),$K$5:K5,">"&RelSex),"") -> 1 | Z5: =IF(AND(Z$4<=$K5,Z$4+4>=$J5),1,"") -> 1 | AA5: =IF(AND(AA$4<=$K5,AA$4+4>=$J5),1,"") | AB5: =IF(AND(AB$4<=$K5,AB$4+4>=$J5),1,"") | AC5: =IF(AND(AC$4<=$K5,AC$4+4>=$J5),1,"") | AD5: =IF(AND(AD$4<=$K5,AD$4+4>=$J5),1,"") | AE5: =IF(AND(AE$4<=$K5,AE$4+4>=$J5),1,"") | AF5: =IF(AND(AF$4<=$K5,AF$4+4>=$J5),1,"") | AG5: =IF(AND(AG$4<=$K5,AG$4+4>=$J5),1,"") | ... AS5: =IF(AND(AS$4<=$K5,AS$4+4>=$J5),1,"")
A6: 2 | B6: Estrutural | C6: 1 – Mobilização e isolamento | D6: Pontos de acompanhamento fotográfico, relatório "antes da obra" e marcos de nível | E6: Registro-base para medição e comparação | F6: 1 | H6: 2 | J6: =IF(AND(F6="",G6=""),WORKDAY(DataBase-1,1,Feriados),WORKDAY(MAX(IFERROR(INDEX($K$5:$K$32,MATCH(F6,$A$5:$A$32,0)),0),IFERROR(INDEX($K$5:$K$32,MATCH(G6,$A$5:$A$32,0)),0)),1,Feriados)) -> 46322 | K6: =WORKDAY(J6,MAX(H6,1)-1,Feriados) -> 46323 | L6: =SUMIFS(ORCAMENTO!$G$5:$G$200,ORCAMENTO!$H$5:$H$200,A6) -> 4500 | M6: =IF(SUM($L$5:$L$32)=0,0,L6/SUM($L$5:$L$32)) -> 0.010279314 | N6: Não iniciado | R6: =IF(DataRef<J6,0,IF(DataRef>=K6,1,NETWORKDAYS(J6,DataRef,Feriados)/MAX(H6,1))) -> 0 | S6: =N(O6)-R6 -> 0 | T6: =IF(N6="Concluído","Concluída",IF(N6="Bloqueado","BLOQUEADA",IF(DataRef>K6,"ATRASADA",IF(AND(DataRef>=J6,N6="Não iniciado"),"INÍCIO ATRASADO","No prazo")))) -> No prazo | U6: =IF(RelSex<J6,0,IF(RelSex>=K6,1,NETWORKDAYS(J6,RelSex,Feriados)/MAX(H6,1))) -> 0 | V6: =IF(N6="Concluído",COUNTIF($N$5:N6,"Concluído"),"") | W6: =IF(N6="Em andamento",COUNTIF($N$5:N6,"Em andamento"),"") | X6: =IF(AND(N6<>"Concluído",J6<=RelSex+7,K6>RelSex),COUNTIFS($N$5:N6,"<>Concluído",$J$5:J6,"<="&(RelSex+7),$K$5:K6,">"&RelSex),"") -> 2 | Z6: =IF(AND(Z$4<=$K6,Z$4+4>=$J6),1,"") -> 1 | AA6: =IF(AND(AA$4<=$K6,AA$4+4>=$J6),1,"") | AB6: =IF(AND(AB$4<=$K6,AB$4+4>=$J6),1,"") | AC6: =IF(AND(AC$4<=$K6,AC$4+4>=$J6),1,"") | AD6: =IF(AND(AD$4<=$K6,AD$4+4>=$J6),1,"") | AE6: =IF(AND(AE$4<=$K6,AE$4+4>=$J6),1,"") | AF6: =IF(AND(AF$4<=$K6,AF$4+4>=$J6),1,"") | AG6: =IF(AND(AG$4<=$K6,AG$4+4>=$J6),1,"") | ... AS6: =IF(AND(AS$4<=$K6,AS$4+4>=$J6),1,"")
A7: 3 | B7: Estrutural | C7: 1 – Mobilização e isolamento | D7: Instalar divisória de fechamento da área | E7: Área isolada e sinalizada | F7: 1 | H7: 2 | J7: =IF(AND(F7="",G7=""),WORKDAY(DataBase-1,1,Feriados),WORKDAY(MAX(IFERROR(INDEX($K$5:$K$32,MATCH(F7,$A$5:$A$32,0)),0),IFERROR(INDEX($K$5:$K$32,MATCH(G7,$A$5:$A$32,0)),0)),1,Feriados)) -> 46322 | K7: =WORKDAY(J7,MAX(H7,1)-1,Feriados) -> 46323 | L7: =SUMIFS(ORCAMENTO!$G$5:$G$200,ORCAMENTO!$H$5:$H$200,A7) -> 17869.2 | M7: =IF(SUM($L$5:$L$32)=0,0,L7/SUM($L$5:$L$32)) -> 0.04081847 | N7: Não iniciado | R7: =IF(DataRef<J7,0,IF(DataRef>=K7,1,NETWORKDAYS(J7,DataRef,Feriados)/MAX(H7,1))) -> 0 | S7: =N(O7)-R7 -> 0 | T7: =IF(N7="Concluído","Concluída",IF(N7="Bloqueado","BLOQUEADA",IF(DataRef>K7,"ATRASADA",IF(AND(DataRef>=J7,N7="Não iniciado"),"INÍCIO ATRASADO","No prazo")))) -> No prazo | U7: =IF(RelSex<J7,0,IF(RelSex>=K7,1,NETWORKDAYS(J7,RelSex,Feriados)/MAX(H7,1))) -> 0 | V7: =IF(N7="Concluído",COUNTIF($N$5:N7,"Concluído"),"") | W7: =IF(N7="Em andamento",COUNTIF($N$5:N7,"Em andamento"),"") | X7: =IF(AND(N7<>"Concluído",J7<=RelSex+7,K7>RelSex),COUNTIFS($N$5:N7,"<>Concluído",$J$5:J7,"<="&(RelSex+7),$K$5:K7,">"&RelSex),"") -> 3 | Z7: =IF(AND(Z$4<=$K7,Z$4+4>=$J7),1,"") -> 1 | AA7: =IF(AND(AA$4<=$K7,AA$4+4>=$J7),1,"") | AB7: =IF(AND(AB$4<=$K7,AB$4+4>=$J7),1,"") | AC7: =IF(AND(AC$4<=$K7,AC$4+4>=$J7),1,"") | AD7: =IF(AND(AD$4<=$K7,AD$4+4>=$J7),1,"") | AE7: =IF(AND(AE$4<=$K7,AE$4+4>=$J7),1,"") | AF7: =IF(AND(AF$4<=$K7,AF$4+4>=$J7),1,"") | AG7: =IF(AND(AG$4<=$K7,AG$4+4>=$J7),1,"") | ... AS7: =IF(AND(AS$4<=$K7,AS$4+4>=$J7),1,"")
A8: 4 | B8: Estrutural | C8: 1 – Mobilização e isolamento | D8: Remover produtos, virar o balcão e mudar o mobiliário da área afetada | E8: Frente de trabalho livre | F8: 3 | H8: 3 | J8: =IF(AND(F8="",G8=""),WORKDAY(DataBase-1,1,Feriados),WORKDAY(MAX(IFERROR(INDEX($K$5:$K$32,MATCH(F8,$A$5:$A$32,0)),0),IFERROR(INDEX($K$5:$K$32,MATCH(G8,$A$5:$A$32,0)),0)),1,Feriados)) -> 46324 | K8: =WORKDAY(J8,MAX(H8,1)-1,Feriados) -> 46329 | L8: =SUMIFS(ORCAMENTO!$G$5:$G$200,ORCAMENTO!$H$5:$H$200,A8) -> 5851 | M8: =IF(SUM($L$5:$L$32)=0,0,L8/SUM($L$5:$L$32)) -> 0.013365392 | N8: Não iniciado | R8: =IF(DataRef<J8,0,IF(DataRef>=K8,1,NETWORKDAYS(J8,DataRef,Feriados)/MAX(H8,1))) -> 0 | S8: =N(O8)-R8 -> 0 | T8: =IF(N8="Concluído","Concluída",IF(N8="Bloqueado","BLOQUEADA",IF(DataRef>K8,"ATRASADA",IF(AND(DataRef>=J8,N8="Não iniciado"),"INÍCIO ATRASADO","No prazo")))) -> No prazo | U8: =IF(RelSex<J8,0,IF(RelSex>=K8,1,NETWORKDAYS(J8,RelSex,Feriados)/MAX(H8,1))) -> 0 | V8: =IF(N8="Concluído",COUNTIF($N$5:N8,"Concluído"),"") | W8: =IF(N8="Em andamento",COUNTIF($N$5:N8,"Em andamento"),"") | X8: =IF(AND(N8<>"Concluído",J8<=RelSex+7,K8>RelSex),COUNTIFS($N$5:N8,"<>Concluído",$J$5:J8,"<="&(RelSex+7),$K$5:K8,">"&RelSex),"") -> 4 | Z8: =IF(AND(Z$4<=$K8,Z$4+4>=$J8),1,"") -> 1 | AA8: =IF(AND(AA$4<=$K8,AA$4+4>=$J8),1,"") -> 1 | AB8: =IF(AND(AB$4<=$K8,AB$4+4>=$J8),1,"") | AC8: =IF(AND(AC$4<=$K8,AC$4+4>=$J8),1,"") | AD8: =IF(AND(AD$4<=$K8,AD$4+4>=$J8),1,"") | AE8: =IF(AND(AE$4<=$K8,AE$4+4>=$J8),1,"") | AF8: =IF(AND(AF$4<=$K8,AF$4+4>=$J8),1,"") | AG8: =IF(AND(AG$4<=$K8,AG$4+4>=$J8),1,"") | ... AS8: =IF(AND(AS$4<=$K8,AS$4+4>=$J8),1,"")
A9: 5 | B9: Estrutural | C9: 1 – Mobilização e isolamento | D9: Aliviar a carga do mezanino (retirar estoque do depósito) | E9: Mezanino descarregado | F9: 3 | H9: 1 | J9: =IF(AND(F9="",G9=""),WORKDAY(DataBase-1,1,Feriados),WORKDAY(MAX(IFERROR(INDEX($K$5:$K$32,MATCH(F9,$A$5:$A$32,0)),0),IFERROR(INDEX($K$5:$K$32,MATCH(G9,$A$5:$A$32,0)),0)),1,Feriados)) -> 46324 | K9: =WORKDAY(J9,MAX(H9,1)-1,Feriados) -> 46324 | L9: =SUMIFS(ORCAMENTO!$G$5:$G$200,ORCAMENTO!$H$5:$H$200,A9) -> 0 | M9: =IF(SUM($L$5:$L$32)=0,0,L9/SUM($L$5:$L$32)) -> 0 | N9: Não iniciado | R9: =IF(DataRef<J9,0,IF(DataRef>=K9,1,NETWORKDAYS(J9,DataRef,Feriados)/MAX(H9,1))) -> 0 | S9: =N(O9)-R9 -> 0 | T9: =IF(N9="Concluído","Concluída",IF(N9="Bloqueado","BLOQUEADA",IF(DataRef>K9,"ATRASADA",IF(AND(DataRef>=J9,N9="Não iniciado"),"INÍCIO ATRASADO","No prazo")))) -> No prazo | U9: =IF(RelSex<J9,0,IF(RelSex>=K9,1,NETWORKDAYS(J9,RelSex,Feriados)/MAX(H9,1))) -> 0 | V9: =IF(N9="Concluído",COUNTIF($N$5:N9,"Concluído"),"") | W9: =IF(N9="Em andamento",COUNTIF($N$5:N9,"Em andamento"),"") | X9: =IF(AND(N9<>"Concluído",J9<=RelSex+7,K9>RelSex),COUNTIFS($N$5:N9,"<>Concluído",$J$5:J9,"<="&(RelSex+7),$K$5:K9,">"&RelSex),"") -> 5 | Z9: =IF(AND(Z$4<=$K9,Z$4+4>=$J9),1,"") -> 1 | AA9: =IF(AND(AA$4<=$K9,AA$4+4>=$J9),1,"") | AB9: =IF(AND(AB$4<=$K9,AB$4+4>=$J9),1,"") | AC9: =IF(AND(AC$4<=$K9,AC$4+4>=$J9),1,"") | AD9: =IF(AND(AD$4<=$K9,AD$4+4>=$J9),1,"") | AE9: =IF(AND(AE$4<=$K9,AE$4+4>=$J9),1,"") | AF9: =IF(AND(AF$4<=$K9,AF$4+4>=$J9),1,"") | AG9: =IF(AND(AG$4<=$K9,AG$4+4>=$J9),1,"") | ... AS9: =IF(AND(AS$4<=$K9,AS$4+4>=$J9),1,"")
A10: 6 | B10: Estrutural | C10: 2 – Estabilização | D10: Escoramento provisório sob a treliça (P2/P3 e vão P3–P4); macaco só para encunhar | E10: PARCIAL – falta a viga principal. Libera demolições. Manter até o nº 15 | F10: 5 | H10: 3 | J10: =IF(AND(F10="",G10=""),WORKDAY(DataBase-1,1,Feriados),WORKDAY(MAX(IFERROR(INDEX($K$5:$K$32,MATCH(F10,$A$5:$A$32,0)),0),IFERROR(INDEX($K$5:$K$32,MATCH(G10,$A$5:$A$32,0)),0)),1,Feriados)) -> 46325 | K10: =WORKDAY(J10,MAX(H10,1)-1,Feriados) -> 46330 | L10: =SUMIFS(ORCAMENTO!$G$5:$G$200,ORCAMENTO!$H$5:$H$200,A10) -> 15200 | M10: =IF(SUM($L$5:$L$32)=0,0,L10/SUM($L$5:$L$32)) -> 0.034721238 | N10: Em andamento | R10: =IF(DataRef<J10,0,IF(DataRef>=K10,1,NETWORKDAYS(J10,DataRef,Feriados)/MAX(H10,1))) -> 0 | S10: =N(O10)-R10 -> 0 | T10: =IF(N10="Concluído","Concluída",IF(N10="Bloqueado","BLOQUEADA",IF(DataRef>K10,"ATRASADA",IF(AND(DataRef>=J10,N10="Não iniciado"),"INÍCIO ATRASADO","No prazo")))) -> No prazo | U10: =IF(RelSex<J10,0,IF(RelSex>=K10,1,NETWORKDAYS(J10,RelSex,Feriados)/MAX(H10,1))) -> 0 | V10: =IF(N10="Concluído",COUNTIF($N$5:N10,"Concluído"),"") | W10: =IF(N10="Em andamento",COUNTIF($N$5:N10,"Em andamento"),"") -> 1 | X10: =IF(AND(N10<>"Concluído",J10<=RelSex+7,K10>RelSex),COUNTIFS($N$5:N10,"<>Concluído",$J$5:J10,"<="&(RelSex+7),$K$5:K10,">"&RelSex),"") -> 6 | Z10: =IF(AND(Z$4<=$K10,Z$4+4>=$J10),1,"") -> 1 | AA10: =IF(AND(AA$4<=$K10,AA$4+4>=$J10),1,"") -> 1 | AB10: =IF(AND(AB$4<=$K10,AB$4+4>=$J10),1,"") | AC10: =IF(AND(AC$4<=$K10,AC$4+4>=$J10),1,"") | AD10: =IF(AND(AD$4<=$K10,AD$4+4>=$J10),1,"") | AE10: =IF(AND(AE$4<=$K10,AE$4+4>=$J10),1,"") | AF10: =IF(AND(AF$4<=$K10,AF$4+4>=$J10),1,"") | AG10: =IF(AND(AG$4<=$K10,AG$4+4>=$J10),1,"") | ... AS10: =IF(AND(AS$4<=$K10,AS$4+4>=$J10),1,"")
A11: 7 | B11: Estrutural | C11: 3 – Investigação e projeto | D11: Levantamento topográfico de níveis e medição dos m² da faixa afetada | E11: Croqui com m² e cotas | F11: 6 | H11: 2 | J11: =IF(AND(F11="",G11=""),WORKDAY(DataBase-1,1,Feriados),WORKDAY(MAX(IFERROR(INDEX($K$5:$K$32,MATCH(F11,$A$5:$A$32,0)),0),IFERROR(INDEX($K$5:$K$32,MATCH(G11,$A$5:$A$32,0)),0)),1,Feriados)) -> 46331 | K11: =WORKDAY(J11,MAX(H11,1)-1,Feriados) -> 46332 | L11: =SUMIFS(ORCAMENTO!$G$5:$G$200,ORCAMENTO!$H$5:$H$200,A11) -> 11500 | M11: =IF(SUM($L$5:$L$32)=0,0,L11/SUM($L$5:$L$32)) -> 0.026269358 | N11: Não iniciado | R11: =IF(DataRef<J11,0,IF(DataRef>=K11,1,NETWORKDAYS(J11,DataRef,Feriados)/MAX(H11,1))) -> 0 | S11: =N(O11)-R11 -> 0 | T11: =IF(N11="Concluído","Concluída",IF(N11="Bloqueado","BLOQUEADA",IF(DataRef>K11,"ATRASADA",IF(AND(DataRef>=J11,N11="Não iniciado"),"INÍCIO ATRASADO","No prazo")))) -> No prazo | U11: =IF(RelSex<J11,0,IF(RelSex>=K11,1,NETWORKDAYS(J11,RelSex,Feriados)/MAX(H11,1))) -> 0 | V11: =IF(N11="Concluído",COUNTIF($N$5:N11,"Concluído"),"") | W11: =IF(N11="Em andamento",COUNTIF($N$5:N11,"Em andamento"),"") | X11: =IF(AND(N11<>"Concluído",J11<=RelSex+7,K11>RelSex),COUNTIFS($N$5:N11,"<>Concluído",$J$5:J11,"<="&(RelSex+7),$K$5:K11,">"&RelSex),"") | Z11: =IF(AND(Z$4<=$K11,Z$4+4>=$J11),1,"") | AA11: =IF(AND(AA$4<=$K11,AA$4+4>=$J11),1,"") -> 1 | AB11: =IF(AND(AB$4<=$K11,AB$4+4>=$J11),1,"") | AC11: =IF(AND(AC$4<=$K11,AC$4+4>=$J11),1,"") | AD11: =IF(AND(AD$4<=$K11,AD$4+4>=$J11),1,"") | AE11: =IF(AND(AE$4<=$K11,AE$4+4>=$J11),1,"") | AF11: =IF(AND(AF$4<=$K11,AF$4+4>=$J11),1,"") | AG11: =IF(AND(AG$4<=$K11,AG$4+4>=$J11),1,"") | ... AS11: =IF(AND(AS$4<=$K11,AS$4+4>=$J11),1,"")
A12: 8 | B12: Estrutural | C12: 3 – Investigação e projeto | D12: Estudo de solo: SPT e poço de inspeção com abertura localizada do piso | E12: Laudo de sondagem | F12: 6 | H12: 5 | J12: =IF(AND(F12="",G12=""),WORKDAY(DataBase-1,1,Feriados),WORKDAY(MAX(IFERROR(INDEX($K$5:$K$32,MATCH(F12,$A$5:$A$32,0)),0),IFERROR(INDEX($K$5:$K$32,MATCH(G12,$A$5:$A$32,0)),0)),1,Feriados)) -> 46331 | K12: =WORKDAY(J12,MAX(H12,1)-1,Feriados) -> 46337 | L12: =SUMIFS(ORCAMENTO!$G$5:$G$200,ORCAMENTO!$H$5:$H$200,A12) -> 38000 | M12: =IF(SUM($L$5:$L$32)=0,0,L12/SUM($L$5:$L$32)) -> 0.086803095 | N12: Não iniciado | R12: =IF(DataRef<J12,0,IF(DataRef>=K12,1,NETWORKDAYS(J12,DataRef,Feriados)/MAX(H12,1))) -> 0 | S12: =N(O12)-R12 -> 0 | T12: =IF(N12="Concluído","Concluída",IF(N12="Bloqueado","BLOQUEADA",IF(DataRef>K12,"ATRASADA",IF(AND(DataRef>=J12,N12="Não iniciado"),"INÍCIO ATRASADO","No prazo")))) -> No prazo | U12: =IF(RelSex<J12,0,IF(RelSex>=K12,1,NETWORKDAYS(J12,RelSex,Feriados)/MAX(H12,1))) -> 0 | V12: =IF(N12="Concluído",COUNTIF($N$5:N12,"Concluído"),"") | W12: =IF(N12="Em andamento",COUNTIF($N$5:N12,"Em andamento"),"") | X12: =IF(AND(N12<>"Concluído",J12<=RelSex+7,K12>RelSex),COUNTIFS($N$5:N12,"<>Concluído",$J$5:J12,"<="&(RelSex+7),$K$5:K12,">"&RelSex),"") | Z12: =IF(AND(Z$4<=$K12,Z$4+4>=$J12),1,"") | AA12: =IF(AND(AA$4<=$K12,AA$4+4>=$J12),1,"") -> 1 | AB12: =IF(AND(AB$4<=$K12,AB$4+4>=$J12),1,"") -> 1 | AC12: =IF(AND(AC$4<=$K12,AC$4+4>=$J12),1,"") | AD12: =IF(AND(AD$4<=$K12,AD$4+4>=$J12),1,"") | AE12: =IF(AND(AE$4<=$K12,AE$4+4>=$J12),1,"") | AF12: =IF(AND(AF$4<=$K12,AF$4+4>=$J12),1,"") | AG12: =IF(AND(AG$4<=$K12,AG$4+4>=$J12),1,"") | ... AS12: =IF(AND(AS$4<=$K12,AS$4+4>=$J12),1,"")
A13: 9 | B13: Estrutural | C13: 3 – Investigação e projeto | D13: Projeto estrutural de reforço (treliça, apoios e fundações) + ART | E13: Projeto executivo aprovado | F13: 8 | G13: 7 | H13: 10 | J13: =IF(AND(F13="",G13=""),WORKDAY(DataBase-1,1,Feriados),WORKDAY(MAX(IFERROR(INDEX($K$5:$K$32,MATCH(F13,$A$5:$A$32,0)),0),IFERROR(INDEX($K$5:$K$32,MATCH(G13,$A$5:$A$32,0)),0)),1,Feriados)) -> 46338 | K13: =WORKDAY(J13,MAX(H13,1)-1,Feriados) -> 46352 | L13: =SUMIFS(ORCAMENTO!$G$5:$G$200,ORCAMENTO!$H$5:$H$200,A13) -> 16293.44 | M13: =IF(SUM($L$5:$L$32)=0,0,L13/SUM($L$5:$L$32)) -> 0.037218974 | N13: Não iniciado | R13: =IF(DataRef<J13,0,IF(DataRef>=K13,1,NETWORKDAYS(J13,DataRef,Feriados)/MAX(H13,1))) -> 0 | S13: =N(O13)-R13 -> 0 | T13: =IF(N13="Concluído","Concluída",IF(N13="Bloqueado","BLOQUEADA",IF(DataRef>K13,"ATRASADA",IF(AND(DataRef>=J13,N13="Não iniciado"),"INÍCIO ATRASADO","No prazo")))) -> No prazo | U13: =IF(RelSex<J13,0,IF(RelSex>=K13,1,NETWORKDAYS(J13,RelSex,Feriados)/MAX(H13,1))) -> 0 | V13: =IF(N13="Concluído",COUNTIF($N$5:N13,"Concluído"),"") | W13: =IF(N13="Em andamento",COUNTIF($N$5:N13,"Em andamento"),"") | X13: =IF(AND(N13<>"Concluído",J13<=RelSex+7,K13>RelSex),COUNTIFS($N$5:N13,"<>Concluído",$J$5:J13,"<="&(RelSex+7),$K$5:K13,">"&RelSex),"") | Z13: =IF(AND(Z$4<=$K13,Z$4+4>=$J13),1,"") | AA13: =IF(AND(AA$4<=$K13,AA$4+4>=$J13),1,"") | AB13: =IF(AND(AB$4<=$K13,AB$4+4>=$J13),1,"") -> 1 | AC13: =IF(AND(AC$4<=$K13,AC$4+4>=$J13),1,"") -> 1 | AD13: =IF(AND(AD$4<=$K13,AD$4+4>=$J13),1,"") -> 1 | AE13: =IF(AND(AE$4<=$K13,AE$4+4>=$J13),1,"") | AF13: =IF(AND(AF$4<=$K13,AF$4+4>=$J13),1,"") | AG13: =IF(AND(AG$4<=$K13,AG$4+4>=$J13),1,"") | ... AS13: =IF(AND(AS$4<=$K13,AS$4+4>=$J13),1,"")
A14: 10 | B14: Estrutural | C14: 3 – Investigação e projeto | D14: Fechar quantitativos e revisar o orçamento da Fase 2 | E14: Escopo e valor aprovados pela DPSP | F14: 9 | H14: 5 | J14: =IF(AND(F14="",G14=""),WORKDAY(DataBase-1,1,Feriados),WORKDAY(MAX(IFERROR(INDEX($K$5:$K$32,MATCH(F14,$A$5:$A$32,0)),0),IFERROR(INDEX($K$5:$K$32,MATCH(G14,$A$5:$A$32,0)),0)),1,Feriados)) -> 46353 | K14: =WORKDAY(J14,MAX(H14,1)-1,Feriados) -> 46359 | L14: =SUMIFS(ORCAMENTO!$G$5:$G$200,ORCAMENTO!$H$5:$H$200,A14) -> 0 | M14: =IF(SUM($L$5:$L$32)=0,0,L14/SUM($L$5:$L$32)) -> 0 | N14: Não iniciado | R14: =IF(DataRef<J14,0,IF(DataRef>=K14,1,NETWORKDAYS(J14,DataRef,Feriados)/MAX(H14,1))) -> 0 | S14: =N(O14)-R14 -> 0 | T14: =IF(N14="Concluído","Concluída",IF(N14="Bloqueado","BLOQUEADA",IF(DataRef>K14,"ATRASADA",IF(AND(DataRef>=J14,N14="Não iniciado"),"INÍCIO ATRASADO","No prazo")))) -> No prazo | U14: =IF(RelSex<J14,0,IF(RelSex>=K14,1,NETWORKDAYS(J14,RelSex,Feriados)/MAX(H14,1))) -> 0 | V14: =IF(N14="Concluído",COUNTIF($N$5:N14,"Concluído"),"") | W14: =IF(N14="Em andamento",COUNTIF($N$5:N14,"Em andamento"),"") | X14: =IF(AND(N14<>"Concluído",J14<=RelSex+7,K14>RelSex),COUNTIFS($N$5:N14,"<>Concluído",$J$5:J14,"<="&(RelSex+7),$K$5:K14,">"&RelSex),"") | Z14: =IF(AND(Z$4<=$K14,Z$4+4>=$J14),1,"") | AA14: =IF(AND(AA$4<=$K14,AA$4+4>=$J14),1,"") | AB14: =IF(AND(AB$4<=$K14,AB$4+4>=$J14),1,"") | AC14: =IF(AND(AC$4<=$K14,AC$4+4>=$J14),1,"") | AD14: =IF(AND(AD$4<=$K14,AD$4+4>=$J14),1,"") -> 1 | AE14: =IF(AND(AE$4<=$K14,AE$4+4>=$J14),1,"") -> 1 | AF14: =IF(AND(AF$4<=$K14,AF$4+4>=$J14),1,"") | AG14: =IF(AND(AG$4<=$K14,AG$4+4>=$J14),1,"") | ... AS14: =IF(AND(AS$4<=$K14,AS$4+4>=$J14),1,"")
A15: 11 | B15: Estrutural | C15: 4 – Desmobilização e demolição | D15: Abertura de porta com retirada de vidro (logística de entulho e materiais) | E15: Acesso liberado | F15: 10 | H15: 1 | J15: =IF(AND(F15="",G15=""),WORKDAY(DataBase-1,1,Feriados),WORKDAY(MAX(IFERROR(INDEX($K$5:$K$32,MATCH(F15,$A$5:$A$32,0)),0),IFERROR(INDEX($K$5:$K$32,MATCH(G15,$A$5:$A$32,0)),0)),1,Feriados)) -> 46360 | K15: =WORKDAY(J15,MAX(H15,1)-1,Feriados) -> 46360 | L15: =SUMIFS(ORCAMENTO!$G$5:$G$200,ORCAMENTO!$H$5:$H$200,A15) -> 2100 | M15: =IF(SUM($L$5:$L$32)=0,0,L15/SUM($L$5:$L$32)) -> 0.0047970131 | N15: Não iniciado | R15: =IF(DataRef<J15,0,IF(DataRef>=K15,1,NETWORKDAYS(J15,DataRef,Feriados)/MAX(H15,1))) -> 0 | S15: =N(O15)-R15 -> 0 | T15: =IF(N15="Concluído","Concluída",IF(N15="Bloqueado","BLOQUEADA",IF(DataRef>K15,"ATRASADA",IF(AND(DataRef>=J15,N15="Não iniciado"),"INÍCIO ATRASADO","No prazo")))) -> No prazo | U15: =IF(RelSex<J15,0,IF(RelSex>=K15,1,NETWORKDAYS(J15,RelSex,Feriados)/MAX(H15,1))) -> 0 | V15: =IF(N15="Concluído",COUNTIF($N$5:N15,"Concluído"),"") | W15: =IF(N15="Em andamento",COUNTIF($N$5:N15,"Em andamento"),"") | X15: =IF(AND(N15<>"Concluído",J15<=RelSex+7,K15>RelSex),COUNTIFS($N$5:N15,"<>Concluído",$J$5:J15,"<="&(RelSex+7),$K$5:K15,">"&RelSex),"") | Z15: =IF(AND(Z$4<=$K15,Z$4+4>=$J15),1,"") | AA15: =IF(AND(AA$4<=$K15,AA$4+4>=$J15),1,"") | AB15: =IF(AND(AB$4<=$K15,AB$4+4>=$J15),1,"") | AC15: =IF(AND(AC$4<=$K15,AC$4+4>=$J15),1,"") | AD15: =IF(AND(AD$4<=$K15,AD$4+4>=$J15),1,"") | AE15: =IF(AND(AE$4<=$K15,AE$4+4>=$J15),1,"") -> 1 | AF15: =IF(AND(AF$4<=$K15,AF$4+4>=$J15),1,"") | AG15: =IF(AND(AG$4<=$K15,AG$4+4>=$J15),1,"") | ... AS15: =IF(AND(AS$4<=$K15,AS$4+4>=$J15),1,"")
A16: 12 | B16: Estrutural | C16: 4 – Desmobilização e demolição | D16: Descarte de gôndolas e geladeira | E16: Termo de baixa de patrimônio DPSP | F16: 10 | H16: 2 | J16: =IF(AND(F16="",G16=""),WORKDAY(DataBase-1,1,Feriados),WORKDAY(MAX(IFERROR(INDEX($K$5:$K$32,MATCH(F16,$A$5:$A$32,0)),0),IFERROR(INDEX($K$5:$K$32,MATCH(G16,$A$5:$A$32,0)),0)),1,Feriados)) -> 46360 | K16: =WORKDAY(J16,MAX(H16,1)-1,Feriados) -> 46363 | L16: =SUMIFS(ORCAMENTO!$G$5:$G$200,ORCAMENTO!$H$5:$H$200,A16) -> 1729 | M16: =IF(SUM($L$5:$L$32)=0,0,L16/SUM($L$5:$L$32)) -> 0.0039495408 | N16: Não iniciado | R16: =IF(DataRef<J16,0,IF(DataRef>=K16,1,NETWORKDAYS(J16,DataRef,Feriados)/MAX(H16,1))) -> 0 | S16: =N(O16)-R16 -> 0 | T16: =IF(N16="Concluído","Concluída",IF(N16="Bloqueado","BLOQUEADA",IF(DataRef>K16,"ATRASADA",IF(AND(DataRef>=J16,N16="Não iniciado"),"INÍCIO ATRASADO","No prazo")))) -> No prazo | U16: =IF(RelSex<J16,0,IF(RelSex>=K16,1,NETWORKDAYS(J16,RelSex,Feriados)/MAX(H16,1))) -> 0 | V16: =IF(N16="Concluído",COUNTIF($N$5:N16,"Concluído"),"") | W16: =IF(N16="Em andamento",COUNTIF($N$5:N16,"Em andamento"),"") | X16: =IF(AND(N16<>"Concluído",J16<=RelSex+7,K16>RelSex),COUNTIFS($N$5:N16,"<>Concluído",$J$5:J16,"<="&(RelSex+7),$K$5:K16,">"&RelSex),"") | Z16: =IF(AND(Z$4<=$K16,Z$4+4>=$J16),1,"") | AA16: =IF(AND(AA$4<=$K16,AA$4+4>=$J16),1,"") | AB16: =IF(AND(AB$4<=$K16,AB$4+4>=$J16),1,"") | AC16: =IF(AND(AC$4<=$K16,AC$4+4>=$J16),1,"") | AD16: =IF(AND(AD$4<=$K16,AD$4+4>=$J16),1,"") | AE16: =IF(AND(AE$4<=$K16,AE$4+4>=$J16),1,"") -> 1 | AF16: =IF(AND(AF$4<=$K16,AF$4+4>=$J16),1,"") -> 1 | AG16: =IF(AND(AG$4<=$K16,AG$4+4>=$J16),1,"") | ... AS16: =IF(AND(AS$4<=$K16,AS$4+4>=$J16),1,"")
A17: 13 | B17: Estrutural | C17: 4 – Desmobilização e demolição | D17: Desmobilização do banheiro | E17: Banheiro liberado para obra | F17: 10 | H17: 2 | J17: =IF(AND(F17="",G17=""),WORKDAY(DataBase-1,1,Feriados),WORKDAY(MAX(IFERROR(INDEX($K$5:$K$32,MATCH(F17,$A$5:$A$32,0)),0),IFERROR(INDEX($K$5:$K$32,MATCH(G17,$A$5:$A$32,0)),0)),1,Feriados)) -> 46360 | K17: =WORKDAY(J17,MAX(H17,1)-1,Feriados) -> 46363 | L17: =SUMIFS(ORCAMENTO!$G$5:$G$200,ORCAMENTO!$H$5:$H$200,A17) -> 438.68 | M17: =IF(SUM($L$5:$L$32)=0,0,L17/SUM($L$5:$L$32)) -> 0.0010020732 | N17: Não iniciado | R17: =IF(DataRef<J17,0,IF(DataRef>=K17,1,NETWORKDAYS(J17,DataRef,Feriados)/MAX(H17,1))) -> 0 | S17: =N(O17)-R17 -> 0 | T17: =IF(N17="Concluído","Concluída",IF(N17="Bloqueado","BLOQUEADA",IF(DataRef>K17,"ATRASADA",IF(AND(DataRef>=J17,N17="Não iniciado"),"INÍCIO ATRASADO","No prazo")))) -> No prazo | U17: =IF(RelSex<J17,0,IF(RelSex>=K17,1,NETWORKDAYS(J17,RelSex,Feriados)/MAX(H17,1))) -> 0 | V17: =IF(N17="Concluído",COUNTIF($N$5:N17,"Concluído"),"") | W17: =IF(N17="Em andamento",COUNTIF($N$5:N17,"Em andamento"),"") | X17: =IF(AND(N17<>"Concluído",J17<=RelSex+7,K17>RelSex),COUNTIFS($N$5:N17,"<>Concluído",$J$5:J17,"<="&(RelSex+7),$K$5:K17,">"&RelSex),"") | Z17: =IF(AND(Z$4<=$K17,Z$4+4>=$J17),1,"") | AA17: =IF(AND(AA$4<=$K17,AA$4+4>=$J17),1,"") | AB17: =IF(AND(AB$4<=$K17,AB$4+4>=$J17),1,"") | AC17: =IF(AND(AC$4<=$K17,AC$4+4>=$J17),1,"") | AD17: =IF(AND(AD$4<=$K17,AD$4+4>=$J17),1,"") | AE17: =IF(AND(AE$4<=$K17,AE$4+4>=$J17),1,"") -> 1 | AF17: =IF(AND(AF$4<=$K17,AF$4+4>=$J17),1,"") -> 1 | AG17: =IF(AND(AG$4<=$K17,AG$4+4>=$J17),1,"") | ... AS17: =IF(AND(AS$4<=$K17,AS$4+4>=$J17),1,"")
A18: 14 | B18: Estrutural | C18: 4 – Desmobilização e demolição | D18: Demolição do piso (revestimento, contrapiso e laje) + descarte com CTR | E18: Solo exposto na área delimitada | F18: 12 | G18: 13 | H18: 5 | J18: =IF(AND(F18="",G18=""),WORKDAY(DataBase-1,1,Feriados),WORKDAY(MAX(IFERROR(INDEX($K$5:$K$32,MATCH(F18,$A$5:$A$32,0)),0),IFERROR(INDEX($K$5:$K$32,MATCH(G18,$A$5:$A$32,0)),0)),1,Feriados)) -> 46364 | K18: =WORKDAY(J18,MAX(H18,1)-1,Feriados) -> 46370 | L18: =SUMIFS(ORCAMENTO!$G$5:$G$200,ORCAMENTO!$H$5:$H$200,A18) -> 23415.86 | M18: =IF(SUM($L$5:$L$32)=0,0,L18/SUM($L$5:$L$32)) -> 0.053488661 | N18: Não iniciado | R18: =IF(DataRef<J18,0,IF(DataRef>=K18,1,NETWORKDAYS(J18,DataRef,Feriados)/MAX(H18,1))) -> 0 | S18: =N(O18)-R18 -> 0 | T18: =IF(N18="Concluído","Concluída",IF(N18="Bloqueado","BLOQUEADA",IF(DataRef>K18,"ATRASADA",IF(AND(DataRef>=J18,N18="Não iniciado"),"INÍCIO ATRASADO","No prazo")))) -> No prazo | U18: =IF(RelSex<J18,0,IF(RelSex>=K18,1,NETWORKDAYS(J18,RelSex,Feriados)/MAX(H18,1))) -> 0 | V18: =IF(N18="Concluído",COUNTIF($N$5:N18,"Concluído"),"") | W18: =IF(N18="Em andamento",COUNTIF($N$5:N18,"Em andamento"),"") | X18: =IF(AND(N18<>"Concluído",J18<=RelSex+7,K18>RelSex),COUNTIFS($N$5:N18,"<>Concluído",$J$5:J18,"<="&(RelSex+7),$K$5:K18,">"&RelSex),"") | Z18: =IF(AND(Z$4<=$K18,Z$4+4>=$J18),1,"") | AA18: =IF(AND(AA$4<=$K18,AA$4+4>=$J18),1,"") | AB18: =IF(AND(AB$4<=$K18,AB$4+4>=$J18),1,"") | AC18: =IF(AND(AC$4<=$K18,AC$4+4>=$J18),1,"") | AD18: =IF(AND(AD$4<=$K18,AD$4+4>=$J18),1,"") | AE18: =IF(AND(AE$4<=$K18,AE$4+4>=$J18),1,"") | AF18: =IF(AND(AF$4<=$K18,AF$4+4>=$J18),1,"") -> 1 | AG18: =IF(AND(AG$4<=$K18,AG$4+4>=$J18),1,"") -> 1 | ... AS18: =IF(AND(AS$4<=$K18,AS$4+4>=$J18),1,"")
A19: 15 | B19: Estrutural | C19: 5 – Reforço e reconstrução | D19: Reforço das fundações de P2/P3 e da treliça, conforme projeto | E19: Estrutura reforçada e conferida pelo RT | F19: 14 | H19: 10 | J19: =IF(AND(F19="",G19=""),WORKDAY(DataBase-1,1,Feriados),WORKDAY(MAX(IFERROR(INDEX($K$5:$K$32,MATCH(F19,$A$5:$A$32,0)),0),IFERROR(INDEX($K$5:$K$32,MATCH(G19,$A$5:$A$32,0)),0)),1,Feriados)) -> 46371 | K19: =WORKDAY(J19,MAX(H19,1)-1,Feriados) -> 46385 | L19: =SUMIFS(ORCAMENTO!$G$5:$G$200,ORCAMENTO!$H$5:$H$200,A19) -> 49000 | M19: =IF(SUM($L$5:$L$32)=0,0,L19/SUM($L$5:$L$32)) -> 0.11193031 | N19: Não iniciado | R19: =IF(DataRef<J19,0,IF(DataRef>=K19,1,NETWORKDAYS(J19,DataRef,Feriados)/MAX(H19,1))) -> 0 | S19: =N(O19)-R19 -> 0 | T19: =IF(N19="Concluído","Concluída",IF(N19="Bloqueado","BLOQUEADA",IF(DataRef>K19,"ATRASADA",IF(AND(DataRef>=J19,N19="Não iniciado"),"INÍCIO ATRASADO","No prazo")))) -> No prazo | U19: =IF(RelSex<J19,0,IF(RelSex>=K19,1,NETWORKDAYS(J19,RelSex,Feriados)/MAX(H19,1))) -> 0 | V19: =IF(N19="Concluído",COUNTIF($N$5:N19,"Concluído"),"") | W19: =IF(N19="Em andamento",COUNTIF($N$5:N19,"Em andamento"),"") | X19: =IF(AND(N19<>"Concluído",J19<=RelSex+7,K19>RelSex),COUNTIFS($N$5:N19,"<>Concluído",$J$5:J19,"<="&(RelSex+7),$K$5:K19,">"&RelSex),"") | Z19: =IF(AND(Z$4<=$K19,Z$4+4>=$J19),1,"") | AA19: =IF(AND(AA$4<=$K19,AA$4+4>=$J19),1,"") | AB19: =IF(AND(AB$4<=$K19,AB$4+4>=$J19),1,"") | AC19: =IF(AND(AC$4<=$K19,AC$4+4>=$J19),1,"") | AD19: =IF(AND(AD$4<=$K19,AD$4+4>=$J19),1,"") | AE19: =IF(AND(AE$4<=$K19,AE$4+4>=$J19),1,"") | AF19: =IF(AND(AF$4<=$K19,AF$4+4>=$J19),1,"") | AG19: =IF(AND(AG$4<=$K19,AG$4+4>=$J19),1,"") -> 1 | ... AS19: =IF(AND(AS$4<=$K19,AS$4+4>=$J19),1,"")
A20: 16 | B20: Estrutural | C20: 5 – Reforço e reconstrução | D20: Remoção do solo inadequado, base de brita e compactação em camadas (máx. 20 cm) | E20: Base aprovada | F20: 14 | H20: 5 | J20: =IF(AND(F20="",G20=""),WORKDAY(DataBase-1,1,Feriados),WORKDAY(MAX(IFERROR(INDEX($K$5:$K$32,MATCH(F20,$A$5:$A$32,0)),0),IFERROR(INDEX($K$5:$K$32,MATCH(G20,$A$5:$A$32,0)),0)),1,Feriados)) -> 46371 | K20: =WORKDAY(J20,MAX(H20,1)-1,Feriados) -> 46377 | L20: =SUMIFS(ORCAMENTO!$G$5:$G$200,ORCAMENTO!$H$5:$H$200,A20) -> 19500 | M20: =IF(SUM($L$5:$L$32)=0,0,L20/SUM($L$5:$L$32)) -> 0.044543693 | N20: Não iniciado | R20: =IF(DataRef<J20,0,IF(DataRef>=K20,1,NETWORKDAYS(J20,DataRef,Feriados)/MAX(H20,1))) -> 0 | S20: =N(O20)-R20 -> 0 | T20: =IF(N20="Concluído","Concluída",IF(N20="Bloqueado","BLOQUEADA",IF(DataRef>K20,"ATRASADA",IF(AND(DataRef>=J20,N20="Não iniciado"),"INÍCIO ATRASADO","No prazo")))) -> No prazo | U20: =IF(RelSex<J20,0,IF(RelSex>=K20,1,NETWORKDAYS(J20,RelSex,Feriados)/MAX(H20,1))) -> 0 | V20: =IF(N20="Concluído",COUNTIF($N$5:N20,"Concluído"),"") | W20: =IF(N20="Em andamento",COUNTIF($N$5:N20,"Em andamento"),"") | X20: =IF(AND(N20<>"Concluído",J20<=RelSex+7,K20>RelSex),COUNTIFS($N$5:N20,"<>Concluído",$J$5:J20,"<="&(RelSex+7),$K$5:K20,">"&RelSex),"") | Z20: =IF(AND(Z$4<=$K20,Z$4+4>=$J20),1,"") | AA20: =IF(AND(AA$4<=$K20,AA$4+4>=$J20),1,"") | AB20: =IF(AND(AB$4<=$K20,AB$4+4>=$J20),1,"") | AC20: =IF(AND(AC$4<=$K20,AC$4+4>=$J20),1,"") | AD20: =IF(AND(AD$4<=$K20,AD$4+4>=$J20),1,"") | AE20: =IF(AND(AE$4<=$K20,AE$4+4>=$J20),1,"") | AF20: =IF(AND(AF$4<=$K20,AF$4+4>=$J20),1,"") | AG20: =IF(AND(AG$4<=$K20,AG$4+4>=$J20),1,"") -> 1 | ... AS20: =IF(AND(AS$4<=$K20,AS$4+4>=$J20),1,"")
A21: 17 | B21: Estrutural | C21: 5 – Reforço e reconstrução | D21: Nova laje de piso armada com nível final (inclui cura) | E21: Laje curada e nivelada | F21: 16 | G21: 15 | H21: 10 | J21: =IF(AND(F21="",G21=""),WORKDAY(DataBase-1,1,Feriados),WORKDAY(MAX(IFERROR(INDEX($K$5:$K$32,MATCH(F21,$A$5:$A$32,0)),0),IFERROR(INDEX($K$5:$K$32,MATCH(G21,$A$5:$A$32,0)),0)),1,Feriados)) -> 46386 | K21: =WORKDAY(J21,MAX(H21,1)-1,Feriados) -> 46400 | L21: =SUMIFS(ORCAMENTO!$G$5:$G$200,ORCAMENTO!$H$5:$H$200,A21) -> 9426 | M21: =IF(SUM($L$5:$L$32)=0,0,L21/SUM($L$5:$L$32)) -> 0.021531736 | N21: Não iniciado | R21: =IF(DataRef<J21,0,IF(DataRef>=K21,1,NETWORKDAYS(J21,DataRef,Feriados)/MAX(H21,1))) -> 0 | S21: =N(O21)-R21 -> 0 | T21: =IF(N21="Concluído","Concluída",IF(N21="Bloqueado","BLOQUEADA",IF(DataRef>K21,"ATRASADA",IF(AND(DataRef>=J21,N21="Não iniciado"),"INÍCIO ATRASADO","No prazo")))) -> No prazo | U21: =IF(RelSex<J21,0,IF(RelSex>=K21,1,NETWORKDAYS(J21,RelSex,Feriados)/MAX(H21,1))) -> 0 | V21: =IF(N21="Concluído",COUNTIF($N$5:N21,"Concluído"),"") | W21: =IF(N21="Em andamento",COUNTIF($N$5:N21,"Em andamento"),"") | X21: =IF(AND(N21<>"Concluído",J21<=RelSex+7,K21>RelSex),COUNTIFS($N$5:N21,"<>Concluído",$J$5:J21,"<="&(RelSex+7),$K$5:K21,">"&RelSex),"") | Z21: =IF(AND(Z$4<=$K21,Z$4+4>=$J21),1,"") | AA21: =IF(AND(AA$4<=$K21,AA$4+4>=$J21),1,"") | AB21: =IF(AND(AB$4<=$K21,AB$4+4>=$J21),1,"") | AC21: =IF(AND(AC$4<=$K21,AC$4+4>=$J21),1,"") | AD21: =IF(AND(AD$4<=$K21,AD$4+4>=$J21),1,"") | AE21: =IF(AND(AE$4<=$K21,AE$4+4>=$J21),1,"") | AF21: =IF(AND(AF$4<=$K21,AF$4+4>=$J21),1,"") | AG21: =IF(AND(AG$4<=$K21,AG$4+4>=$J21),1,"") | ... AS21: =IF(AND(AS$4<=$K21,AS$4+4>=$J21),1,"")
A22: 18 | B22: Estrutural | C22: 5 – Reforço e reconstrução | D22: Piso do banheiro e revestimento do salão | E22: Piso entregue | F22: 17 | H22: 8 | J22: =IF(AND(F22="",G22=""),WORKDAY(DataBase-1,1,Feriados),WORKDAY(MAX(IFERROR(INDEX($K$5:$K$32,MATCH(F22,$A$5:$A$32,0)),0),IFERROR(INDEX($K$5:$K$32,MATCH(G22,$A$5:$A$32,0)),0)),1,Feriados)) -> 46401 | K22: =WORKDAY(J22,MAX(H22,1)-1,Feriados) -> 46412 | L22: =SUMIFS(ORCAMENTO!$G$5:$G$200,ORCAMENTO!$H$5:$H$200,A22) -> 28000 | M22: =IF(SUM($L$5:$L$32)=0,0,L22/SUM($L$5:$L$32)) -> 0.063960175 | N22: Não iniciado | R22: =IF(DataRef<J22,0,IF(DataRef>=K22,1,NETWORKDAYS(J22,DataRef,Feriados)/MAX(H22,1))) -> 0 | S22: =N(O22)-R22 -> 0 | T22: =IF(N22="Concluído","Concluída",IF(N22="Bloqueado","BLOQUEADA",IF(DataRef>K22,"ATRASADA",IF(AND(DataRef>=J22,N22="Não iniciado"),"INÍCIO ATRASADO","No prazo")))) -> No prazo | U22: =IF(RelSex<J22,0,IF(RelSex>=K22,1,NETWORKDAYS(J22,RelSex,Feriados)/MAX(H22,1))) -> 0 | V22: =IF(N22="Concluído",COUNTIF($N$5:N22,"Concluído"),"") | W22: =IF(N22="Em andamento",COUNTIF($N$5:N22,"Em andamento"),"") | X22: =IF(AND(N22<>"Concluído",J22<=RelSex+7,K22>RelSex),COUNTIFS($N$5:N22,"<>Concluído",$J$5:J22,"<="&(RelSex+7),$K$5:K22,">"&RelSex),"") | Z22: =IF(AND(Z$4<=$K22,Z$4+4>=$J22),1,"") | AA22: =IF(AND(AA$4<=$K22,AA$4+4>=$J22),1,"") | AB22: =IF(AND(AB$4<=$K22,AB$4+4>=$J22),1,"") | AC22: =IF(AND(AC$4<=$K22,AC$4+4>=$J22),1,"") | AD22: =IF(AND(AD$4<=$K22,AD$4+4>=$J22),1,"") | AE22: =IF(AND(AE$4<=$K22,AE$4+4>=$J22),1,"") | AF22: =IF(AND(AF$4<=$K22,AF$4+4>=$J22),1,"") | AG22: =IF(AND(AG$4<=$K22,AG$4+4>=$J22),1,"") | ... AS22: =IF(AND(AS$4<=$K22,AS$4+4>=$J22),1,"")
A23: 19 | B23: Estrutural | C23: 6 – Acabamentos e entrega | D23: Recuperação do mezanino: drywall, piso cerâmico, copa e WCs | E23: Mezanino recuperado | F23: 15 | H23: 8 | J23: =IF(AND(F23="",G23=""),WORKDAY(DataBase-1,1,Feriados),WORKDAY(MAX(IFERROR(INDEX($K$5:$K$32,MATCH(F23,$A$5:$A$32,0)),0),IFERROR(INDEX($K$5:$K$32,MATCH(G23,$A$5:$A$32,0)),0)),1,Feriados)) -> 46386 | K23: =WORKDAY(J23,MAX(H23,1)-1,Feriados) -> 46398 | L23: =SUMIFS(ORCAMENTO!$G$5:$G$200,ORCAMENTO!$H$5:$H$200,A23) -> 20000 | M23: =IF(SUM($L$5:$L$32)=0,0,L23/SUM($L$5:$L$32)) -> 0.045685839 | N23: Não iniciado | R23: =IF(DataRef<J23,0,IF(DataRef>=K23,1,NETWORKDAYS(J23,DataRef,Feriados)/MAX(H23,1))) -> 0 | S23: =N(O23)-R23 -> 0 | T23: =IF(N23="Concluído","Concluída",IF(N23="Bloqueado","BLOQUEADA",IF(DataRef>K23,"ATRASADA",IF(AND(DataRef>=J23,N23="Não iniciado"),"INÍCIO ATRASADO","No prazo")))) -> No prazo | U23: =IF(RelSex<J23,0,IF(RelSex>=K23,1,NETWORKDAYS(J23,RelSex,Feriados)/MAX(H23,1))) -> 0 | V23: =IF(N23="Concluído",COUNTIF($N$5:N23,"Concluído"),"") | W23: =IF(N23="Em andamento",COUNTIF($N$5:N23,"Em andamento"),"") | X23: =IF(AND(N23<>"Concluído",J23<=RelSex+7,K23>RelSex),COUNTIFS($N$5:N23,"<>Concluído",$J$5:J23,"<="&(RelSex+7),$K$5:K23,">"&RelSex),"") | Z23: =IF(AND(Z$4<=$K23,Z$4+4>=$J23),1,"") | AA23: =IF(AND(AA$4<=$K23,AA$4+4>=$J23),1,"") | AB23: =IF(AND(AB$4<=$K23,AB$4+4>=$J23),1,"") | AC23: =IF(AND(AC$4<=$K23,AC$4+4>=$J23),1,"") | AD23: =IF(AND(AD$4<=$K23,AD$4+4>=$J23),1,"") | AE23: =IF(AND(AE$4<=$K23,AE$4+4>=$J23),1,"") | AF23: =IF(AND(AF$4<=$K23,AF$4+4>=$J23),1,"") | AG23: =IF(AND(AG$4<=$K23,AG$4+4>=$J23),1,"") | ... AS23: =IF(AND(AS$4<=$K23,AS$4+4>=$J23),1,"")
A24: 20 | B24: Estrutural | C24: 6 – Acabamentos e entrega | D24: Retirada do escoramento, conferência final de níveis, limpeza e liberação | E24: Loja liberada; relatório "depois" | F24: 18 | G24: 27 | H24: 3 | J24: =IF(AND(F24="",G24=""),WORKDAY(DataBase-1,1,Feriados),WORKDAY(MAX(IFERROR(INDEX($K$5:$K$32,MATCH(F24,$A$5:$A$32,0)),0),IFERROR(INDEX($K$5:$K$32,MATCH(G24,$A$5:$A$32,0)),0)),1,Feriados)) -> 46413 | K24: =WORKDAY(J24,MAX(H24,1)-1,Feriados) -> 46415 | L24: =SUMIFS(ORCAMENTO!$G$5:$G$200,ORCAMENTO!$H$5:$H$200,A24) -> 13656 | M24: =IF(SUM($L$5:$L$32)=0,0,L24/SUM($L$5:$L$32)) -> 0.031194291 | N24: Não iniciado | R24: =IF(DataRef<J24,0,IF(DataRef>=K24,1,NETWORKDAYS(J24,DataRef,Feriados)/MAX(H24,1))) -> 0 | S24: =N(O24)-R24 -> 0 | T24: =IF(N24="Concluído","Concluída",IF(N24="Bloqueado","BLOQUEADA",IF(DataRef>K24,"ATRASADA",IF(AND(DataRef>=J24,N24="Não iniciado"),"INÍCIO ATRASADO","No prazo")))) -> No prazo | U24: =IF(RelSex<J24,0,IF(RelSex>=K24,1,NETWORKDAYS(J24,RelSex,Feriados)/MAX(H24,1))) -> 0 | V24: =IF(N24="Concluído",COUNTIF($N$5:N24,"Concluído"),"") | W24: =IF(N24="Em andamento",COUNTIF($N$5:N24,"Em andamento"),"") | X24: =IF(AND(N24<>"Concluído",J24<=RelSex+7,K24>RelSex),COUNTIFS($N$5:N24,"<>Concluído",$J$5:J24,"<="&(RelSex+7),$K$5:K24,">"&RelSex),"") | Z24: =IF(AND(Z$4<=$K24,Z$4+4>=$J24),1,"") | AA24: =IF(AND(AA$4<=$K24,AA$4+4>=$J24),1,"") | AB24: =IF(AND(AB$4<=$K24,AB$4+4>=$J24),1,"") | AC24: =IF(AND(AC$4<=$K24,AC$4+4>=$J24),1,"") | AD24: =IF(AND(AD$4<=$K24,AD$4+4>=$J24),1,"") | AE24: =IF(AND(AE$4<=$K24,AE$4+4>=$J24),1,"") | AF24: =IF(AND(AF$4<=$K24,AF$4+4>=$J24),1,"") | AG24: =IF(AND(AG$4<=$K24,AG$4+4>=$J24),1,"") | ... AS24: =IF(AND(AS$4<=$K24,AS$4+4>=$J24),1,"")
A25: 21 | B25: Reforma light | C25: R – Reforma light | D25: Demolição de forro (250 m²) e drywall (100 m²) | E25: Somente após nº 6 concluído | F25: 6 | H25: 4 | J25: =IF(AND(F25="",G25=""),WORKDAY(DataBase-1,1,Feriados),WORKDAY(MAX(IFERROR(INDEX($K$5:$K$32,MATCH(F25,$A$5:$A$32,0)),0),IFERROR(INDEX($K$5:$K$32,MATCH(G25,$A$5:$A$32,0)),0)),1,Feriados)) -> 46331 | K25: =WORKDAY(J25,MAX(H25,1)-1,Feriados) -> 46336 | L25: =SUMIFS(ORCAMENTO!$G$5:$G$200,ORCAMENTO!$H$5:$H$200,A25) -> 2122.5 | M25: =IF(SUM($L$5:$L$32)=0,0,L25/SUM($L$5:$L$32)) -> 0.0048484097 | N25: Não iniciado | R25: =IF(DataRef<J25,0,IF(DataRef>=K25,1,NETWORKDAYS(J25,DataRef,Feriados)/MAX(H25,1))) -> 0 | S25: =N(O25)-R25 -> 0 | T25: =IF(N25="Concluído","Concluída",IF(N25="Bloqueado","BLOQUEADA",IF(DataRef>K25,"ATRASADA",IF(AND(DataRef>=J25,N25="Não iniciado"),"INÍCIO ATRASADO","No prazo")))) -> No prazo | U25: =IF(RelSex<J25,0,IF(RelSex>=K25,1,NETWORKDAYS(J25,RelSex,Feriados)/MAX(H25,1))) -> 0 | V25: =IF(N25="Concluído",COUNTIF($N$5:N25,"Concluído"),"") | W25: =IF(N25="Em andamento",COUNTIF($N$5:N25,"Em andamento"),"") | X25: =IF(AND(N25<>"Concluído",J25<=RelSex+7,K25>RelSex),COUNTIFS($N$5:N25,"<>Concluído",$J$5:J25,"<="&(RelSex+7),$K$5:K25,">"&RelSex),"") | Z25: =IF(AND(Z$4<=$K25,Z$4+4>=$J25),1,"") | AA25: =IF(AND(AA$4<=$K25,AA$4+4>=$J25),1,"") -> 1 | AB25: =IF(AND(AB$4<=$K25,AB$4+4>=$J25),1,"") -> 1 | AC25: =IF(AND(AC$4<=$K25,AC$4+4>=$J25),1,"") | AD25: =IF(AND(AD$4<=$K25,AD$4+4>=$J25),1,"") | AE25: =IF(AND(AE$4<=$K25,AE$4+4>=$J25),1,"") | AF25: =IF(AND(AF$4<=$K25,AF$4+4>=$J25),1,"") | AG25: =IF(AND(AG$4<=$K25,AG$4+4>=$J25),1,"") | ... AS25: =IF(AND(AS$4<=$K25,AS$4+4>=$J25),1,"")
A26: 22 | B26: Reforma light | C26: R – Reforma light | D26: Infraestrutura elétrica, rede, iluminação e ativações | E26: Circuitos testados | F26: 21 | H26: 10 | J26: =IF(AND(F26="",G26=""),WORKDAY(DataBase-1,1,Feriados),WORKDAY(MAX(IFERROR(INDEX($K$5:$K$32,MATCH(F26,$A$5:$A$32,0)),0),IFERROR(INDEX($K$5:$K$32,MATCH(G26,$A$5:$A$32,0)),0)),1,Feriados)) -> 46337 | K26: =WORKDAY(J26,MAX(H26,1)-1,Feriados) -> 46351 | L26: =SUMIFS(ORCAMENTO!$G$5:$G$200,ORCAMENTO!$H$5:$H$200,A26) -> 38254.25 | M26: =IF(SUM($L$5:$L$32)=0,0,L26/SUM($L$5:$L$32)) -> 0.087383876 | N26: Não iniciado | R26: =IF(DataRef<J26,0,IF(DataRef>=K26,1,NETWORKDAYS(J26,DataRef,Feriados)/MAX(H26,1))) -> 0 | S26: =N(O26)-R26 -> 0 | T26: =IF(N26="Concluído","Concluída",IF(N26="Bloqueado","BLOQUEADA",IF(DataRef>K26,"ATRASADA",IF(AND(DataRef>=J26,N26="Não iniciado"),"INÍCIO ATRASADO","No prazo")))) -> No prazo | U26: =IF(RelSex<J26,0,IF(RelSex>=K26,1,NETWORKDAYS(J26,RelSex,Feriados)/MAX(H26,1))) -> 0 | V26: =IF(N26="Concluído",COUNTIF($N$5:N26,"Concluído"),"") | W26: =IF(N26="Em andamento",COUNTIF($N$5:N26,"Em andamento"),"") | X26: =IF(AND(N26<>"Concluído",J26<=RelSex+7,K26>RelSex),COUNTIFS($N$5:N26,"<>Concluído",$J$5:J26,"<="&(RelSex+7),$K$5:K26,">"&RelSex),"") | Z26: =IF(AND(Z$4<=$K26,Z$4+4>=$J26),1,"") | AA26: =IF(AND(AA$4<=$K26,AA$4+4>=$J26),1,"") | AB26: =IF(AND(AB$4<=$K26,AB$4+4>=$J26),1,"") -> 1 | AC26: =IF(AND(AC$4<=$K26,AC$4+4>=$J26),1,"") -> 1 | AD26: =IF(AND(AD$4<=$K26,AD$4+4>=$J26),1,"") -> 1 | AE26: =IF(AND(AE$4<=$K26,AE$4+4>=$J26),1,"") | AF26: =IF(AND(AF$4<=$K26,AF$4+4>=$J26),1,"") | AG26: =IF(AND(AG$4<=$K26,AG$4+4>=$J26),1,"") | ... AS26: =IF(AND(AS$4<=$K26,AS$4+4>=$J26),1,"")
A27: 23 | B27: Reforma light | C27: R – Reforma light | D27: Ar-condicionado: retirada, reinstalação de splits e drenos | E27: Equipamentos operando | F27: 21 | H27: 5 | J27: =IF(AND(F27="",G27=""),WORKDAY(DataBase-1,1,Feriados),WORKDAY(MAX(IFERROR(INDEX($K$5:$K$32,MATCH(F27,$A$5:$A$32,0)),0),IFERROR(INDEX($K$5:$K$32,MATCH(G27,$A$5:$A$32,0)),0)),1,Feriados)) -> 46337 | K27: =WORKDAY(J27,MAX(H27,1)-1,Feriados) -> 46343 | L27: =SUMIFS(ORCAMENTO!$G$5:$G$200,ORCAMENTO!$H$5:$H$200,A27) -> 22042.6 | M27: =IF(SUM($L$5:$L$32)=0,0,L27/SUM($L$5:$L$32)) -> 0.050351734 | N27: Não iniciado | R27: =IF(DataRef<J27,0,IF(DataRef>=K27,1,NETWORKDAYS(J27,DataRef,Feriados)/MAX(H27,1))) -> 0 | S27: =N(O27)-R27 -> 0 | T27: =IF(N27="Concluído","Concluída",IF(N27="Bloqueado","BLOQUEADA",IF(DataRef>K27,"ATRASADA",IF(AND(DataRef>=J27,N27="Não iniciado"),"INÍCIO ATRASADO","No prazo")))) -> No prazo | U27: =IF(RelSex<J27,0,IF(RelSex>=K27,1,NETWORKDAYS(J27,RelSex,Feriados)/MAX(H27,1))) -> 0 | V27: =IF(N27="Concluído",COUNTIF($N$5:N27,"Concluído"),"") | W27: =IF(N27="Em andamento",COUNTIF($N$5:N27,"Em andamento"),"") | X27: =IF(AND(N27<>"Concluído",J27<=RelSex+7,K27>RelSex),COUNTIFS($N$5:N27,"<>Concluído",$J$5:J27,"<="&(RelSex+7),$K$5:K27,">"&RelSex),"") | Z27: =IF(AND(Z$4<=$K27,Z$4+4>=$J27),1,"") | AA27: =IF(AND(AA$4<=$K27,AA$4+4>=$J27),1,"") | AB27: =IF(AND(AB$4<=$K27,AB$4+4>=$J27),1,"") -> 1 | AC27: =IF(AND(AC$4<=$K27,AC$4+4>=$J27),1,"") -> 1 | AD27: =IF(AND(AD$4<=$K27,AD$4+4>=$J27),1,"") | AE27: =IF(AND(AE$4<=$K27,AE$4+4>=$J27),1,"") | AF27: =IF(AND(AF$4<=$K27,AF$4+4>=$J27),1,"") | AG27: =IF(AND(AG$4<=$K27,AG$4+4>=$J27),1,"") | ... AS27: =IF(AND(AS$4<=$K27,AS$4+4>=$J27),1,"")
A28: 24 | B28: Reforma light | C28: R – Reforma light | D28: Drywall novo (190 m²) com reforço em MDF | E28: No mezanino, só após nº 15 | F28: 22 | H28: 6 | J28: =IF(AND(F28="",G28=""),WORKDAY(DataBase-1,1,Feriados),WORKDAY(MAX(IFERROR(INDEX($K$5:$K$32,MATCH(F28,$A$5:$A$32,0)),0),IFERROR(INDEX($K$5:$K$32,MATCH(G28,$A$5:$A$32,0)),0)),1,Feriados)) -> 46352 | K28: =WORKDAY(J28,MAX(H28,1)-1,Feriados) -> 46359 | L28: =SUMIFS(ORCAMENTO!$G$5:$G$200,ORCAMENTO!$H$5:$H$200,A28) -> 24917.6 | M28: =IF(SUM($L$5:$L$32)=0,0,L28/SUM($L$5:$L$32)) -> 0.056919074 | N28: Não iniciado | R28: =IF(DataRef<J28,0,IF(DataRef>=K28,1,NETWORKDAYS(J28,DataRef,Feriados)/MAX(H28,1))) -> 0 | S28: =N(O28)-R28 -> 0 | T28: =IF(N28="Concluído","Concluída",IF(N28="Bloqueado","BLOQUEADA",IF(DataRef>K28,"ATRASADA",IF(AND(DataRef>=J28,N28="Não iniciado"),"INÍCIO ATRASADO","No prazo")))) -> No prazo | U28: =IF(RelSex<J28,0,IF(RelSex>=K28,1,NETWORKDAYS(J28,RelSex,Feriados)/MAX(H28,1))) -> 0 | V28: =IF(N28="Concluído",COUNTIF($N$5:N28,"Concluído"),"") | W28: =IF(N28="Em andamento",COUNTIF($N$5:N28,"Em andamento"),"") | X28: =IF(AND(N28<>"Concluído",J28<=RelSex+7,K28>RelSex),COUNTIFS($N$5:N28,"<>Concluído",$J$5:J28,"<="&(RelSex+7),$K$5:K28,">"&RelSex),"") | Z28: =IF(AND(Z$4<=$K28,Z$4+4>=$J28),1,"") | AA28: =IF(AND(AA$4<=$K28,AA$4+4>=$J28),1,"") | AB28: =IF(AND(AB$4<=$K28,AB$4+4>=$J28),1,"") | AC28: =IF(AND(AC$4<=$K28,AC$4+4>=$J28),1,"") | AD28: =IF(AND(AD$4<=$K28,AD$4+4>=$J28),1,"") -> 1 | AE28: =IF(AND(AE$4<=$K28,AE$4+4>=$J28),1,"") -> 1 | AF28: =IF(AND(AF$4<=$K28,AF$4+4>=$J28),1,"") | AG28: =IF(AND(AG$4<=$K28,AG$4+4>=$J28),1,"") | ... AS28: =IF(AND(AS$4<=$K28,AS$4+4>=$J28),1,"")
A29: 25 | B29: Reforma light | C29: R – Reforma light | D29: Forro mineral (250 m²) e abertura de luminárias | E29: Forro fechado | F29: 24 | G29: 23 | H29: 6 | J29: =IF(AND(F29="",G29=""),WORKDAY(DataBase-1,1,Feriados),WORKDAY(MAX(IFERROR(INDEX($K$5:$K$32,MATCH(F29,$A$5:$A$32,0)),0),IFERROR(INDEX($K$5:$K$32,MATCH(G29,$A$5:$A$32,0)),0)),1,Feriados)) -> 46360 | K29: =WORKDAY(J29,MAX(H29,1)-1,Feriados) -> 46367 | L29: =SUMIFS(ORCAMENTO!$G$5:$G$200,ORCAMENTO!$H$5:$H$200,A29) -> 35648.08 | M29: =IF(SUM($L$5:$L$32)=0,0,L29/SUM($L$5:$L$32)) -> 0.081430622 | N29: Não iniciado | R29: =IF(DataRef<J29,0,IF(DataRef>=K29,1,NETWORKDAYS(J29,DataRef,Feriados)/MAX(H29,1))) -> 0 | S29: =N(O29)-R29 -> 0 | T29: =IF(N29="Concluído","Concluída",IF(N29="Bloqueado","BLOQUEADA",IF(DataRef>K29,"ATRASADA",IF(AND(DataRef>=J29,N29="Não iniciado"),"INÍCIO ATRASADO","No prazo")))) -> No prazo | U29: =IF(RelSex<J29,0,IF(RelSex>=K29,1,NETWORKDAYS(J29,RelSex,Feriados)/MAX(H29,1))) -> 0 | V29: =IF(N29="Concluído",COUNTIF($N$5:N29,"Concluído"),"") | W29: =IF(N29="Em andamento",COUNTIF($N$5:N29,"Em andamento"),"") | X29: =IF(AND(N29<>"Concluído",J29<=RelSex+7,K29>RelSex),COUNTIFS($N$5:N29,"<>Concluído",$J$5:J29,"<="&(RelSex+7),$K$5:K29,">"&RelSex),"") | Z29: =IF(AND(Z$4<=$K29,Z$4+4>=$J29),1,"") | AA29: =IF(AND(AA$4<=$K29,AA$4+4>=$J29),1,"") | AB29: =IF(AND(AB$4<=$K29,AB$4+4>=$J29),1,"") | AC29: =IF(AND(AC$4<=$K29,AC$4+4>=$J29),1,"") | AD29: =IF(AND(AD$4<=$K29,AD$4+4>=$J29),1,"") | AE29: =IF(AND(AE$4<=$K29,AE$4+4>=$J29),1,"") -> 1 | AF29: =IF(AND(AF$4<=$K29,AF$4+4>=$J29),1,"") -> 1 | AG29: =IF(AND(AG$4<=$K29,AG$4+4>=$J29),1,"") | ... AS29: =IF(AND(AS$4<=$K29,AS$4+4>=$J29),1,"")
A30: 26 | B30: Reforma light | C30: R – Reforma light | D30: Portas, molas, grelhas, guia de porta de enrolar e fechadura | E30: Esquadrias instaladas | F30: 24 | H30: 4 | J30: =IF(AND(F30="",G30=""),WORKDAY(DataBase-1,1,Feriados),WORKDAY(MAX(IFERROR(INDEX($K$5:$K$32,MATCH(F30,$A$5:$A$32,0)),0),IFERROR(INDEX($K$5:$K$32,MATCH(G30,$A$5:$A$32,0)),0)),1,Feriados)) -> 46360 | K30: =WORKDAY(J30,MAX(H30,1)-1,Feriados) -> 46365 | L30: =SUMIFS(ORCAMENTO!$G$5:$G$200,ORCAMENTO!$H$5:$H$200,A30) -> 14246.2 | M30: =IF(SUM($L$5:$L$32)=0,0,L30/SUM($L$5:$L$32)) -> 0.03254248 | N30: Não iniciado | R30: =IF(DataRef<J30,0,IF(DataRef>=K30,1,NETWORKDAYS(J30,DataRef,Feriados)/MAX(H30,1))) -> 0 | S30: =N(O30)-R30 -> 0 | T30: =IF(N30="Concluído","Concluída",IF(N30="Bloqueado","BLOQUEADA",IF(DataRef>K30,"ATRASADA",IF(AND(DataRef>=J30,N30="Não iniciado"),"INÍCIO ATRASADO","No prazo")))) -> No prazo | U30: =IF(RelSex<J30,0,IF(RelSex>=K30,1,NETWORKDAYS(J30,RelSex,Feriados)/MAX(H30,1))) -> 0 | V30: =IF(N30="Concluído",COUNTIF($N$5:N30,"Concluído"),"") | W30: =IF(N30="Em andamento",COUNTIF($N$5:N30,"Em andamento"),"") | X30: =IF(AND(N30<>"Concluído",J30<=RelSex+7,K30>RelSex),COUNTIFS($N$5:N30,"<>Concluído",$J$5:J30,"<="&(RelSex+7),$K$5:K30,">"&RelSex),"") | Z30: =IF(AND(Z$4<=$K30,Z$4+4>=$J30),1,"") | AA30: =IF(AND(AA$4<=$K30,AA$4+4>=$J30),1,"") | AB30: =IF(AND(AB$4<=$K30,AB$4+4>=$J30),1,"") | AC30: =IF(AND(AC$4<=$K30,AC$4+4>=$J30),1,"") | AD30: =IF(AND(AD$4<=$K30,AD$4+4>=$J30),1,"") | AE30: =IF(AND(AE$4<=$K30,AE$4+4>=$J30),1,"") -> 1 | AF30: =IF(AND(AF$4<=$K30,AF$4+4>=$J30),1,"") -> 1 | AG30: =IF(AND(AG$4<=$K30,AG$4+4>=$J30),1,"") | ... AS30: =IF(AND(AS$4<=$K30,AS$4+4>=$J30),1,"")
A31: 27 | B31: Reforma light | C31: R – Reforma light | D31: Pintura (fundo, massa e acabamento) | E31: Pintura concluída | F31: 25 | G31: 19 | H31: 6 | J31: =IF(AND(F31="",G31=""),WORKDAY(DataBase-1,1,Feriados),WORKDAY(MAX(IFERROR(INDEX($K$5:$K$32,MATCH(F31,$A$5:$A$32,0)),0),IFERROR(INDEX($K$5:$K$32,MATCH(G31,$A$5:$A$32,0)),0)),1,Feriados)) -> 46399 | K31: =WORKDAY(J31,MAX(H31,1)-1,Feriados) -> 46406 | L31: =SUMIFS(ORCAMENTO!$G$5:$G$200,ORCAMENTO!$H$5:$H$200,A31) -> 13620 | M31: =IF(SUM($L$5:$L$32)=0,0,L31/SUM($L$5:$L$32)) -> 0.031112057 | N31: Não iniciado | R31: =IF(DataRef<J31,0,IF(DataRef>=K31,1,NETWORKDAYS(J31,DataRef,Feriados)/MAX(H31,1))) -> 0 | S31: =N(O31)-R31 -> 0 | T31: =IF(N31="Concluído","Concluída",IF(N31="Bloqueado","BLOQUEADA",IF(DataRef>K31,"ATRASADA",IF(AND(DataRef>=J31,N31="Não iniciado"),"INÍCIO ATRASADO","No prazo")))) -> No prazo | U31: =IF(RelSex<J31,0,IF(RelSex>=K31,1,NETWORKDAYS(J31,RelSex,Feriados)/MAX(H31,1))) -> 0 | V31: =IF(N31="Concluído",COUNTIF($N$5:N31,"Concluído"),"") | W31: =IF(N31="Em andamento",COUNTIF($N$5:N31,"Em andamento"),"") | X31: =IF(AND(N31<>"Concluído",J31<=RelSex+7,K31>RelSex),COUNTIFS($N$5:N31,"<>Concluído",$J$5:J31,"<="&(RelSex+7),$K$5:K31,">"&RelSex),"") | Z31: =IF(AND(Z$4<=$K31,Z$4+4>=$J31),1,"") | AA31: =IF(AND(AA$4<=$K31,AA$4+4>=$J31),1,"") | AB31: =IF(AND(AB$4<=$K31,AB$4+4>=$J31),1,"") | AC31: =IF(AND(AC$4<=$K31,AC$4+4>=$J31),1,"") | AD31: =IF(AND(AD$4<=$K31,AD$4+4>=$J31),1,"") | AE31: =IF(AND(AE$4<=$K31,AE$4+4>=$J31),1,"") | AF31: =IF(AND(AF$4<=$K31,AF$4+4>=$J31),1,"") | AG31: =IF(AND(AG$4<=$K31,AG$4+4>=$J31),1,"") | ... AS31: =IF(AND(AS$4<=$K31,AS$4+4>=$J31),1,"")
A32: 28 | B32: Reforma light | C32: R – Reforma light | D32: Fachada: fixação de vidros e pintura | E32: Fachada entregue | F32: 11 | H32: 3 | J32: =IF(AND(F32="",G32=""),WORKDAY(DataBase-1,1,Feriados),WORKDAY(MAX(IFERROR(INDEX($K$5:$K$32,MATCH(F32,$A$5:$A$32,0)),0),IFERROR(INDEX($K$5:$K$32,MATCH(G32,$A$5:$A$32,0)),0)),1,Feriados)) -> 46363 | K32: =WORKDAY(J32,MAX(H32,1)-1,Feriados) -> 46365 | L32: =SUMIFS(ORCAMENTO!$G$5:$G$200,ORCAMENTO!$H$5:$H$200,A32) -> 3792 | M32: =IF(SUM($L$5:$L$32)=0,0,L32/SUM($L$5:$L$32)) -> 0.0086620352 | N32: Não iniciado | R32: =IF(DataRef<J32,0,IF(DataRef>=K32,1,NETWORKDAYS(J32,DataRef,Feriados)/MAX(H32,1))) -> 0 | S32: =N(O32)-R32 -> 0 | T32: =IF(N32="Concluído","Concluída",IF(N32="Bloqueado","BLOQUEADA",IF(DataRef>K32,"ATRASADA",IF(AND(DataRef>=J32,N32="Não iniciado"),"INÍCIO ATRASADO","No prazo")))) -> No prazo | U32: =IF(RelSex<J32,0,IF(RelSex>=K32,1,NETWORKDAYS(J32,RelSex,Feriados)/MAX(H32,1))) -> 0 | V32: =IF(N32="Concluído",COUNTIF($N$5:N32,"Concluído"),"") | W32: =IF(N32="Em andamento",COUNTIF($N$5:N32,"Em andamento"),"") | X32: =IF(AND(N32<>"Concluído",J32<=RelSex+7,K32>RelSex),COUNTIFS($N$5:N32,"<>Concluído",$J$5:J32,"<="&(RelSex+7),$K$5:K32,">"&RelSex),"") | Z32: =IF(AND(Z$4<=$K32,Z$4+4>=$J32),1,"") | AA32: =IF(AND(AA$4<=$K32,AA$4+4>=$J32),1,"") | AB32: =IF(AND(AB$4<=$K32,AB$4+4>=$J32),1,"") | AC32: =IF(AND(AC$4<=$K32,AC$4+4>=$J32),1,"") | AD32: =IF(AND(AD$4<=$K32,AD$4+4>=$J32),1,"") | AE32: =IF(AND(AE$4<=$K32,AE$4+4>=$J32),1,"") | AF32: =IF(AND(AF$4<=$K32,AF$4+4>=$J32),1,"") -> 1 | AG32: =IF(AND(AG$4<=$K32,AG$4+4>=$J32),1,"") | ... AS32: =IF(AND(AS$4<=$K32,AS$4+4>=$J32),1,"")
D34: Total | L34: =SUM(L5:L32) -> 437772.41 | M34: =SUM(M5:M32) -> 1
D35: Valor de orçamento sem atividade (indiretos e imposto – fora do peso) | L35: =SUMIFS(ORCAMENTO!$G$5:$G$200,ORCAMENTO!$H$5:$H$200,0) -> 68568

Sheet CURVA_S
A1: Curva S – avanço previsto x realizado (semanal)
A2: Previsto calculado do cronograma. Realizado: toda sexta, copie aqui o avanço realizado do PAINEL (linha amarela).
B3: Sexta-feira | C3: =DataBase+MOD(5-WEEKDAY(DataBase,2),7)+0 -> 46325 | D3: =DataBase+MOD(5-WEEKDAY(DataBase,2),7)+7 -> 46332 | E3: =DataBase+MOD(5-WEEKDAY(DataBase,2),7)+14 -> 46339 | F3: =DataBase+MOD(5-WEEKDAY(DataBase,2),7)+21 -> 46346 | G3: =DataBase+MOD(5-WEEKDAY(DataBase,2),7)+28 -> 46353 | H3: =DataBase+MOD(5-WEEKDAY(DataBase,2),7)+35 -> 46360 | I3: =DataBase+MOD(5-WEEKDAY(DataBase,2),7)+42 -> 46367 | J3: =DataBase+MOD(5-WEEKDAY(DataBase,2),7)+49 -> 46374 | K3: =DataBase+MOD(5-WEEKDAY(DataBase,2),7)+56 -> 46381 | L3: =DataBase+MOD(5-WEEKDAY(DataBase,2),7)+63 -> 46388 | M3: =DataBase+MOD(5-WEEKDAY(DataBase,2),7)+70 -> 46395 | N3: =DataBase+MOD(5-WEEKDAY(DataBase,2),7)+77 -> 46402 | O3: =DataBase+MOD(5-WEEKDAY(DataBase,2),7)+84 -> 46409 | P3: =DataBase+MOD(5-WEEKDAY(DataBase,2),7)+91 -> 46416 | Q3: =DataBase+MOD(5-WEEKDAY(DataBase,2),7)+98 -> 46423 | R3: =DataBase+MOD(5-WEEKDAY(DataBase,2),7)+105 -> 46430 | S3: =DataBase+MOD(5-WEEKDAY(DataBase,2),7)+112 -> 46437 | T3: =DataBase+MOD(5-WEEKDAY(DataBase,2),7)+119 -> 46444 | U3: =DataBase+MOD(5-WEEKDAY(DataBase,2),7)+126 -> 46451 | V3: =DataBase+MOD(5-WEEKDAY(DataBase,2),7)+133 -> 46458
A5: =CRONOGRAMA!A5 -> 1 | B5: =CRONOGRAMA!D5 -> Reunião de partida no local: identificar P1–P4, treliça e faixa de piso afetada | C5: =CRONOGRAMA!$M5*IF(C$3<CRONOGRAMA!$J5,0,IF(C$3>=CRONOGRAMA!$K5,1,NETWORKDAYS(CRONOGRAMA!$J5,C$3,Feriados)/MAX(CRONOGRAMA!$H5,1))) -> 0.015190542 | D5: =CRONOGRAMA!$M5*IF(D$3<CRONOGRAMA!$J5,0,IF(D$3>=CRONOGRAMA!$K5,1,NETWORKDAYS(CRONOGRAMA!$J5,D$3,Feriados)/MAX(CRONOGRAMA!$H5,1))) -> 0.015190542 | E5: =CRONOGRAMA!$M5*IF(E$3<CRONOGRAMA!$J5,0,IF(E$3>=CRONOGRAMA!$K5,1,NETWORKDAYS(CRONOGRAMA!$J5,E$3,Feriados)/MAX(CRONOGRAMA!$H5,1))) -> 0.015190542 | F5: =CRONOGRAMA!$M5*IF(F$3<CRONOGRAMA!$J5,0,IF(F$3>=CRONOGRAMA!$K5,1,NETWORKDAYS(CRONOGRAMA!$J5,F$3,Feriados)/MAX(CRONOGRAMA!$H5,1))) -> 0.015190542 | G5: =CRONOGRAMA!$M5*IF(G$3<CRONOGRAMA!$J5,0,IF(G$3>=CRONOGRAMA!$K5,1,NETWORKDAYS(CRONOGRAMA!$J5,G$3,Feriados)/MAX(CRONOGRAMA!$H5,1))) -> 0.015190542 | H5: =CRONOGRAMA!$M5*IF(H$3<CRONOGRAMA!$J5,0,IF(H$3>=CRONOGRAMA!$K5,1,NETWORKDAYS(CRONOGRAMA!$J5,H$3,Feriados)/MAX(CRONOGRAMA!$H5,1))) -> 0.015190542 | I5: =CRONOGRAMA!$M5*IF(I$3<CRONOGRAMA!$J5,0,IF(I$3>=CRONOGRAMA!$K5,1,NETWORKDAYS(CRONOGRAMA!$J5,I$3,Feriados)/MAX(CRONOGRAMA!$H5,1))) -> 0.015190542 | J5: =CRONOGRAMA!$M5*IF(J$3<CRONOGRAMA!$J5,0,IF(J$3>=CRONOGRAMA!$K5,1,NETWORKDAYS(CRONOGRAMA!$J5,J$3,Feriados)/MAX(CRONOGRAMA!$H5,1))) -> 0.015190542 | ... V5: =CRONOGRAMA!$M5*IF(V$3<CRONOGRAMA!$J5,0,IF(V$3>=CRONOGRAMA!$K5,1,NETWORKDAYS(CRONOGRAMA!$J5,V$3,Feriados)/MAX(CRONOGRAMA!$H5,1))) -> 0.015190542
